Workbook

Sheet 生產管理報表(月)
A1: 新豐廠生產管理報表
A3: 月別 | B3: 11 | C3: 工廠 | D3: 屏榮新豐廠
A4: （１）收支狀況 | E4: ※單位：千元 | G4: （２）ＫＰＩ達成進度
A5: 項目 | B5: 當月 | C5: 前月 | D5: 差異 | E5: 累計 | G5: 項目 | H5: KPI | I5: 當月 | J5: 前月 | K5: 累計 | L5: ※補充
A6: 業績金額 | B6: ='（１）收支狀況'!H97/1000 -> 183102.28 | C6: 173975.38 | D6: =B6-C6 -> 9126.8913 | G6: 人時性(個/月均) | H6: ='生產管理報表(週) '!H6 -> 150.5 | I6: ='（２）ＫＰＩ達成進度'!H97 -> 146.33 | J6: 146.35806 | L6: 個／MH
A7: 訂單數量 | B7: ='（４）訂單數量構成比'!H99 -> 5458762 | C7: 5308649 | D7: =B7-C7 -> 150113 | G7: 人時達成率(%/月均) | H7: ='生產管理報表(週) '!H7 -> 0.8 | I7: ='（２）ＫＰＩ達成進度'!K97 -> 0.97229236 | J7: 0.97247883 | L7: 達成率
A8: 材料費 | B8: ='（１）收支狀況'!N97/1000 -> 128040.74 | C8: 122020.9 | D8: =B8-C8 -> 6019.8431 | G8: 半成品-報廢(%) | H8: ='生產管理報表(週) '!H8 -> 0.0025 | I8: ='（２）ＫＰＩ達成進度'!N97 -> 0.0024295403 | J8: 0.0024269082 | L8: 報廢率
A9: 材料費率 | B9: ='（１）收支狀況'!Q97 -> 0.69928537 | C9: 0.70136875 | D9: =B9-C9 -> -0.0020833891 | G9: 半成品-超用(%) | H9: ='生產管理報表(週) '!H9 -> 0.004 | I9: ='（２）ＫＰＩ達成進度'!Q97 -> 0.0073095368 | J9: 0.0073353396 | L9: 超用率
A10: 勞務成本 | B10: ='（１）收支狀況'!T97/1000 -> 29348.058 | C10: 29429.236 | D10: =B10-C10 -> -81.17785 | G10: 固定產線-導入率(%) | H10: ='生產管理報表(週) '!H10 -> 0.8 | I10: ='（２）ＫＰＩ達成進度'!T97 -> 0.8 | J10: 0.8 | L10: 導入率
A11: 勞務費率 | B11: ='（１）收支狀況'!W97 -> 0.16028233 | C11: 0.16915747 | D11: =B11-C11 -> -0.0088751476 | G11: 教育訓練-實施率(%) | H11: ='生產管理報表(週) '!H11 -> 1 | I11: ='（２）ＫＰＩ達成進度'!W97 -> 0.87291667 | J11: 0.78103226 | L11: 實施率
A13: （３）業績構成比 | G13: （４）訂單數量構成比
A14: 品群 | B14: 當月 | C14: 比例 | D14: 前月 | E14: 差異 | G14: 品群 | H14: 當月 | I14: 比例 | J14: 前月 | K14: 差異
A15: 主食(091,092,093,094,095) | B15: =SUM('（３）業績構成比'!M99:M128)/1000 -> 51588.386 | C15: =IFERROR(B15/$B$6,"") -> 0.28174628 | D15: 0.24297924 | E15: =IFERROR(C15-D15,"") -> 0.038767039 | G15: 主食(091,092,093,094,095) | H15: =SUM('（４）訂單數量構成比'!M99:M128) -> 971592 | I15: =IFERROR(H15/$B$7,"") -> 0.17798761 | J15: 0.14971286 | K15: =IFERROR(I15-J15,"") -> 0.028274754
A16: 熱食義麵(122,123,124,126) | B16: =SUM('（３）業績構成比'!Q99:Q128)/1000 -> 4090.229 | C16: =IFERROR(B16/$B$6,"") -> 0.022338493 | D16: 0.01377222 | E16: =IFERROR(C16-D16,"") -> 0.0085662738 | G16: 熱食義麵(122,123,124,126) | H16: =SUM('（４）訂單數量構成比'!Q99:Q128) -> 78181 | I16: =IFERROR(H16/$B$7,"") -> 0.014322112 | J16: 0.007982822 | K16: =IFERROR(I16-J16,"") -> 0.0063392899
A17: 季節調理麵(111,112) | B17: 0 | C17: =IFERROR(B17/$B$6,"") -> 0 | D17: 0 | E17: =IFERROR(C17-D17,"") -> 0 | G17: 季節調理麵(111,112) | H17: 0 | I17: =IFERROR(H17/$B$7,"") -> 0 | J17: 0 | K17: =IFERROR(I17-J17,"") -> 0
A18: 微波小吃(153,154,155) | B18: =SUM('（３）業績構成比'!U99:U128)/1000 -> 4712.9226 | C18: =IFERROR(B18/$B$6,"") -> 0.02573929 | D18: 0.025900659 | E18: =IFERROR(C18-D18,"") -> -0.00016136883 | G18: 微波小吃(153,154,155) | H18: =SUM('（４）訂單數量構成比'!U99:U128) -> 112912 | I18: =IFERROR(H18/$B$7,"") -> 0.020684543 | J18: 0.020304601 | K18: =IFERROR(I18-J18,"") -> 0.00037994245
A19: 三明治(106) | B19: =SUM('（３）業績構成比'!W99:W128)/1000 -> 62412.131 | C19: =IFERROR(B19/$B$6,"") -> 0.34085939 | D19: 0.36738023 | E19: =IFERROR(C19-D19,"") -> -0.026520831 | G19: 三明治(106) | H19: =SUM('（４）訂單數量構成比'!W99:W128) -> 2530607 | I19: =IFERROR(H19/$B$7,"") -> 0.46358625 | J19: 0.48941473 | K19: =IFERROR(I19-J19,"") -> -0.025828478
A20: 調理麵包(107) | B20: =SUM('（３）業績構成比'!Y99:Y128)/1000 -> 36214.185 | C20: =IFERROR(B20/$B$6,"") -> 0.19778118 | D20: 0.19326746 | E20: =IFERROR(C20-D20,"") -> 0.004513725 | G20: 調理麵包(107) | H20: =SUM('（４）訂單數量構成比'!Y99:Y128) -> 1153450 | I20: =IFERROR(H20/$B$7,"") -> 0.21130249 | J20: 0.20250425 | K20: =IFERROR(I20-J20,"") -> 0.0087982365
A21: 沙拉(141) | B21: =SUM('（３）業績構成比'!AA99:AA128)/1000 -> 24084.423 | C21: =IFERROR(B21/$B$6,"") -> 0.13153536 | D21: 0.15670019 | E21: =IFERROR(C21-D21,"") -> -0.025164838 | G21: 沙拉(141) | H21: =SUM('（４）訂單數量構成比'!AA99:AA128) -> 612020 | I21: =IFERROR(H21/$B$7,"") -> 0.112117 | J21: 0.13008074 | K21: =IFERROR(I21-J21,"") -> -0.017963745
A22: 便當 | B22: =SUM('（３）業績構成比'!O99:O128)/1000 -> 0 | C22: =IFERROR(B22/$B$6,"") -> 0 | D22: 0 | E22: =IFERROR(C22-D22,"") -> 0 | G22: 便當 | H22: =SUM('（４）訂單數量構成比'!O99:O128) -> 0 | I22: =IFERROR(H22/$B$7,"") -> 0 | J22: 0 | K22: =IFERROR(I22-J22,"") -> 0
C23: =IFERROR(B23/$B$6,"") -> 0 | D23: 0 | E23: =IFERROR(C23-D23,"") -> 0 | I23: =IFERROR(H23/$B$7,"") -> 0 | J23: 0 | K23: =IFERROR(I23-J23,"") -> 0
C24: =SUM(C15:C23) -> 1 | D24: =SUM(D15:D23) -> 1 | I24: =SUM(I15:I23) -> 1 | J24: =SUM(J15:J23) -> 1
A26: （５）品群別人時生產性
A27: 品群 | B27: 當月 | C27: 前月 | D27: 差異 | E27: 累計
A28: 主食(091,092,093,094,095) | B28: ='（５-1）品群別人時生產性（4℃-主食）'!C1 -> 118.32758 | C28: 117.33798 | D28: =B28-C28 -> 0.98959867
A29: 熱食義麵(122,123,124,126) | B29: ='（５-3）品群別人時生產性（4℃-熱食義麵)'!C1 -> 112.86704 | C29: 84.383146 | D29: =B29-C29 -> 28.483896
A30: 季節調理麵(111,112) | B30: 0 | C30: 0 | D30: =B30-C30 -> 0
A31: 微波小吃(153,154,155) | B31: ='（５-4）品群別人時生產性（4℃-微波小吃)'!C1 -> 84.086268 | C31: 84.305793 | D31: =B31-C31 -> -0.21952418
A32: 三明治(106) | B32: ='（５-5）品群別人時生產性（4℃-三明治)'!C1 -> 136.0689 | C32: 132.93105 | D32: =B32-C32 -> 3.1378516
A33: 調理麵包(107) | B33: ='（５-6）品群別人時生產性（4℃-調理麵包)'!C1 -> 279.93393 | C33: 287.57514 | D33: =B33-C33 -> -7.6412063
A34: 沙拉(141) | B34: ='（５-7）品群別人時生產性（4℃-沙拉)'!C1 -> 112.83781 | C34: 105.94781 | D34: =B34-C34 -> 6.8900044
A35: 便當 | B35: ='（５-2）品群別人時生產性（4℃-便當）'!C1 -> #DIV/0! | C35: #DIV/0! | D35: =B35-C35 -> #DIV/0!
D36: 0
A39: 三明治 １０６
A40: 調理麵包 １０７
A41: 沙拉 １４１

Sheet 生產管理報表(週) 
A1: 新豐廠生產管理報表
A3: 月別 | B3: 12 | C3: 週別 | D3: W2 | E3: 工廠 | F3: ='生產管理報表(月)'!D3 -> 屏榮新豐廠
A4: （１）收支狀況 | E4: ※單位：千元 | G4: （２）ＫＰＩ達成進度
A5: 項目 | B5: 當週 | C5: 前週 | D5: 差異 | E5: 累計 | G5: 項目 | H5: KPI | I5: 當週 | J5: 前週 | K5: 累計 | L5: ※補充
A6: 業績金額 | B6: ='（１）收支狀況'!G135:G135/1000 -> 40299.484 | C6: 40306.238 | D6: =B6-C6 -> -6.75347 | E6: ='（１）收支狀況'!H127:H127/1000 -> 86901.174 | G6: 人時性(個/週均) | H6: 150.5 | I6: ='（２）ＫＰＩ達成進度'!G135 -> 144.22857 | J6: 148.1 | K6: ='（２）ＫＰＩ達成進度'!H127 -> 146.35333 | L6: 個／MH
A7: 訂單數量 | B7: ='（１）收支狀況'!J135:J135 -> 1209166 | C7: 1189096 | D7: =B7-C7 -> 20070 | E7: ='（１）收支狀況'!K127:K127 -> 2587065 | G7: 人時達成率(%/週均) | H7: 0.8 | I7: ='（２）ＫＰＩ達成進度'!J135 -> 0.95832938 | J7: 0.98405316 | K7: ='（２）ＫＰＩ達成進度'!K127 -> 0.9724474 | L7: 達成率
A8: 材料費 | B8: ='（１）收支狀況'!M135:M135/1000 -> 28022.225 | C8: 27945.425 | D8: =B8-C8 -> 76.80018 | E8: ='（１）收支狀況'!N127:N127/1000 -> 60282.566 | G8: 半成品-報廢(%) | H8: 0.0025 | I8: ='（２）ＫＰＩ達成進度'!M135 -> 0.002423264 | J8: 0.0024223363 | K8: ='（２）ＫＰＩ達成進度'!N127 -> 0.0024234134 | L8: 報廢率
A9: 材料費率 | B9: ='（１）收支狀況'!P135 -> 0.69534948 | C9: 0.69332755 | D9: =B9-C9 -> 0.0020219253 | E9: ='（１）收支狀況'!Q127 -> 0.69369105 | G9: 半成品-超用(%) | H9: 0.004 | I9: ='（２）ＫＰＩ達成進度'!P135 -> 0.0072784615 | J9: 0.0073140619 | K9: ='（２）ＫＰＩ達成進度'!Q127 -> 0.0072898654 | L9: 超用率
A10: 勞務成本 | B10: ='（１）收支狀況'!S135:S135/1000 -> 6627.4089 | C10: 6495.0241 | D10: =B10-C10 -> 132.38473 | E10: ='（１）收支狀況'!T127:T127/1000 -> 14047.932 | G10: 固定產線-導入率(%) | H10: 0.8 | I10: ='（２）ＫＰＩ達成進度'!S135 -> 0.8 | J10: 0.8 | K10: ='（２）ＫＰＩ達成進度'!T127 -> 0.8 | L10: 導入率
A11: 勞務費率 | B11: ='（１）收支狀況'!V135:V135 -> 0.16445394 | C11: 0.16114191 | D11: =B11-C11 -> 0.0033120273 | E11: ='（１）收支狀況'!W127:W127 -> 0.16165411 | G11: 教育訓練-實施率(%) | H11: 1 | I11: ='（２）ＫＰＩ達成進度'!V135 -> 0.965 | J11: 0.92 | K11: ='（２）ＫＰＩ達成進度'!W127 -> 0.941 | L11: 實施率
A13: （３）業績構成比 | E13: ※單位：千元 | G13: （４）訂單數量構成比 | K13: ※單位：個
A14: 品群 | B14: 當週 | C14: 比例 | D14: 前週 | E14: 差異 | G14: 品群 | H14: 當週 | I14: 比例 | J14: 前週 | K14: 差異
A15: 主食(091,092,093,094,095) | B15: =SUM('（３）業績構成比'!M137:M143)/1000 -> 10541.021 | C15: =IFERROR(B15/$B$6,"") -> 0.26156715 | D15: 0.27941093 | E15: =IFERROR(C15-D15,"") -> -0.017843781 | G15: 主食(091,092,093,094,095) | H15: =SUM('（４）訂單數量構成比'!M137:M143) -> 196725 | I15: =IFERROR(H15/$B$7,"") -> 0.16269478 | J15: 0.17743059 | K15: =IFERROR(I15-J15,"") -> -0.014735803
A16: 熱食義麵(122,123,124,126) | B16: =SUM('（３）業績構成比'!Q137:Q143)/1000 -> 502.3433 | C16: =IFERROR(B16/$B$6,"") -> 0.012465254 | D16: 0.014718841 | E16: =IFERROR(C16-D16,"") -> -0.0022535871 | G16: 熱食義麵(122,123,124,126) | H16: =SUM('（４）訂單數量構成比'!Q137:Q143) -> 10067 | I16: =IFERROR(H16/$B$7,"") -> 0.0083255732 | J16: 0.0099983517 | K16: =IFERROR(I16-J16,"") -> -0.0016727785
A17: 季節調理麵(111,112) | B17: =SUM('（３）業績構成比'!S137:S143)/1000 -> 935.9872 | C17: =IFERROR(B17/$B$6,"") -> 0.023225786 | D17: 0.03337947 | E17: =IFERROR(C17-D17,"") -> -0.010153684 | G17: 季節調理麵(111,112) | H17: =SUM('（４）訂單數量構成比'!S137:S143) -> 12928 | I17: =IFERROR(H17/$B$7,"") -> 0.010691667 | J17: 0.016050849 | K17: =IFERROR(I17-J17,"") -> -0.0053591819
A18: 微波小吃(153,154,155) | B18: =SUM('（３）業績構成比'!U137:U143)/1000 -> 954.06298 | C18: =IFERROR(B18/$B$6,"") -> 0.023674322 | D18: 0.025089125 | E18: =IFERROR(C18-D18,"") -> -0.0014148023 | G18: 微波小吃(153,154,155) | H18: =SUM('（４）訂單數量構成比'!U137:U143) -> 22878 | I18: =IFERROR(H18/$B$7,"") -> 0.018920479 | J18: 0.020383552 | K18: =IFERROR(I18-J18,"") -> -0.0014630728
A19: 三明治(106) | B19: =SUM('（３）業績構成比'!W137:W143)/1000 -> 14154.403 | C19: =IFERROR(B19/$B$6,"") -> 0.35123038 | D19: 0.34243756 | E19: =IFERROR(C19-D19,"") -> 0.0087928188 | G19: 三明治(106) | H19: =SUM('（４）訂單數量構成比'!W137:W143) -> 579233 | I19: =IFERROR(H19/$B$7,"") -> 0.47903514 | J19: 0.47018407 | K19: =IFERROR(I19-J19,"") -> 0.008851064
A20: 調理麵包(107) | B20: =SUM('（３）業績構成比'!Y137:Y143)/1000 -> 8537.1414 | C20: =IFERROR(B20/$B$6,"") -> 0.21184245 | D20: 0.1861023 | E20: =IFERROR(C20-D20,"") -> 0.025740148 | G20: 調理麵包(107) | H20: =SUM('（４）訂單數量構成比'!Y137:Y143) -> 268050 | I20: =IFERROR(H20/$B$7,"") -> 0.22168172 | J20: 0.20320983 | K20: =IFERROR(I20-J20,"") -> 0.018471888
A21: 沙拉(141) | B21: =SUM('（３）業績構成比'!AA137:AA143)/1000 -> 4674.5251 | C21: =IFERROR(B21/$B$6,"") -> 0.11599466 | D21: 0.11886178 | E21: =IFERROR(C21-D21,"") -> -0.0028671124 | G21: 沙拉(141) | H21: =SUM('（４）訂單數量構成比'!AA137:AA143) -> 119285 | I21: =IFERROR(H21/$B$7,"") -> 0.09865064 | J21: 0.10274276 | K21: =IFERROR(I21-J21,"") -> -0.0040921156
A22: 便當 | B22: =SUM('（３）業績構成比'!O137:O143)/1000 -> 0 | C22: =IFERROR(B22/$B$6,"") -> 0 | D22: 0 | E22: =IFERROR(C22-D22,"") -> 0 | G22: 便當 | H22: =SUM('（４）訂單數量構成比'!O137:O143) -> 0 | I22: =IFERROR(H22/$B$7,"") -> 0 | J22: 0 | K22: =IFERROR(I22-J22,"") -> 0
C23: =IFERROR(B23/$B$6,"") -> 0 | D23: 0 | E23: =IFERROR(C23-D23,"") -> 0 | I23: =IFERROR(H23/$B$7,"") -> 0 | J23: 0 | K23: =IFERROR(I23-J23,"") -> 0
C24: =SUM(C15:C23) -> 1 | D24: =SUM(D15:D23) -> 1 | I24: =SUM(I15:I23) -> 1 | J24: =SUM(J15:J23) -> 1
A26: （５）品群別人時生產性
A27: 品群 | B27: 當週 | C27: 前週 | D27: 差異 | E27: 累計
A28: 主食(091,092,093,094,095) | B28: ='（５-1）品群別人時生產性（4℃-主食）'!L391 -> 118.34995 | C28: 118.3052 | D28: =B28-C28 -> 0.044746385 | E28: ='（５-1）品群別人時生產性（4℃-主食）'!C1 -> 118.32758
A29: 熱食義麵(122,123,124,126) | B29: ='（５-3）品群別人時生產性（4℃-熱食義麵)'!L387 -> 113.1867 | C29: 112.54738 | D29: =B29-C29 -> 0.6393139 | E29: ='（５-3）品群別人時生產性（4℃-熱食義麵)'!C1 -> 112.86704
A30: 季節調理麵(111,112) | B30: ='（５-3）品群別人時生產性（4℃-季節調理麵)'!L387 -> 79.799782 | C30: 79.689141 | D30: =B30-C30 -> 0.11064112 | E30: ='（５-3）品群別人時生產性（4℃-季節調理麵)'!C1 -> 79.744462
A31: 微波小吃(153,154,155) | B31: ='（５-4）品群別人時生產性（4℃-微波小吃)'!L387 -> 84.231604 | C31: 83.940933 | D31: =B31-C31 -> 0.29067039 | E31: ='（５-4）品群別人時生產性（4℃-微波小吃)'!C1 -> 84.086268
A32: 三明治(106) | B32: ='（５-5）品群別人時生產性（4℃-三明治)'!L435 -> 136.30229 | C32: 135.83551 | D32: =B32-C32 -> 0.46677737 | E32: ='（５-5）品群別人時生產性（4℃-三明治)'!C1 -> 136.0689
A33: 調理麵包(107) | B33: ='（５-6）品群別人時生產性（4℃-調理麵包)'!L387 -> 272.62265 | C33: 287.24522 | D33: =B33-C33 -> -14.622568 | E33: ='（５-6）品群別人時生產性（4℃-調理麵包)'!C1 -> 279.93393
A34: 沙拉(141) | B34: ='（５-7）品群別人時生產性（4℃-沙拉)'!L387 -> 112.8649 | C34: 112.81072 | D34: =B34-C34 -> 0.054176854 | E34: ='（５-7）品群別人時生產性（4℃-沙拉)'!C1 -> 112.83781
A35: 便當 | B35: ='（５-2）品群別人時生產性（4℃-便當）'!L387 -> - | C35: - | D35: =B35-C35 -> #VALUE! | E35: ='（５-2）品群別人時生產性（4℃-便當）'!C1 -> #DIV/0!
D36: 0
A39: 三明治 １０６
A40: 調理麵包 １０７
A41: 沙拉 １４１

Sheet （１）收支狀況
B2: （１）收支狀況
B3: 資料繳交日 | C3: 月份 | D3: 日期 | F3: 營業額(元) | I3: 訂單數量(個) | L3: 材料費(元) | O3: 材料費率（材料費／營業額） | R3: 勞務成本（全廠人事成本） | U3: 勞務費率（勞務成本／營業額）
F4: 日 | G4: 週累積 | H4: 月累積 | I4: 日 | J4: 週累積 | K4: 月累積 | L4: 日 | M4: 週累積 | N4: 月累積 | O4: 日 | P4: 週累積 | Q4: 月累積 | R4: 日 | S4: 週累積 | T4: 月累積 | U4: 日 | V4: 週累積 | W4: 月累積
B5: =D17 -> 45882 | C5: 八 | D5: 45870 | E5: 五 | F5: ='（３）業績構成比'!F7 -> 4376902.4 | G5: =SUM(F5:F8) -> 20827993 | H5: =SUM(F5:F35) -> 1.7063649e+08 | I5: ='（４）訂單數量構成比'!F7 -> 126626 | J5: =SUM(I5:I8) -> 603449 | K5: =SUM(I5:I35) -> 4956065 | L5: 2914701.1 | M5: =SUM(L5:L8) -> 14609030 | N5: =SUM(L5:L35) -> 1.2031567e+08 | O5: =IFERROR(L5/F5,"") -> 0.66592784 | P5: =M5/G5 -> 0.70141323 | Q5: =N5/H5 -> 0.70509929 | R5: 879473.39 | S5: =SUM(R5:R8) -> 3602566.4 | T5: =SUM(R5:R35) -> 28193858 | U5: =IFERROR(R5/F5,"") -> 0.20093512 | V5: =S5/G5 -> 0.17296752 | W5: =T5/H5 -> 0.1652276
D6: 45871 | E6: 六 | F6: ='（３）業績構成比'!F8 -> 4635761.7 | I6: ='（４）訂單數量構成比'!F8 -> 132231 | L6: 3336553.7 | O6: =IFERROR(L6/F6,"") -> 0.71974227 | R6: 890278.88 | U6: =IFERROR(R6/F6,"") -> 0.19204587
D7: 45872 | E7: 日 | F7: ='（３）業績構成比'!F9 -> 5941913.1 | I7: ='（４）訂單數量構成比'!F9 -> 172946 | L7: 4251530.7 | O7: =IFERROR(L7/F7,"") -> 0.71551546 | R7: 873942.43 | U7: =IFERROR(R7/F7,"") -> 0.14708098
D8: 45873 | E8: 一 | F8: ='（３）業績構成比'!F10 -> 5873416.1 | I8: ='（４）訂單數量構成比'!F10 -> 171646 | L8: 4106244.5 | O8: =IFERROR(L8/F8,"") -> 0.69912371 | R8: 958871.67 | U8: =IFERROR(R8/F8,"") -> 0.16325621
D9: 45874 | E9: 二 | F9: ='（３）業績構成比'!F11 -> 6182700.1 | G9: =SUM(F9:F15) -> 38973977 | I9: ='（４）訂單數量構成比'!F11 -> 185947 | J9: =SUM(I9:I15) -> 1159872 | L9: 4317373.1 | M9: =SUM(L9:L15) -> 27196273 | O9: =IFERROR(L9/F9,"") -> 0.69829897 | P9: =M9/G9 -> 0.69780596 | R9: 973458.53 | S9: =SUM(R9:R15) -> 6523306.9 | U9: =IFERROR(R9/F9,"") -> 0.15744877 | V9: =S9/G9 -> 0.16737596
D10: 45875 | E10: 三 | F10: ='（３）業績構成比'!F12 -> 6008483.6 | I10: ='（４）訂單數量構成比'!F12 -> 179806 | L10: 4167843.5 | O10: =IFERROR(L10/F10,"") -> 0.69365979 | R10: 1011615.9 | U10: =IFERROR(R10/F10,"") -> 0.16836459
D11: 45876 | E11: 四 | F11: ='（３）業績構成比'!F13 -> 5578775.7 | I11: ='（４）訂單數量構成比'!F13 -> 167846 | L11: 3948565.4 | O11: =IFERROR(L11/F11,"") -> 0.70778351 | R11: 958610.28 | U11: =IFERROR(R11/F11,"") -> 0.17183166
D12: 45877 | E12: 五 | F12: ='（３）業績構成比'!F14 -> 4540704.5 | I12: ='（４）訂單數量構成比'!F14 -> 133441 | L12: 3136128.8 | O12: =IFERROR(L12/F12,"") -> 0.6906701 | R12: 918456.39 | U12: =IFERROR(R12/F12,"") -> 0.20227178
D13: 45878 | E13: 六 | F13: ='（３）業績構成比'!F15 -> 4698363 | I13: ='（４）訂單數量構成比'!F15 -> 136383 | L13: 3324455.1 | O13: =IFERROR(L13/F13,"") -> 0.70757732 | R13: 846441.95 | U13: =IFERROR(R13/F13,"") -> 0.18015678
D14: 45879 | E14: 日 | F14: ='（３）業績構成比'!F16 -> 6020434.1 | I14: ='（４）訂單數量構成比'!F16 -> 179198 | L14: 4164340.5 | O14: =IFERROR(L14/F14,"") -> 0.69170103 | R14: 855877.17 | U14: =IFERROR(R14/F14,"") -> 0.14216204
D15: 45880 | E15: 一 | F15: ='（３）業績構成比'!F17 -> 5944516 | I15: ='（４）訂單數量構成比'!F17 -> 177251 | L15: 4137567 | O15: =IFERROR(L15/F15,"") -> 0.69603093 | R15: 958846.71 | U15: =IFERROR(R15/F15,"") -> 0.16129937
B16: =D24 -> 45889 | D16: 45881 | E16: 二 | F16: ='（３）業績構成比'!F18 -> 5571060 | G16: =SUM(F16:F22) -> 36769734 | I16: ='（４）訂單數量構成比'!F18 -> 163807 | J16: =SUM(I16:I22) -> 1082673 | L16: 3965503.5 | M16: =SUM(L16:L22) -> 25835317 | O16: =IFERROR(L16/F16,"") -> 0.71180412 | P16: =M16/G16 -> 0.70262454 | R16: 941877.15 | S16: =SUM(R16:R22) -> 6176194.7 | U16: =IFERROR(R16/F16,"") -> 0.16906606 | V16: =S16/G16 -> 0.16796953
D17: 45882 | E17: 三 | F17: ='（３）業績構成比'!F19 -> 5601894.3 | I17: ='（４）訂單數量構成比'!F19 -> 165300 | L17: 3927389.9 | O17: =IFERROR(L17/F17,"") -> 0.70108247 | R17: 918616.62 | U17: =IFERROR(R17/F17,"") -> 0.16398321
D18: 45883 | E18: 四 | F18: ='（３）業績構成比'!F20 -> 5220507.7 | I18: ='（４）訂單數量構成比'!F20 -> 154459 | L18: 3599190.2 | O18: =IFERROR(L18/F18,"") -> 0.68943299 | R18: 892023.12 | U18: =IFERROR(R18/F18,"") -> 0.17086904
D19: 45884 | E19: 五 | F19: ='（３）業績構成比'!F21 -> 4456648 | I19: ='（４）訂單數量構成比'!F21 -> 129575 | L19: 3145612.5 | O19: =IFERROR(L19/F19,"") -> 0.70582474 | R19: 852394.56 | U19: =IFERROR(R19/F19,"") -> 0.1912636
D20: 45885 | E20: 六 | F20: ='（３）業績構成比'!F22 -> 4483117.5 | I20: ='（４）訂單數量構成比'!F22 -> 129760 | L20: 3180471.4 | O20: =IFERROR(L20/F20,"") -> 0.70943299 | R20: 826415.92 | U20: =IFERROR(R20/F20,"") -> 0.18433956
D21: 45886 | E21: 日 | F21: ='（３）業績構成比'!F23 -> 5735188.3 | I21: ='（４）訂單數量構成比'!F23 -> 169934 | L21: 4087060.7 | O21: =IFERROR(L21/F21,"") -> 0.71262887 | R21: 826385.08 | U21: =IFERROR(R21/F21,"") -> 0.14409031
D22: 45887 | E22: 一 | F22: ='（３）業績構成比'!F24 -> 5701317.8 | I22: ='（４）訂單數量構成比'!F24 -> 169838 | L22: 3930088.8 | O22: =IFERROR(L22/F22,"") -> 0.6893299 | R22: 918482.3 | U22: =IFERROR(R22/F22,"") -> 0.1611
B23: =D31 -> 45896 | D23: 45888 | E23: 二 | F23: ='（３）業績構成比'!F25 -> 6939236.5 | G23: =SUM(F23:F29) -> 41790039 | I23: ='（４）訂單數量構成比'!F25 -> 193634 | J23: =SUM(I23:I29) -> 1179305 | L23: 5126092.7 | M23: =SUM(L23:L29) -> 29847662 | O23: =IFERROR(L23/F23,"") -> 0.73871134 | P23: =M23/G23 -> 0.7142291 | R23: 917891.66 | S23: =SUM(R23:R29) -> 6478375.8 | U23: =IFERROR(R23/F23,"") -> 0.1322756 | V23: =S23/G23 -> 0.15502201
D24: 45889 | E24: 三 | F24: ='（３）業績構成比'!F26 -> 6333786.4 | I24: ='（４）訂單數量構成比'!F26 -> 180887 | L24: 4556734.9 | O24: =IFERROR(L24/F24,"") -> 0.71943299 | R24: 1030986.5 | U24: =IFERROR(R24/F24,"") -> 0.1627757
D25: 45890 | E25: 四 | F25: ='（３）業績構成比'!F27 -> 5963895.7 | I25: ='（４）訂單數量構成比'!F27 -> 170601 | L25: 4187331.1 | O25: =IFERROR(L25/F25,"") -> 0.7021134 | R25: 967364.37 | U25: =IFERROR(R25/F25,"") -> 0.16220344
D26: 45891 | E26: 五 | F26: ='（３）業績構成比'!F28 -> 4909451 | I26: ='（４）訂單數量構成比'!F28 -> 134952 | L26: 3583140 | O26: =IFERROR(L26/F26,"") -> 0.72984536 | R26: 895981.97 | U26: =IFERROR(R26/F26,"") -> 0.18250146
D27: 45892 | E27: 六 | F27: ='（３）業績構成比'!F29 -> 5147138.7 | I27: ='（４）訂單數量構成比'!F29 -> 140531 | L27: 3664285.2 | O27: =IFERROR(L27/F27,"") -> 0.71190722 | R27: 839624.8 | U27: =IFERROR(R27/F27,"") -> 0.16312457
D28: 45893 | E28: 日 | F28: ='（３）業績構成比'!F30 -> 6385967.1 | I28: ='（４）訂單數量構成比'!F30 -> 182419 | L28: 4502765.2 | O28: =IFERROR(L28/F28,"") -> 0.70510309 | R28: 869487.04 | U28: =IFERROR(R28/F28,"") -> 0.13615589
D29: 45894 | E29: 一 | F29: ='（３）業績構成比'!F31 -> 6110563.6 | I29: ='（４）訂單數量構成比'!F31 -> 176281 | L29: 4227313.1 | O29: =IFERROR(L29/F29,"") -> 0.69180412 | R29: 957039.43 | U29: =IFERROR(R29/F29,"") -> 0.15662048
B30: =D38 -> 45903 | D30: 45895 | E30: 二 | F30: ='（３）業績構成比'!F32 -> 5751890.8 | G30: =SUM(F30:F36) -> 38277517 | I30: ='（４）訂單數量構成比'!F32 -> 166644 | J30: =SUM(I30:I36) -> 1105998 | L30: 4112601.9 | M30: =SUM(L30:L36) -> 27040774 | O30: =IFERROR(L30/F30,"") -> 0.715 | P30: =M30/G30 -> 0.70644011 | R30: 953162.47 | S30: =SUM(R30:R36) -> 6420325.2 | U30: =IFERROR(R30/F30,"") -> 0.16571289 | V30: =S30/G30 -> 0.16773097
D31: 45896 | E31: 三 | F31: ='（３）業績構成比'!F33 -> 5656058.4 | I31: ='（４）訂單數量構成比'!F33 -> 164419 | L31: 4056909.9 | O31: =IFERROR(L31/F31,"") -> 0.71726804 | R31: 922677.27 | U31: =IFERROR(R31/F31,"") -> 0.16313079
D32: 45897 | E32: 四 | F32: ='（３）業績構成比'!F34 -> 5359266.3 | I32: ='（４）訂單數量構成比'!F34 -> 155645 | L32: 3756182.7 | O32: =IFERROR(L32/F32,"") -> 0.70087629 | R32: 915926.48 | U32: =IFERROR(R32/F32,"") -> 0.1709052
D33: 45898 | E33: 五 | F33: ='（３）業績構成比'!F35 -> 4553981.3 | I33: ='（４）訂單數量構成比'!F35 -> 129900 | L33: 3202106.1 | O33: =IFERROR(L33/F33,"") -> 0.70314433 | R33: 903047.26 | U33: =IFERROR(R33/F33,"") -> 0.19829841
D34: 45899 | E34: 六 | F34: ='（３）業績構成比'!F36 -> 4840642 | I34: ='（４）訂單數量構成比'!F36 -> 136235 | L34: 3386203.8 | O34: =IFERROR(L34/F34,"") -> 0.69953608 | R34: 836362.97 | U34: =IFERROR(R34/F34,"") -> 0.17277935
D35: 45900 | E35: 日 | F35: ='（３）業績構成比'!F37 -> 6112909.4 | I35: ='（４）訂單數量構成比'!F37 -> 177923 | L35: 4313382.3 | O35: =IFERROR(L35/F35,"") -> 0.70561856 | R35: 882237.65 | U35: =IFERROR(R35/F35,"") -> 0.14432369
C36: 九 | D36: 45901 | E36: 一 | F36: ='（３）業績構成比'!F38 -> 6002768.9 | H36: =SUM(F36:F65) -> 1.6954486e+08 | I36: ='（４）訂單數量構成比'!F38 -> 175232 | K36: =SUM(I36:I65) -> 5123862 | L36: 4213386.8 | N36: =SUM(L36:L65) -> 1.1799664e+08 | O36: =IFERROR(L36/F36,"") -> 0.70190722 | Q36: =N36/H36 -> 0.69596115 | R36: 1006911.1 | T36: =SUM(R36:R65) -> 28554124 | U36: =IFERROR(R36/F36,"") -> 0.1677411 | W36: =T36/H36 -> 0.16841633
D37: 45902 | E37: 二 | F37: ='（３）業績構成比'!F39 -> 6639488.4 | G37: =SUM(F37:F43) -> 40192283 | I37: ='（４）訂單數量構成比'!F39 -> 193593 | J37: =SUM(I37:I43) -> 1186458 | L37: 4697951.4 | M37: =SUM(L37:L43) -> 27970289 | O37: =IFERROR(L37/F37,"") -> 0.70757732 | P37: =M37/G37 -> 0.69591193 | R37: 1063249.6 | S37: =SUM(R37:R43) -> 6810329.3 | U37: =IFERROR(R37/F37,"") -> 0.16014029 | V37: =S37/G37 -> 0.16944371
D38: 45903 | E38: 三 | F38: ='（３）業績構成比'!F40 -> 6228436.4 | I38: ='（４）訂單數量構成比'!F40 -> 182804 | L38: 4292163.2 | O38: =IFERROR(L38/F38,"") -> 0.68912371 | R38: 988761.34 | U38: =IFERROR(R38/F38,"") -> 0.15874953
D39: 45904 | E39: 四 | F39: ='（３）業績構成比'!F41 -> 5632441.8 | I39: ='（４）訂單數量構成比'!F41 -> 168001 | L39: 3958677.5 | O39: =IFERROR(L39/F39,"") -> 0.70283505 | R39: 971018.78 | U39: =IFERROR(R39/F39,"") -> 0.17239748
D40: 45905 | E40: 五 | F40: ='（３）業績構成比'!F42 -> 4472239 | I40: ='（４）訂單數量構成比'!F42 -> 132042 | L40: 3171831.8 | O40: =IFERROR(L40/F40,"") -> 0.7092268 | R40: 898496.3 | U40: =IFERROR(R40/F40,"") -> 0.20090525
D41: 45906 | E41: 六 | F41: ='（３）業績構成比'!F43 -> 4788156 | I41: ='（４）訂單數量構成比'!F43 -> 139507 | L41: 3332704.7 | O41: =IFERROR(L41/F41,"") -> 0.69603093 | R41: 920494.31 | U41: =IFERROR(R41/F41,"") -> 0.19224401
...

Sheet （２）ＫＰＩ達成進度
B1: 人時生產性基準值 | C1: 150.5
B2: （２）ＫＰＩ達成進度
B3: 資料繳交日 | C3: 月份 | D3: 日期 | F3: 人時生產性(個/人) | I3: 人時生產性達成率(%) | L3: 半成品報廢(%) | O3: 半成品超用(%) | R3: 固定產線-導入率(固定產線數/總產線數) | U3: 教育訓練-實施率(進度/計畫)
F4: 日 | G4: 週平均 | H4: 月平均 | I4: 日 | J4: 週平均 | K4: 月平均 | L4: 日 | M4: 週平均 | N4: 月平均 | O4: 日 | P4: 週平均 | Q4: 月平均 | R4: 日 | S4: 週平均 | T4: 月平均 | U4: 日 | V4: 週平均 | W4: 月平均
B5: =D17 -> 45882 | C5: 八 | D5: 45870 | E5: 五 | F5: 130.1 | G5: =AVERAGE(F5:F8) -> 134.7 | H5: =AVERAGEIF(F5:F35,"<>0") -> 136.63548 | I5: =F5/$C$1 -> 0.86445183 | J5: =AVERAGE(I5:I8) -> 0.89501661 | K5: =AVERAGEIF(I5:I35,"<>0") -> 0.90787697 | L5: 0.0024042963 | M5: =AVERAGE(L5:L8) -> 0.0024211186 | N5: =AVERAGEIF(L5:L35,"<>0") -> 0.0024262338 | O5: 0.0085958988 | P5: =AVERAGE(O5:O8) -> 0.0085787423 | Q5: =AVERAGEIF(O5:O35,"<>0") -> 0.0083806862 | R5: =(10-2)/10 -> 0.8 | S5: =AVERAGE(R5:R8) -> 0.8 | T5: =AVERAGEIF(R5:R35,"<>0") -> 0.8 | U5: 0.583 | V5: =AVERAGE(U5:U8) -> 0.583 | W5: =AVERAGEIF(U5:U35,"<>0") -> 0.60867742
D6: 45871 | E6: 六 | F6: 135.9 | I6: =F6/$C$1 -> 0.90299003 | L6: 0.0024062432 | O6: 0.0085932975 | R6: =(10-2)/10 -> 0.8 | U6: 0.583
D7: 45872 | E7: 日 | F7: 136.3 | I7: =F7/$C$1 -> 0.90564784 | L7: 0.0024375045 | O7: 0.0085624022 | R7: =(10-2)/10 -> 0.8 | U7: 0.583
D8: 45873 | E8: 一 | F8: 136.5 | I8: =F8/$C$1 -> 0.90697674 | L8: 0.0024364305 | O8: 0.0085633708 | R8: =(10-2)/10 -> 0.8 | U8: 0.583
D9: 45874 | E9: 二 | F9: 137.4 | G9: =AVERAGE(F9:F15) -> 137.35714 | I9: =F9/$C$1 -> 0.91295681 | J9: =AVERAGE(I9:I15) -> 0.91267205 | L9: 0.0024501382 | M9: =AVERAGE(L9:L15) -> 0.0024313113 | O9: 0.0085497936 | P9: =AVERAGE(O9:O15) -> 0.0085685374 | R9: =(10-2)/10 -> 0.8 | S9: =AVERAGE(R9:R15) -> 0.8 | U9: 0.583 | V9: =AVERAGE(U9:U15) -> 0.583
D10: 45875 | E10: 三 | F10: 137.3 | I10: =F10/$C$1 -> 0.91229236 | L10: 0.0024394275 | O10: 0.0085603163 | R10: =(10-2)/10 -> 0.8 | U10: 0.583
D11: 45876 | E11: 四 | F11: 137.5 | I11: =F11/$C$1 -> 0.91362126 | L11: 0.0024293054 | O11: 0.0085706045 | R11: =(10-2)/10 -> 0.8 | U11: 0.583
D12: 45877 | E12: 五 | F12: 137.2 | I12: =F12/$C$1 -> 0.91162791 | L12: 0.0024038032 | O12: 0.0085963468 | R12: =(10-2)/10 -> 0.8 | U12: 0.583
D13: 45878 | E13: 六 | F13: 137.2 | I13: =F13/$C$1 -> 0.91162791 | L13: 0.0024070235 | O13: 0.0085928994 | R13: =(10-2)/10 -> 0.8 | U13: 0.583
D14: 45879 | E14: 日 | F14: 137.5 | I14: =F14/$C$1 -> 0.91362126 | L14: 0.0024394553 | O14: 0.0085601469 | R14: =(10-2)/10 -> 0.8 | U14: 0.583
D15: 45880 | E15: 一 | F15: 137.4 | I15: =F15/$C$1 -> 0.91295681 | L15: 0.0024500262 | O15: 0.0085496548 | R15: =(10-2)/10 -> 0.8 | U15: 0.583
B16: =D24 -> 45889 | D16: 45881 | E16: 二 | F16: 138.2 | G16: =AVERAGE(F16:F22) -> 138.07143 | I16: =F16/$C$1 -> 0.91827243 | J16: =AVERAGE(I16:I22) -> 0.91741813 | L16: 0.0024293618 | M16: =AVERAGE(L16:L22) -> 0.002413715 | O16: 0.0085707263 | P16: =AVERAGE(O16:O22) -> 0.0085862571 | R16: =(10-2)/10 -> 0.8 | S16: =AVERAGE(R16:R22) -> 0.8 | U16: 0.583 | V16: =AVERAGE(U16:U22) -> 0.583
D17: 45882 | E17: 三 | F17: 138.2 | I17: =F17/$C$1 -> 0.91827243 | L17: 0.002399649 | O17: 0.0086003176 | R17: =(10-2)/10 -> 0.8 | U17: 0.583
D18: 45883 | E18: 四 | F18: 138.4 | I18: =F18/$C$1 -> 0.91960133 | L18: 0.0024003719 | O18: 0.0085997441 | R18: =(10-2)/10 -> 0.8 | U18: 0.583
D19: 45884 | E19: 五 | F19: 137.9 | I19: =F19/$C$1 -> 0.91627907 | L19: 0.0023998036 | O19: 0.0085998938 | R19: =(10-2)/10 -> 0.8 | U19: 0.583
D20: 45885 | E20: 六 | F20: 137.8 | I20: =F20/$C$1 -> 0.91561462 | L20: 0.0024021253 | O20: 0.0085977805 | R20: =(10-2)/10 -> 0.8 | U20: 0.583
D21: 45886 | E21: 日 | F21: 138 | I21: =F21/$C$1 -> 0.91694352 | L21: 0.002432445 | O21: 0.0085678268 | R21: =(10-2)/10 -> 0.8 | U21: 0.583
D22: 45887 | E22: 一 | F22: 138 | I22: =F22/$C$1 -> 0.91694352 | L22: 0.0024322482 | O22: 0.0085675104 | R22: =(10-2)/10 -> 0.8 | U22: 0.583
B23: =D24 -> 45889 | D23: 45888 | E23: 二 | F23: 134.9 | G23: =AVERAGE(F23:F29) -> 135.7 | I23: =F23/$C$1 -> 0.89634551 | J23: =AVERAGE(I23:I29) -> 0.90166113 | L23: 0.0024503402 | M23: =AVERAGE(L23:L29) -> 0.0024341466 | O23: 0.0085499535 | P23: =AVERAGE(O23:O29) -> 0.0084877557 | R23: =(10-2)/10 -> 0.8 | S23: =AVERAGE(R23:R29) -> 0.8 | U23: 0.625 | V23: =AVERAGE(U23:U29) -> 0.625
D24: 45889 | E24: 三 | F24: 135.2 | I24: =F24/$C$1 -> 0.89833887 | L24: 0.0024366578 | O24: 0.0085632838 | R24: =(10-2)/10 -> 0.8 | U24: 0.625
D25: 45890 | E25: 四 | F25: 135 | I25: =F25/$C$1 -> 0.89700997 | L25: 0.0024285636 | O25: 0.0085710722 | R25: =(10-2)/10 -> 0.8 | U25: 0.625
D26: 45891 | E26: 五 | F26: 136.4 | I26: =F26/$C$1 -> 0.90631229 | L26: 0.0024122249 | O26: 0.0085874348 | R26: =(10-2)/10 -> 0.8 | U26: 0.625
D27: 45892 | E27: 六 | F27: 136.5 | I27: =F27/$C$1 -> 0.90697674 | L27: 0.0024223342 | O27: 0.0085781175 | R27: =(10-2)/10 -> 0.8 | U27: 0.625
D28: 45893 | E28: 日 | F28: 136.4 | I28: =F28/$C$1 -> 0.90631229 | L28: 0.0024471141 | O28: 0.00855249 | R28: =(10-2)/10 -> 0.8 | U28: 0.625
D29: 45894 | E29: 一 | F29: 135.5 | I29: =F29/$C$1 -> 0.90033223 | L29: 0.0024417911 | O29: 0.0080119385 | R29: =(10-2)/10 -> 0.8 | U29: 0.625
B30: =D38 -> 45903 | D30: 45895 | E30: 二 | F30: 136.4 | G30: =AVERAGE(F30:F36) -> 136.7 | I30: =F30/$C$1 -> 0.90631229 | J30: =AVERAGE(I30:I36) -> 0.90830565 | L30: 0.0024306372 | M30: =AVERAGE(L30:L36) -> 0.0024304495 | O30: 0.0077275789 | P30: =AVERAGE(O30:O36) -> 0.0076896107 | R30: =(10-2)/10 -> 0.8 | S30: =AVERAGE(R30:R36) -> 0.8 | U30: 0.66666667 | V30: =AVERAGE(U30:U36) -> 0.66666667
D31: 45896 | E31: 三 | F31: 136.8 | I31: =F31/$C$1 -> 0.9089701 | L31: 0.0024267235 | O31: 0.0076750676 | R31: =(10-2)/10 -> 0.8 | U31: 0.66666667
D32: 45897 | E32: 四 | F32: 136.5 | I32: =F32/$C$1 -> 0.90697674 | L32: 0.0024308701 | O32: 0.0075018907 | R32: =(10-2)/10 -> 0.8 | U32: 0.66666667
D33: 45898 | E33: 五 | F33: 136.5 | I33: =F33/$C$1 -> 0.90697674 | L33: 0.0024039998 | O33: 0.0075406459 | R33: =(10-2)/10 -> 0.8 | U33: 0.66666667
D34: 45899 | E34: 六 | F34: 136 | I34: =F34/$C$1 -> 0.90365449 | L34: 0.0024406039 | O34: 0.0076337477 | R34: =(10-2)/10 -> 0.8 | U34: 0.66666667
D35: 45900 | E35: 日 | F35: 136.8 | I35: =F35/$C$1 -> 0.9089701 | L35: 0.0024417277 | O35: 0.0079095218 | R35: =(10-2)/10 -> 0.8 | U35: 0.66666667
C36: 九 | D36: 45901 | E36: 一 | F36: 137.9 | H36: =AVERAGEIF(F36:F65,"<>0") -> 140.37333 | I36: =F36/$C$1 -> 0.91627907 | K36: =AVERAGEIF(I36:I65,"<>0") -> 0.93271318 | L36: 0.0024385846 | N36: =AVERAGEIF(L36:L65,"<>0") -> 0.0024304511 | O36: 0.0078388225 | Q36: =AVERAGEIF(O36:O65,"<>0") -> 0.0076554308 | R36: =(10-2)/10 -> 0.8 | T36: =AVERAGEIF(R36:R65,"<>0") -> 0.8 | U36: 0.66666667 | W36: =AVERAGEIF(U36:U65,"<>0") -> 0.69868889
D37: 45902 | E37: 二 | F37: 136.9 | G37: =AVERAGE(F37:F43) -> 137.05714 | I37: =F37/$C$1 -> 0.90963455 | J37: =AVERAGE(I37:I43) -> 0.91067869 | L37: 0.0024493122 | M37: =AVERAGE(L37:L43) -> 0.0024304197 | O37: 0.0078141759 | P37: =AVERAGE(O37:O43) -> 0.0077841864 | R37: =(10-2)/10 -> 0.8 | S37: =AVERAGE(R37:R43) -> 0.8 | U37: 0.667 | V37: =AVERAGE(U37:U43) -> 0.667
D38: 45903 | E38: 三 | F38: 137 | I38: =F38/$C$1 -> 0.910299 | L38: 0.0024435314 | O38: 0.0075679299 | R38: =(10-2)/10 -> 0.8 | U38: 0.667
D39: 45904 | E39: 四 | F39: 137.4 | I39: =F39/$C$1 -> 0.91295681 | L39: 0.0024319417 | O39: 0.0077711837 | R39: =(10-2)/10 -> 0.8 | U39: 0.667
D40: 45905 | E40: 五 | F40: 137 | I40: =F40/$C$1 -> 0.910299 | L40: 0.0024020072 | O40: 0.0077562492 | R40: =(10-2)/10 -> 0.8 | U40: 0.667
...

Sheet （３）業績構成比
B2: （3）業績構成比
B3: 資料繳交日 | C3: 月份 | D3: 日期 | F3: 營業額 | I3: 品類業績
I4: 主食 | O4: 便當 | Q4: 熱食義麵 | S4: 季節調理麵 | U4: 微波小吃 | W4: 三明治 | Y4: 調理麵包 | AA4: 沙拉
F5: 日 | G5: 週累積 | H5: 月累積 | I5: 一配 | K5: 二配 | M5: 合計 | O5: 一配 | Q5: 一配 | S5: 一配 | U5: 一配 | W5: 一配 | Y5: 一配 | AA5: 一配
I6: 業績(元) | J6: 比例(%) | K6: 業績(元) | L6: 比例(%) | M6: 業績(元) | N6: 比例(%) | O6: 業績(元) | P6: 比例(%) | Q6: 業績(元) | R6: 比例(%) | S6: 業績(元) | T6: 比例(%) | U6: 業績(元) | V6: 比例(%) | W6: 業績(元) | X6: 比例(%) | Y6: 業績(元) | Z6: 比例(%) | AA6: 業績(元) | AB6: 比例(%)
B7: =D19 -> 45882 | C7: 八 | D7: 45870 | E7: 五 | F7: =SUM(M7,Q7,S7,U7,W7,Y7,AA7) -> 4376902.4 | G7: =SUM(F7:F10) -> 20827993 | H7: =SUM(F7:F37) -> 1.7063649e+08 | I7: 372515.59 | J7: =I7/$F7 -> 0.085109412 | K7: 888085.12 | L7: =K7/$F7 -> 0.20290266 | M7: =SUM(I7+K7) -> 1260600.7 | N7: =M7/$F7 -> 0.28801207 | P7: =O7/$F7 -> 0 | R7: =Q7/$F7 -> 0 | T7: =S7/$F7 -> 0 | U7: 105036.38 | V7: =U7/$F7 -> 0.02399788 | W7: 1263256.8 | X7: =W7/$F7 -> 0.28861892 | Y7: 865376.31 | Z7: =Y7/$F7 -> 0.19771433 | AA7: 882632.15 | AB7: =AA7/$F7 -> 0.20165681
D8: 45871 | E8: 六 | F8: =SUM(M8,Q8,S8,U8,W8,Y8,AA8) -> 4635761.7 | I8: 405225.99 | J8: =I8/$F8 -> 0.087413032 | K8: 1044135.4 | L8: =K8/$F8 -> 0.22523492 | M8: =SUM(I8+K8) -> 1449361.4 | N8: =M8/$F8 -> 0.31264796 | P8: =O8/$F8 -> 0 | R8: =Q8/$F8 -> 0 | T8: =S8/$F8 -> 0 | U8: 113598.28 | V8: =U8/$F8 -> 0.024504771 | W8: 1270206.8 | X8: =W8/$F8 -> 0.27400174 | Y8: 895354.32 | Z8: =Y8/$F8 -> 0.19314071 | AA8: 907240.95 | AB8: =AA8/$F8 -> 0.19570483
D9: 45872 | E9: 日 | F9: =SUM(M9,Q9,S9,U9,W9,Y9,AA9) -> 5941913.1 | I9: 523628.12 | J9: =I9/$F9 -> 0.088124499 | K9: 1190992.3 | L9: =K9/$F9 -> 0.20043919 | M9: =SUM(I9+K9) -> 1714620.4 | N9: =M9/$F9 -> 0.28856369 | P9: =O9/$F9 -> 0 | R9: =Q9/$F9 -> 0 | T9: =S9/$F9 -> 0 | U9: 136925.1 | V9: =U9/$F9 -> 0.023043942 | W9: 1806951.1 | X9: =W9/$F9 -> 0.30410258 | Y9: 1090606.4 | Z9: =Y9/$F9 -> 0.18354466 | AA9: 1192810.1 | AB9: =AA9/$F9 -> 0.20074513
D10: 45873 | E10: 一 | F10: =SUM(M10,Q10,S10,U10,W10,Y10,AA10) -> 5873416.1 | I10: 511960.82 | J10: =I10/$F10 -> 0.087165767 | K10: 1161653.8 | L10: =K10/$F10 -> 0.19778163 | M10: =SUM(I10+K10) -> 1673614.6 | N10: =M10/$F10 -> 0.28494739 | P10: =O10/$F10 -> 0 | R10: =Q10/$F10 -> 0 | T10: =S10/$F10 -> 0 | U10: 131825.68 | V10: =U10/$F10 -> 0.022444465 | W10: 1829451.6 | X10: =W10/$F10 -> 0.31148 | Y10: 1067402 | Z10: =Y10/$F10 -> 0.18173444 | AA10: 1171122.2 | AB10: =AA10/$F10 -> 0.19939371
D11: 45874 | E11: 二 | F11: =SUM(M11,Q11,S11,U11,W11,Y11,AA11) -> 6182700.1 | G11: =SUM(F11:F17) -> 38973977 | I11: 459052.54 | J11: =I11/$F11 -> 0.074247906 | K11: 1163567.9 | L11: =K11/$F11 -> 0.18819738 | M11: =SUM(I11+K11) -> 1622620.5 | N11: =M11/$F11 -> 0.26244528 | P11: =O11/$F11 -> 0 | R11: =Q11/$F11 -> 0 | T11: =S11/$F11 -> 0 | U11: 132296.62 | V11: =U11/$F11 -> 0.021397871 | W11: 2146003.2 | X11: =W11/$F11 -> 0.34709805 | Y11: 1162367.8 | Z11: =Y11/$F11 -> 0.18800327 | AA11: 1119412 | AB11: =AA11/$F11 -> 0.18105553
D12: 45875 | E12: 三 | F12: =SUM(M12,Q12,S12,U12,W12,Y12,AA12) -> 6008483.6 | I12: 452918.16 | J12: =I12/$F12 -> 0.075379778 | K12: 1130580.7 | L12: =K12/$F12 -> 0.18816406 | M12: =SUM(I12+K12) -> 1583498.8 | N12: =M12/$F12 -> 0.26354384 | P12: =O12/$F12 -> 0 | R12: =Q12/$F12 -> 0 | T12: =S12/$F12 -> 0 | U12: 132169.34 | V12: =U12/$F12 -> 0.021997121 | W12: 2006641.3 | X12: =W12/$F12 -> 0.33396801 | Y12: 1155171.8 | Z12: =Y12/$F12 -> 0.1922568 | AA12: 1131002.3 | AB12: =AA12/$F12 -> 0.18823424
D13: 45876 | E13: 四 | F13: =SUM(M13,Q13,S13,U13,W13,Y13,AA13) -> 5578775.7 | I13: 432857.18 | J13: =I13/$F13 -> 0.077589995 | K13: 973130.68 | L13: =K13/$F13 -> 0.17443445 | M13: =SUM(I13+K13) -> 1405987.9 | N13: =M13/$F13 -> 0.25202445 | P13: =O13/$F13 -> 0 | R13: =Q13/$F13 -> 0 | T13: =S13/$F13 -> 0 | U13: 122332.16 | V13: =U13/$F13 -> 0.021928137 | W13: 1882360.8 | X13: =W13/$F13 -> 0.33741467 | Y13: 1070508.3 | Z13: =Y13/$F13 -> 0.19188946 | AA13: 1097586.6 | AB13: =AA13/$F13 -> 0.19674328
D14: 45877 | E14: 五 | F14: =SUM(M14,Q14,S14,U14,W14,Y14,AA14) -> 4540704.5 | I14: 355964.38 | J14: =I14/$F14 -> 0.078394087 | K14: 897669.55 | L14: =K14/$F14 -> 0.1976939 | M14: =SUM(I14+K14) -> 1253633.9 | N14: =M14/$F14 -> 0.27608798 | P14: =O14/$F14 -> 0 | R14: =Q14/$F14 -> 0 | T14: =S14/$F14 -> 0 | U14: 105236.76 | V14: =U14/$F14 -> 0.023176307 | W14: 1407850.3 | X14: =W14/$F14 -> 0.31005107 | Y14: 862332.2 | Z14: =Y14/$F14 -> 0.18991155 | AA14: 911651.3 | AB14: =AA14/$F14 -> 0.2007731
D15: 45878 | E15: 六 | F15: =SUM(M15,Q15,S15,U15,W15,Y15,AA15) -> 4698363 | I15: 371298.21 | J15: =I15/$F15 -> 0.079027145 | K15: 1030206.9 | L15: =K15/$F15 -> 0.21926932 | M15: =SUM(I15+K15) -> 1401505.1 | N15: =M15/$F15 -> 0.29829647 | P15: =O15/$F15 -> 0 | R15: =Q15/$F15 -> 0 | T15: =S15/$F15 -> 0 | U15: 110372.12 | V15: =U15/$F15 -> 0.023491612 | W15: 1420694.7 | X15: =W15/$F15 -> 0.3023808 | Y15: 849989.61 | Z15: =Y15/$F15 -> 0.18091187 | AA15: 915801.42 | AB15: =AA15/$F15 -> 0.19491926
D16: 45879 | E16: 日 | F16: =SUM(M16,Q16,S16,U16,W16,Y16,AA16) -> 6020434.1 | I16: 497251.32 | J16: =I16/$F16 -> 0.082593931 | K16: 1118899.8 | L16: =K16/$F16 -> 0.18585034 | M16: =SUM(I16+K16) -> 1616151.1 | N16: =M16/$F16 -> 0.26844428 | P16: =O16/$F16 -> 0 | R16: =Q16/$F16 -> 0 | T16: =S16/$F16 -> 0 | U16: 132622.92 | V16: =U16/$F16 -> 0.022028797 | W16: 2019966.6 | X16: =W16/$F16 -> 0.33551843 | Y16: 1063964.8 | Z16: =Y16/$F16 -> 0.17672559 | AA16: 1187728.7 | AB16: =AA16/$F16 -> 0.19728291
D17: 45880 | E17: 一 | F17: =SUM(M17,Q17,S17,U17,W17,Y17,AA17) -> 5944516 | I17: 480214.93 | J17: =I17/$F17 -> 0.080782847 | K17: 1101753.6 | L17: =K17/$F17 -> 0.18533949 | M17: =SUM(I17+K17) -> 1581968.5 | N17: =M17/$F17 -> 0.26612234 | P17: =O17/$F17 -> 0 | R17: =Q17/$F17 -> 0 | T17: =S17/$F17 -> 0 | U17: 125259.26 | V17: =U17/$F17 -> 0.021071398 | W17: 2011777.6 | X17: =W17/$F17 -> 0.3384258 | Y17: 1059609.7 | Z17: =Y17/$F17 -> 0.17824996 | AA17: 1165900.9 | AB17: =AA17/$F17 -> 0.19613051
B18: =D26 -> 45889 | D18: 45881 | E18: 二 | F18: =SUM(M18,Q18,S18,U18,W18,Y18,AA18) -> 5571060 | G18: =SUM(F18:F24) -> 36769734 | I18: 460679.93 | J18: =I18/$F18 -> 0.082691612 | K18: 1106375.6 | L18: =K18/$F18 -> 0.19859337 | M18: =SUM(I18+K18) -> 1567055.5 | N18: =M18/$F18 -> 0.28128498 | P18: =O18/$F18 -> 0 | R18: =Q18/$F18 -> 0 | T18: =S18/$F18 -> 0 | U18: 128326.04 | V18: =U18/$F18 -> 0.023034403 | W18: 1791243 | X18: =W18/$F18 -> 0.32152642 | Y18: 1005441.2 | Z18: =Y18/$F18 -> 0.18047575 | AA18: 1078994.2 | AB18: =AA18/$F18 -> 0.19367844
D19: 45882 | E19: 三 | F19: =SUM(M19,Q19,S19,U19,W19,Y19,AA19) -> 5601894.3 | I19: 427993.78 | J19: =I19/$F19 -> 0.076401617 | K19: 1086150.7 | L19: =K19/$F19 -> 0.1938899 | M19: =SUM(I19+K19) -> 1514144.5 | N19: =M19/$F19 -> 0.27029151 | P19: =O19/$F19 -> 0 | R19: =Q19/$F19 -> 0 | T19: =S19/$F19 -> 0 | U19: 135082.58 | V19: =U19/$F19 -> 0.024113732 | W19: 1804961.4 | X19: =W19/$F19 -> 0.32220554 | Y19: 1028716.8 | Z19: =Y19/$F19 -> 0.1836373 | AA19: 1118989.1 | AB19: =AA19/$F19 -> 0.19975191
D20: 45883 | E20: 四 | F20: =SUM(M20,Q20,S20,U20,W20,Y20,AA20) -> 5220507.7 | I20: 383265.48 | J20: =I20/$F20 -> 0.073415365 | K20: 964763.4 | L20: =K20/$F20 -> 0.1848026 | M20: =SUM(I20+K20) -> 1348028.9 | N20: =M20/$F20 -> 0.25821797 | P20: =O20/$F20 -> 0 | R20: =Q20/$F20 -> 0 | T20: =S20/$F20 -> 0 | U20: 127451.52 | V20: =U20/$F20 -> 0.024413626 | W20: 1684528.2 | X20: =W20/$F20 -> 0.32267517 | Y20: 982165.65 | Z20: =Y20/$F20 -> 0.18813604 | AA20: 1078333.4 | AB20: =AA20/$F20 -> 0.20655719
D21: 45884 | E21: 五 | F21: =SUM(M21,Q21,S21,U21,W21,Y21,AA21) -> 4456648 | I21: 322573.95 | J21: =I21/$F21 -> 0.072380396 | K21: 940366.55 | L21: =K21/$F21 -> 0.2110031 | M21: =SUM(I21+K21) -> 1262940.5 | N21: =M21/$F21 -> 0.2833835 | P21: =O21/$F21 -> 0 | R21: =Q21/$F21 -> 0 | T21: =S21/$F21 -> 0 | U21: 116160.66 | V21: =U21/$F21 -> 0.02606458 | W21: 1317139 | X21: =W21/$F21 -> 0.29554477 | Y21: 852684.58 | Z21: =Y21/$F21 -> 0.19132868 | AA21: 907723.26 | AB21: =AA21/$F21 -> 0.20367847
D22: 45885 | E22: 六 | F22: =SUM(M22,Q22,S22,U22,W22,Y22,AA22) -> 4483117.5 | I22: 324249.31 | J22: =I22/$F22 -> 0.072326748 | K22: 1031142.4 | L22: =K22/$F22 -> 0.23000565 | M22: =SUM(I22+K22) -> 1355391.7 | N22: =M22/$F22 -> 0.3023324 | P22: =O22/$F22 -> 0 | R22: =Q22/$F22 -> 0 | T22: =S22/$F22 -> 0 | U22: 111258.12 | V22: =U22/$F22 -> 0.024817132 | W22: 1316018.7 | X22: =W22/$F22 -> 0.2935499 | Y22: 863058.71 | Z22: =Y22/$F22 -> 0.19251307 | AA22: 837390.29 | AB22: =AA22/$F22 -> 0.1867875
D23: 45886 | E23: 日 | F23: =SUM(M23,Q23,S23,U23,W23,Y23,AA23) -> 5735188.3 | I23: 411696.6 | J23: =I23/$F23 -> 0.071784322 | K23: 1150121.2 | L23: =K23/$F23 -> 0.20053765 | M23: =SUM(I23+K23) -> 1561817.8 | N23: =M23/$F23 -> 0.27232197 | P23: =O23/$F23 -> 0 | R23: =Q23/$F23 -> 0 | T23: =S23/$F23 -> 0 | U23: 133100.62 | V23: =U23/$F23 -> 0.023207716 | W23: 1871886.6 | X23: =W23/$F23 -> 0.32638624 | Y23: 1072765.5 | Z23: =Y23/$F23 -> 0.18704974 | AA23: 1095617.9 | AB23: =AA23/$F23 -> 0.19103433
D24: 45887 | E24: 一 | F24: =SUM(M24,Q24,S24,U24,W24,Y24,AA24) -> 5701317.8 | I24: 403315.41 | J24: =I24/$F24 -> 0.070740734 | K24: 1115944.5 | L24: =K24/$F24 -> 0.19573448 | M24: =SUM(I24+K24) -> 1519259.9 | N24: =M24/$F24 -> 0.26647521 | P24: =O24/$F24 -> 0 | R24: =Q24/$F24 -> 0 | T24: =S24/$F24 -> 0 | U24: 129199.2 | V24: =U24/$F24 -> 0.022661287 | W24: 1906687.8 | X24: =W24/$F24 -> 0.33442931 | Y24: 1065194.1 | Z24: =Y24/$F24 -> 0.18683296 | AA24: 1080976.8 | AB24: =AA24/$F24 -> 0.18960122
B25: =D26 -> 45889 | D25: 45888 | E25: 二 | F25: =SUM(M25,Q25,S25,U25,W25,Y25,AA25,O25) -> 6939236.5 | G25: =SUM(F25:F31) -> 41790039 | I25: 391106.51 | J25: =I25/$F25 -> 0.056361605 | K25: 1139309 | L25: =K25/$F25 -> 0.16418362 | M25: =SUM(I25+K25) -> 1530415.5 | N25: =M25/$F25 -> 0.22054522 | O25: 860084.75 | P25: =O25/$F25 -> 0.12394516 | R25: =Q25/$F25 -> 0 | T25: =S25/$F25 -> 0 | U25: 132364.08 | V25: =U25/$F25 -> 0.019074732 | W25: 2072437.2 | X25: =W25/$F25 -> 0.29865493 | Y25: 1345441.9 | Z25: =Y25/$F25 -> 0.19388904 | AA25: 998493.1 | AB25: =AA25/$F25 -> 0.14389092
D26: 45889 | E26: 三 | F26: =SUM(M26,Q26,S26,U26,W26,Y26,AA26,O26) -> 6333786.4 | I26: 383099.98 | J26: =I26/$F26 -> 0.060485144 | K26: 1054399.7 | L26: =K26/$F26 -> 0.16647225 | M26: =SUM(I26+K26) -> 1437499.6 | N26: =M26/$F26 -> 0.22695739 | O26: 550695.95 | P26: =O26/$F26 -> 0.086945773 | R26: =Q26/$F26 -> 0 | T26: =S26/$F26 -> 0 | U26: 135241.62 | V26: =U26/$F26 -> 0.021352413 | W26: 1974722.6 | X26: =W26/$F26 -> 0.311776 | Y26: 1222776.3 | Z26: =Y26/$F26 -> 0.19305614 | AA26: 1012850.3 | AB26: =AA26/$F26 -> 0.15991229
D27: 45890 | E27: 四 | F27: =SUM(M27,Q27,S27,U27,W27,Y27,AA27,O27) -> 5963895.7 | I27: 346214.05 | J27: =I27/$F27 -> 0.058051661 | K27: 919375.91 | L27: =K27/$F27 -> 0.15415694 | M27: =SUM(I27+K27) -> 1265590 | N27: =M27/$F27 -> 0.2122086 | O27: 574464.1 | P27: =O27/$F27 -> 0.096323634 | R27: =Q27/$F27 -> 0 | T27: =S27/$F27 -> 0 | U27: 133785.56 | V27: =U27/$F27 -> 0.022432579 | W27: 1902200.4 | X27: =W27/$F27 -> 0.31895266 | Y27: 1131054.8 | Z27: =Y27/$F27 -> 0.18965033 | AA27: 956800.9 | AB27: =AA27/$F27 -> 0.1604322
D28: 45891 | E28: 五 | F28: =SUM(M28,Q28,S28,U28,W28,Y28,AA28,O28) -> 4909451 | I28: 282736.28 | J28: =I28/$F28 -> 0.057590203 | K28: 866178.92 | L28: =K28/$F28 -> 0.17643091 | M28: =SUM(I28+K28) -> 1148915.2 | N28: =M28/$F28 -> 0.23402112 | O28: 575090.55 | P28: =O28/$F28 -> 0.11713948 | R28: =Q28/$F28 -> 0 | T28: =S28/$F28 -> 0 | U28: 116678.78 | V28: =U28/$F28 -> 0.023766156 | W28: 1402007.5 | X28: =W28/$F28 -> 0.28557317 | Y28: 869601.73 | Z28: =Y28/$F28 -> 0.1771281 | AA28: 797157.24 | AB28: =AA28/$F28 -> 0.16237197
D29: 45892 | E29: 六 | F29: =SUM(M29,Q29,S29,U29,W29,Y29,AA29,O29) -> 5147138.7 | I29: 294074.44 | J29: =I29/$F29 -> 0.057133576 | K29: 1029693.9 | L29: =K29/$F29 -> 0.20005172 | M29: =SUM(I29+K29) -> 1323768.4 | N29: =M29/$F29 -> 0.25718529 | O29: 556244.82 | P29: =O29/$F29 -> 0.10806875 | R29: =Q29/$F29 -> 0 | T29: =S29/$F29 -> 0 | U29: 120447.62 | V29: =U29/$F29 -> 0.023400889 | W29: 1424678.9 | X29: =W29/$F29 -> 0.27679047 | Y29: 901832.65 | Z29: =Y29/$F29 -> 0.17521048 | AA29: 820166.29 | AB29: =AA29/$F29 -> 0.15934412
D30: 45893 | E30: 日 | F30: =SUM(M30,Q30,S30,U30,W30,Y30,AA30,O30) -> 6385967.1 | I30: 383618.07 | J30: =I30/$F30 -> 0.06007204 | K30: 1118037.3 | L30: =K30/$F30 -> 0.1750772 | M30: =SUM(I30+K30) -> 1501655.3 | N30: =M30/$F30 -> 0.23514924 | O30: 469030.5 | P30: =O30/$F30 -> 0.073447058 | R30: =Q30/$F30 -> 0 | T30: =S30/$F30 -> 0 | U30: 147674.06 | V30: =U30/$F30 -> 0.023124776 | W30: 2028552.9 | X30: =W30/$F30 -> 0.31765791 | Y30: 1155014.8 | Z30: =Y30/$F30 -> 0.18086764 | AA30: 1084039.5 | AB30: =AA30/$F30 -> 0.16975338
D31: 45894 | E31: 一 | F31: =SUM(M31,Q31,S31,U31,W31,Y31,AA31,O31) -> 6110563.6 | I31: 380873.35 | J31: =I31/$F31 -> 0.062330314 | K31: 1130537.5 | L31: =K31/$F31 -> 0.18501362 | M31: =SUM(I31+K31) -> 1511410.9 | N31: =M31/$F31 -> 0.24734393 | O31: 361280.25 | P31: =O31/$F31 -> 0.059123883 | R31: =Q31/$F31 -> 0 | T31: =S31/$F31 -> 0 | U31: 144334.48 | V31: =U31/$F31 -> 0.023620486 | W31: 2014012.7 | X31: =W31/$F31 -> 0.32959525 | Y31: 1018455.3 | Z31: =Y31/$F31 -> 0.16667125 | AA31: 1061070.1 | AB31: =AA31/$F31 -> 0.1736452
B32: =D40 -> 45903 | D32: 45895 | E32: 二 | F32: =SUM(M32,Q32,S32,U32,W32,Y32,AA32,O32) -> 5751890.8 | G32: =SUM(F32:F38) -> 38277517 | I32: 375740.98 | J32: =I32/$F32 -> 0.065324776 | K32: 1086162.5 | L32: =K32/$F32 -> 0.18883573 | M32: =SUM(I32+K32) -> 1461903.5 | N32: =M32/$F32 -> 0.2541605 | O32: 303644.43 | P32: =O32/$F32 -> 0.052790367 | R32: =Q32/$F32 -> 0 | T32: =S32/$F32 -> 0 | U32: 139102.14 | V32: =U32/$F32 -> 0.024183724 | W32: 1861457.6 | X32: =W32/$F32 -> 0.32362534 | Y32: 984346.63 | Z32: =Y32/$F32 -> 0.17113444 | AA32: 1001436.5 | AB32: =AA32/$F32 -> 0.17410562
D33: 45896 | E33: 三 | F33: =SUM(M33,Q33,S33,U33,W33,Y33,AA33,O33) -> 5656058.4 | I33: 355805.25 | J33: =I33/$F33 -> 0.062906927 | K33: 1009049.3 | L33: =K33/$F33 -> 0.1784015 | M33: =SUM(I33+K33) -> 1364854.6 | N33: =M33/$F33 -> 0.24130843 | O33: 304996.59 | P33: =O33/$F33 -> 0.053923876 | R33: =Q33/$F33 -> 0 | T33: =S33/$F33 -> 0 | U33: 138139.88 | V33: =U33/$F33 -> 0.024423348 | W33: 1843223.1 | X33: =W33/$F33 -> 0.32588474 | Y33: 998910.96 | Z33: =Y33/$F33 -> 0.17660903 | AA33: 1005933.3 | AB33: =AA33/$F33 -> 0.17785058
D34: 45897 | E34: 四 | F34: =SUM(M34,Q34,S34,U34,W34,Y34,AA34,O34) -> 5359266.3 | I34: 323566.18 | J34: =I34/$F34 -> 0.060375089 | K34: 928178.23 | L34: =K34/$F34 -> 0.17319129 | M34: =SUM(I34+K34) -> 1251744.4 | N34: =M34/$F34 -> 0.23356638 | O34: 305672.67 | P34: =O34/$F34 -> 0.05703629 | R34: =Q34/$F34 -> 0 | T34: =S34/$F34 -> 0 | U34: 131815.86 | V34: =U34/$F34 -> 0.024595878 | W34: 1731377.2 | X34: =W34/$F34 -> 0.32306235 | Y34: 978404.63 | Z34: =Y34/$F34 -> 0.18256317 | AA34: 960251.57 | AB34: =AA34/$F34 -> 0.17917594
D35: 45898 | E35: 五 | F35: =SUM(M35,Q35,S35,U35,W35,Y35,AA35,O35) -> 4553981.3 | I35: 278500.73 | J35: =I35/$F35 -> 0.061155441 | K35: 888931.77 | L35: =K35/$F35 -> 0.19519882 | M35: =SUM(I35+K35) -> 1167432.5 | N35: =M35/$F35 -> 0.25635426 | O35: 260544.33 | P35: =O35/$F35 -> 0.057212429 | R35: =Q35/$F35 -> 0 | T35: =S35/$F35 -> 0 | U35: 117064.56 | V35: =U35/$F35 -> 0.025705982 | W35: 1343987.6 | X35: =W35/$F35 -> 0.29512366 | Y35: 836771 | Z35: =Y35/$F35 -> 0.18374494 | AA35: 828181.25 | AB35: =AA35/$F35 -> 0.18185873
D36: 45899 | E36: 六 | F36: =SUM(M36,Q36,S36,U36,W36,Y36,AA36,O36) -> 4840642 | I36: 298825.06 | J36: =I36/$F36 -> 0.061732526 | K36: 1089823.6 | L36: =K36/$F36 -> 0.2251403 | M36: =SUM(I36+K36) -> 1388648.7 | N36: =M36/$F36 -> 0.28687283 | O36: 243050.76 | P36: =O36/$F36 -> 0.050210439 | R36: =Q36/$F36 -> 0 | T36: =S36/$F36 -> 0 | U36: 129707.64 | V36: =U36/$F36 -> 0.026795545 | W36: 1356114.9 | X36: =W36/$F36 -> 0.28015186 | Y36: 878969.04 | Z36: =Y36/$F36 -> 0.18158109 | AA36: 844151.06 | AB36: =AA36/$F36 -> 0.17438824
D37: 45900 | E37: 日 | F37: =SUM(M37,Q37,S37,U37,W37,Y37,AA37,O37) -> 6112909.4 | I37: 386861.84 | J37: =I37/$F37 -> 0.063286042 | K37: 1133721.1 | L37: =K37/$F37 -> 0.18546343 | M37: =SUM(I37+K37) -> 1520583 | N37: =M37/$F37 -> 0.24874947 | O37: 276432.21 | P37: =O37/$F37 -> 0.045221055 | R37: =Q37/$F37 -> 0 | T37: =S37/$F37 -> 0 | U37: 152575.58 | V37: =U37/$F37 -> 0.024959568 | W37: 1967941.3 | X37: =W37/$F37 -> 0.32193203 | Y37: 1092110.8 | Z37: =Y37/$F37 -> 0.17865647 | AA37: 1103266.4 | AB37: =AA37/$F37 -> 0.1804814
C38: 九 | D38: 45901 | E38: 一 | F38: =SUM(M38,Q38,S38,U38,W38,Y38,AA38,O38) -> 6002768.9 | H38: =SUM(F38:F67) -> 1.6954486e+08 | I38: 379960.05 | J38: =I38/$F38 -> 0.063297464 | K38: 1160941 | L38: =K38/$F38 -> 0.19340091 | M38: =SUM(I38+K38) -> 1540901 | N38: =M38/$F38 -> 0.25669838 | O38: 236797.02 | P38: =O38/$F38 -> 0.039447965 | R38: =Q38/$F38 -> 0 | T38: =S38/$F38 -> 0 | U38: 149127.98 | V38: =U38/$F38 -> 0.024843198 | W38: 1945256.4 | X38: =W38/$F38 -> 0.32405984 | Y38: 1059370.1 | Z38: =Y38/$F38 -> 0.17648023 | AA38: 1071316.5 | AB38: =AA38/$F38 -> 0.17847038
D39: 45902 | E39: 二 | F39: =SUM(M39,Q39,S39,U39,W39,Y39,AA39,O39) -> 6639488.4 | G39: =SUM(F39:F45) -> 40192283 | I39: 642171.27 | J39: =I39/$F39 -> 0.096719993 | K39: 1150709.1 | L39: =K39/$F39 -> 0.17331292 | M39: =SUM(I39+K39) -> 1792880.4 | N39: =M39/$F39 -> 0.27003292 | O39: 205950.87 | P39: =O39/$F39 -> 0.031019087 | R39: =Q39/$F39 -> 0 | T39: =S39/$F39 -> 0 | U39: 140033.76 | V39: =U39/$F39 -> 0.021091047 | W39: 2126449.5 | X39: =W39/$F39 -> 0.3202731 | Y39: 1042351.9 | Z39: =Y39/$F39 -> 0.1569928 | AA39: 1331821.9 | AB39: =AA39/$F39 -> 0.20059105
D40: 45903 | E40: 三 | F40: =SUM(M40,Q40,S40,U40,W40,Y40,AA40,O40) -> 6228436.4 | I40: 596146.7 | J40: =I40/$F40 -> 0.095713701 | K40: 1051043.3 | L40: =K40/$F40 -> 0.16874914 | M40: =SUM(I40+K40) -> 1647190 | N40: =M40/$F40 -> 0.26446284 | O40: 169696.08 | P40: =O40/$F40 -> 0.027245374 | R40: =Q40/$F40 -> 0 | T40: =S40/$F40 -> 0 | U40: 144052.54 | V40: =U40/$F40 -> 0.023128203 | W40: 2021656.6 | X40: =W40/$F40 -> 0.32458493 | Y40: 1018128.1 | Z40: =Y40/$F40 -> 0.16346448 | AA40: 1227713.1 | AB40: =AA40/$F40 -> 0.19711417
D41: 45904 | E41: 四 | F41: =SUM(M41,Q41,S41,U41,W41,Y41,AA41,O41) -> 5632441.8 | I41: 465250.56 | J41: =I41/$F41 -> 0.082601929 | K41: 867218.43 | L41: =K41/$F41 -> 0.15396847 | M41: =SUM(I41+K41) -> 1332469 | N41: =M41/$F41 -> 0.2365704 | O41: 155836.44 | P41: =O41/$F41 -> 0.027667652 | R41: =Q41/$F41 -> 0 | T41: =S41/$F41 -> 0 | U41: 134755.46 | V41: =U41/$F41 -> 0.023924874 | W41: 1911944.3 | X41: =W41/$F41 -> 0.33945212 | Y41: 940100.69 | Z41: =Y41/$F41 -> 0.16690819 | AA41: 1157335.9 | AB41: =AA41/$F41 -> 0.20547676
...

Sheet （４）訂單數量構成比
B2: （4）訂單數量構成比
B3: 資料繳交日 | C3: 月份 | D3: 日期 | F3: 訂單量 | I3: 品類訂單量
I4: 主食 | O4: 便當 | Q4: 熱食義麵 | S4: 季節調理麵 | U4: 微波小吃 | W4: 三明治 | Y4: 調理麵包 | AA4: 沙拉
F5: 日 | G5: 週累積 | H5: 月累積 | I5: 一配 | K5: 二配 | M5: 合計 | O5: 一配 | Q5: 一配 | S5: 一配 | U5: 一配 | W5: 一配 | Y5: 一配 | AA5: 一配
I6: 訂單數 | J6: 比例(%) | K6: 訂單數 | L6: 比例(%) | M6: 訂單數 | N6: 比例(%) | O6: 訂單數 | P6: 比例(%) | Q6: 訂單數 | R6: 比例(%) | S6: 訂單數 | T6: 比例(%) | U6: 訂單數 | V6: 比例(%) | W6: 訂單數 | X6: 比例(%) | Y6: 訂單數 | Z6: 比例(%) | AA6: 訂單數 | AB6: 比例(%)
B7: =D19 -> 45882 | C7: 八 | D7: 45870 | E7: 五 | F7: =SUM(M7,Q7,S7,U7,W7,Y7,AA7) -> 126626 | G7: =SUM(F7:F10) -> 603449 | H7: =SUM(F7:F37) -> 4956065 | I7: 6647 | J7: =I7/$F$7 -> 0.052493169 | K7: 16877 | L7: =K7/$F$7 -> 0.13328226 | M7: =SUM(I7+K7) -> 23524 | N7: =M7/$F$7 -> 0.18577543 | P7: =O7/$F$7 -> 0 | R7: =Q7/$F$7 -> 0 | T7: =S7/$F$7 -> 0 | U7: 2514 | V7: =U7/$F$7 -> 0.019853743 | W7: 50685 | X7: =W7/$F$7 -> 0.40027325 | Y7: 27599 | Z7: =Y7/$F$7 -> 0.21795682 | AA7: 22304 | AB7: =AA7/$F$7 -> 0.17614076
D8: 45871 | E8: 六 | F8: =SUM(M8,Q8,S8,U8,W8,Y8,AA8) -> 132231 | I8: 7221 | J8: =I8/$F$7 -> 0.057026203 | K8: 19863 | L8: =K8/$F$7 -> 0.15686352 | M8: =SUM(I8+K8) -> 27084 | N8: =M8/$F$7 -> 0.21388972 | P8: =O8/$F$7 -> 0 | R8: =Q8/$F$7 -> 0 | T8: =S8/$F$7 -> 0 | U8: 2721 | V8: =U8/$F$7 -> 0.021488478 | W8: 50980 | X8: =W8/$F$7 -> 0.40260294 | Y8: 28528 | Z8: =Y8/$F$7 -> 0.22529338 | AA8: 22918 | AB8: =AA8/$F$7 -> 0.18098969
D9: 45872 | E9: 日 | F9: =SUM(M9,Q9,S9,U9,W9,Y9,AA9) -> 172946 | I9: 9328 | J9: =I9/$F$7 -> 0.073665756 | K9: 22654 | L9: =K9/$F$7 -> 0.17890481 | M9: =SUM(I9+K9) -> 31982 | N9: =M9/$F$7 -> 0.25257056 | P9: =O9/$F$7 -> 0 | R9: =Q9/$F$7 -> 0 | T9: =S9/$F$7 -> 0 | U9: 3271 | V9: =U9/$F$7 -> 0.025831978 | W9: 72638 | X9: =W9/$F$7 -> 0.57364206 | Y9: 34986 | Z9: =Y9/$F$7 -> 0.27629397 | AA9: 30069 | AB9: =AA9/$F$7 -> 0.23746308
D10: 45873 | E10: 一 | F10: =SUM(M10,Q10,S10,U10,W10,Y10,AA10) -> 171646 | I10: 9114 | J10: =I10/$F$7 -> 0.07197574 | K10: 22093 | L10: =K10/$F$7 -> 0.17447444 | M10: =SUM(I10+K10) -> 31207 | N10: =M10/$F$7 -> 0.24645018 | P10: =O10/$F$7 -> 0 | R10: =Q10/$F$7 -> 0 | T10: =S10/$F$7 -> 0 | U10: 3152 | V10: =U10/$F$7 -> 0.024892202 | W10: 73508 | X10: =W10/$F$7 -> 0.58051269 | Y10: 34242 | Z10: =Y10/$F$7 -> 0.2704184 | AA10: 29537 | AB10: =AA10/$F$7 -> 0.23326173
D11: 45874 | E11: 二 | F11: =SUM(M11,Q11,S11,U11,W11,Y11,AA11) -> 185947 | G11: =SUM(F11:F17) -> 1159872 | I11: 8179 | J11: =I11/$F$7 -> 0.06459179 | K11: 22129 | L11: =K11/$F$7 -> 0.17475874 | M11: =SUM(I11+K11) -> 30308 | N11: =M11/$F$7 -> 0.23935053 | P11: =O11/$F$7 -> 0 | R11: =Q11/$F$7 -> 0 | T11: =S11/$F$7 -> 0 | U11: 3165 | V11: =U11/$F$7 -> 0.024994867 | W11: 86711 | X11: =W11/$F$7 -> 0.68478038 | Y11: 37532 | Z11: =Y11/$F$7 -> 0.29640042 | AA11: 28231 | AB11: =AA11/$F$7 -> 0.22294789
D12: 45875 | E12: 三 | F12: =SUM(M12,Q12,S12,U12,W12,Y12,AA12) -> 179806 | I12: 8075 | J12: =I12/$F$7 -> 0.063770474 | K12: 21498 | L12: =K12/$F$7 -> 0.16977556 | M12: =SUM(I12+K12) -> 29573 | N12: =M12/$F$7 -> 0.23354603 | P12: =O12/$F$7 -> 0 | R12: =Q12/$F$7 -> 0 | T12: =S12/$F$7 -> 0 | U12: 3162 | V12: =U12/$F$7 -> 0.024971175 | W12: 81227 | X12: =W12/$F$7 -> 0.64147174 | Y12: 37322 | Z12: =Y12/$F$7 -> 0.294742 | AA12: 28522 | AB12: =AA12/$F$7 -> 0.225246
D13: 45876 | E13: 四 | F13: =SUM(M13,Q13,S13,U13,W13,Y13,AA13) -> 167846 | I13: 7726 | J13: =I13/$F$7 -> 0.061014326 | K13: 18509 | L13: =K13/$F$7 -> 0.14617061 | M13: =SUM(I13+K13) -> 26235 | N13: =M13/$F$7 -> 0.20718494 | P13: =O13/$F$7 -> 0 | R13: =Q13/$F$7 -> 0 | T13: =S13/$F$7 -> 0 | U13: 2924 | V13: =U13/$F$7 -> 0.023091624 | W13: 76327 | X13: =W13/$F$7 -> 0.6027751 | Y13: 34642 | Z13: =Y13/$F$7 -> 0.27357731 | AA13: 27718 | AB13: =AA13/$F$7 -> 0.21889659
D14: 45877 | E14: 五 | F14: =SUM(M14,Q14,S14,U14,W14,Y14,AA14) -> 133441 | I14: 6354 | J14: =I14/$F$7 -> 0.050179268 | K14: 17055 | L14: =K14/$F$7 -> 0.13468798 | M14: =SUM(I14+K14) -> 23409 | N14: =M14/$F$7 -> 0.18486725 | P14: =O14/$F$7 -> 0 | R14: =Q14/$F$7 -> 0 | T14: =S14/$F$7 -> 0 | U14: 2518 | V14: =U14/$F$7 -> 0.019885332 | W14: 56755 | X14: =W14/$F$7 -> 0.44820969 | Y14: 27718 | Z14: =Y14/$F$7 -> 0.21889659 | AA14: 23041 | AB14: =AA14/$F$7 -> 0.18196105
D15: 45878 | E15: 六 | F15: =SUM(M15,Q15,S15,U15,W15,Y15,AA15) -> 136383 | I15: 6627 | J15: =I15/$F$7 -> 0.052335223 | K15: 19571 | L15: =K15/$F$7 -> 0.15455752 | M15: =SUM(I15+K15) -> 26198 | N15: =M15/$F$7 -> 0.20689274 | P15: =O15/$F$7 -> 0 | R15: =Q15/$F$7 -> 0 | T15: =S15/$F$7 -> 0 | U15: 2642 | V15: =U15/$F$7 -> 0.020864593 | W15: 57207 | X15: =W15/$F$7 -> 0.45177926 | Y15: 27171 | Z15: =Y15/$F$7 -> 0.21457679 | AA15: 23165 | AB15: =AA15/$F$7 -> 0.18294031
D16: 45879 | E16: 日 | F16: =SUM(M16,Q16,S16,U16,W16,Y16,AA16) -> 179198 | I16: 8869 | J16: =I16/$F$7 -> 0.070040908 | K16: 21271 | L16: =K16/$F$7 -> 0.16798288 | M16: =SUM(I16+K16) -> 30140 | N16: =M16/$F$7 -> 0.23802379 | P16: =O16/$F$7 -> 0 | R16: =Q16/$F$7 -> 0 | T16: =S16/$F$7 -> 0 | U16: 3168 | V16: =U16/$F$7 -> 0.025018559 | W16: 81618 | X16: =W16/$F$7 -> 0.64455957 | Y16: 34318 | Z16: =Y16/$F$7 -> 0.27101859 | AA16: 29954 | AB16: =AA16/$F$7 -> 0.23655489
D17: 45880 | E17: 一 | F17: =SUM(M17,Q17,S17,U17,W17,Y17,AA17) -> 177251 | I17: 8564 | J17: =I17/$F$7 -> 0.06763224 | K17: 20943 | L17: =K17/$F$7 -> 0.16539257 | M17: =SUM(I17+K17) -> 29507 | N17: =M17/$F$7 -> 0.23302481 | P17: =O17/$F$7 -> 0 | R17: =Q17/$F$7 -> 0 | T17: =S17/$F$7 -> 0 | U17: 2992 | V17: =U17/$F$7 -> 0.023628639 | W17: 81203 | X17: =W17/$F$7 -> 0.6412822 | Y17: 34119 | Z17: =Y17/$F$7 -> 0.26944703 | AA17: 29430 | AB17: =AA17/$F$7 -> 0.23241672
B18: =D26 -> 45889 | D18: 45881 | E18: 二 | F18: =SUM(M18,Q18,S18,U18,W18,Y18,AA18) -> 163807 | G18: =SUM(F18:F24) -> 1082673 | I18: 8218 | J18: =I18/$F$7 -> 0.064899784 | K18: 21050 | L18: =K18/$F$7 -> 0.16623758 | M18: =SUM(I18+K18) -> 29268 | N18: =M18/$F$7 -> 0.23113737 | P18: =O18/$F$7 -> 0 | R18: =Q18/$F$7 -> 0 | T18: =S18/$F$7 -> 0 | U18: 3068 | V18: =U18/$F$7 -> 0.024228831 | W18: 72045 | X18: =W18/$F$7 -> 0.56895898 | Y18: 32166 | Z18: =Y18/$F$7 -> 0.25402366 | AA18: 27260 | AB18: =AA18/$F$7 -> 0.21527964
D19: 45882 | E19: 三 | F19: =SUM(M19,Q19,S19,U19,W19,Y19,AA19) -> 165300 | I19: 7540 | J19: =I19/$F$7 -> 0.059545433 | K19: 20658 | L19: =K19/$F$7 -> 0.16314185 | M19: =SUM(I19+K19) -> 28198 | N19: =M19/$F$7 -> 0.22268728 | P19: =O19/$F$7 -> 0 | R19: =Q19/$F$7 -> 0 | T19: =S19/$F$7 -> 0 | U19: 3227 | V19: =U19/$F$7 -> 0.025484498 | W19: 72598 | X19: =W19/$F$7 -> 0.57332617 | Y19: 33055 | Z19: =Y19/$F$7 -> 0.26104434 | AA19: 28222 | AB19: =AA19/$F$7 -> 0.22287682
D20: 45883 | E20: 四 | F20: =SUM(M20,Q20,S20,U20,W20,Y20,AA20) -> 154459 | I20: 6748 | J20: =I20/$F$7 -> 0.053290793 | K20: 18345 | L20: =K20/$F$7 -> 0.14487546 | M20: =SUM(I20+K20) -> 25093 | N20: =M20/$F$7 -> 0.19816625 | P20: =O20/$F$7 -> 0 | R20: =Q20/$F$7 -> 0 | T20: =S20/$F$7 -> 0 | U20: 3045 | V20: =U20/$F$7 -> 0.024047194 | W20: 67535 | X20: =W20/$F$7 -> 0.53334228 | Y20: 31549 | Z20: =Y20/$F$7 -> 0.24915104 | AA20: 27237 | AB20: =AA20/$F$7 -> 0.21509801
D21: 45884 | E21: 五 | F21: =SUM(M21,Q21,S21,U21,W21,Y21,AA21) -> 129575 | I21: 5677 | J21: =I21/$F$7 -> 0.044832815 | K21: 17865 | L21: =K21/$F$7 -> 0.14108477 | M21: =SUM(I21+K21) -> 23542 | N21: =M21/$F$7 -> 0.18591758 | P21: =O21/$F$7 -> 0 | R21: =Q21/$F$7 -> 0 | T21: =S21/$F$7 -> 0 | U21: 2780 | V21: =U21/$F$7 -> 0.021954417 | W21: 52959 | X21: =W21/$F$7 -> 0.41823164 | Y21: 27320 | Z21: =Y21/$F$7 -> 0.21575348 | AA21: 22974 | AB21: =AA21/$F$7 -> 0.18143193
D22: 45885 | E22: 六 | F22: =SUM(M22,Q22,S22,U22,W22,Y22,AA22) -> 129760 | I22: 5707 | J22: =I22/$F$7 -> 0.045069733 | K22: 19589 | L22: =K22/$F$7 -> 0.15469967 | M22: =SUM(I22+K22) -> 25296 | N22: =M22/$F$7 -> 0.1997694 | P22: =O22/$F$7 -> 0 | R22: =Q22/$F$7 -> 0 | T22: =S22/$F$7 -> 0 | U22: 2661 | V22: =U22/$F$7 -> 0.021014642 | W22: 53014 | X22: =W22/$F$7 -> 0.41866599 | Y22: 27659 | Z22: =Y22/$F$7 -> 0.21843065 | AA22: 21130 | AB22: =AA22/$F$7 -> 0.16686936
D23: 45886 | E23: 日 | F23: =SUM(M23,Q23,S23,U23,W23,Y23,AA23) -> 169934 | I23: 7254 | J23: =I23/$F$7 -> 0.057286813 | K23: 21841 | L23: =K23/$F$7 -> 0.17248432 | M23: =SUM(I23+K23) -> 29095 | N23: =M23/$F$7 -> 0.22977114 | P23: =O23/$F$7 -> 0 | R23: =Q23/$F$7 -> 0 | T23: =S23/$F$7 -> 0 | U23: 3182 | V23: =U23/$F$7 -> 0.02512912 | W23: 75485 | X23: =W23/$F$7 -> 0.5961256 | Y23: 34588 | Z23: =Y23/$F$7 -> 0.27315085 | AA23: 27584 | AB23: =AA23/$F$7 -> 0.21783836
D24: 45887 | E24: 一 | F24: =SUM(M24,Q24,S24,U24,W24,Y24,AA24) -> 169838 | I24: 7105 | J24: =I24/$F$7 -> 0.05611012 | K24: 21198 | L24: =K24/$F$7 -> 0.16740638 | M24: =SUM(I24+K24) -> 28303 | N24: =M24/$F$7 -> 0.2235165 | P24: =O24/$F$7 -> 0 | R24: =Q24/$F$7 -> 0 | T24: =S24/$F$7 -> 0 | U24: 3087 | V24: =U24/$F$7 -> 0.02437888 | W24: 76843 | X24: =W24/$F$7 -> 0.60685009 | Y24: 34352 | Z24: =Y24/$F$7 -> 0.2712871 | AA24: 27253 | AB24: =AA24/$F$7 -> 0.21522436
B25: =D33 -> 45896 | D25: 45888 | E25: 二 | F25: =SUM(M25,Q25,S25,U25,W25,Y25,AA25,O25) -> 193634 | G25: =SUM(F25:F31) -> 1179305 | I25: 6894 | J25: =I25/$F$7 -> 0.054443795 | K25: 21639 | L25: =K25/$F$7 -> 0.17088907 | M25: =SUM(I25+K25) -> 28533 | N25: =M25/$F$7 -> 0.22533287 | O25: 10675 | P25: =O25/$F$7 -> 0.084303382 | R25: =Q25/$F$7 -> 0 | T25: =S25/$F$7 -> 0 | U25: 3162 | V25: =U25/$F$7 -> 0.024971175 | W25: 83726 | X25: =W25/$F$7 -> 0.66120702 | Y25: 42339 | Z25: =Y25/$F$7 -> 0.33436261 | AA25: 25199 | AB25: =AA25/$F$7 -> 0.19900336
D26: 45889 | E26: 三 | F26: =SUM(M26,Q26,S26,U26,W26,Y26,AA26,O26) -> 180887 | I26: 6752 | J26: =I26/$F$7 -> 0.053322382 | K26: 20032 | L26: =K26/$F$7 -> 0.15819816 | M26: =SUM(I26+K26) -> 26784 | N26: =M26/$F$7 -> 0.21152054 | O26: 6835 | P26: =O26/$F$7 -> 0.053977856 | R26: =Q26/$F$7 -> 0 | T26: =S26/$F$7 -> 0 | U26: 3229 | V26: =U26/$F$7 -> 0.025500292 | W26: 79744 | X26: =W26/$F$7 -> 0.62976008 | Y26: 38750 | Z26: =Y26/$F$7 -> 0.3060193 | AA26: 25545 | AB26: =AA26/$F$7 -> 0.20173582
D27: 45890 | E27: 四 | F27: =SUM(M27,Q27,S27,U27,W27,Y27,AA27,O27) -> 170601 | I27: 6104 | J27: =I27/$F$7 -> 0.04820495 | K27: 17462 | L27: =K27/$F$7 -> 0.13790217 | M27: =SUM(I27+K27) -> 23566 | N27: =M27/$F$7 -> 0.18610712 | O27: 7130 | P27: =O27/$F$7 -> 0.056307551 | R27: =Q27/$F$7 -> 0 | T27: =S27/$F$7 -> 0 | U27: 3195 | V27: =U27/$F$7 -> 0.025231785 | W27: 76674 | X27: =W27/$F$7 -> 0.60551545 | Y27: 35865 | Z27: =Y27/$F$7 -> 0.28323567 | AA27: 24171 | AB27: =AA27/$F$7 -> 0.19088497
D28: 45891 | E28: 五 | F28: =SUM(M28,Q28,S28,U28,W28,Y28,AA28,O28) -> 134952 | I28: 4984 | J28: =I28/$F$7 -> 0.039360005 | K28: 16432 | L28: =K28/$F$7 -> 0.12976798 | M28: =SUM(I28+K28) -> 21416 | N28: =M28/$F$7 -> 0.16912798 | O28: 6805 | P28: =O28/$F$7 -> 0.053740938 | R28: =Q28/$F$7 -> 0 | T28: =S28/$F$7 -> 0 | U28: 2787 | V28: =U28/$F$7 -> 0.022009698 | W28: 56341 | X28: =W28/$F$7 -> 0.44494022 | Y28: 27439 | Z28: =Y28/$F$7 -> 0.21669325 | AA28: 20164 | AB28: =AA28/$F$7 -> 0.1592406
D29: 45892 | E29: 六 | F29: =SUM(M29,Q29,S29,U29,W29,Y29,AA29,O29) -> 140531 | I29: 5182 | J29: =I29/$F$7 -> 0.040923665 | K29: 19554 | L29: =K29/$F$7 -> 0.15442326 | M29: =SUM(I29+K29) -> 24736 | N29: =M29/$F$7 -> 0.19534693 | O29: 6582 | P29: =O29/$F$7 -> 0.051979846 | R29: =Q29/$F$7 -> 0 | T29: =S29/$F$7 -> 0 | U29: 2876 | V29: =U29/$F$7 -> 0.022712555 | W29: 57209 | X29: =W29/$F$7 -> 0.45179505 | Y29: 28402 | Z29: =Y29/$F$7 -> 0.22429833 | AA29: 20726 | AB29: =AA29/$F$7 -> 0.16367887
D30: 45893 | E30: 日 | F30: =SUM(M30,Q30,S30,U30,W30,Y30,AA30,O30) -> 182419 | I30: 6764 | J30: =I30/$F$7 -> 0.05341715 | K30: 21221 | L30: =K30/$F$7 -> 0.16758802 | M30: =SUM(I30+K30) -> 27985 | N30: =M30/$F$7 -> 0.22100516 | O30: 5550 | P30: =O30/$F$7 -> 0.043829861 | R30: =Q30/$F$7 -> 0 | T30: =S30/$F$7 -> 0 | U30: 3522 | V30: =U30/$F$7 -> 0.027814193 | W30: 81582 | X30: =W30/$F$7 -> 0.64427527 | Y30: 36450 | Z30: =Y30/$F$7 -> 0.28785557 | AA30: 27330 | AB30: =AA30/$F$7 -> 0.21583245
D31: 45894 | E31: 一 | F31: =SUM(M31,Q31,S31,U31,W31,Y31,AA31,O31) -> 176281 | I31: 6717 | J31: =I31/$F$7 -> 0.053045978 | K31: 21462 | L31: =K31/$F$7 -> 0.16949126 | M31: =SUM(I31+K31) -> 28179 | N31: =M31/$F$7 -> 0.22253724 | O31: 4275 | P31: =O31/$F$7 -> 0.033760839 | R31: =Q31/$F$7 -> 0 | T31: =S31/$F$7 -> 0 | U31: 3443 | V31: =U31/$F$7 -> 0.027190308 | W31: 80998 | X31: =W31/$F$7 -> 0.63966326 | Y31: 32621 | Z31: =Y31/$F$7 -> 0.25761692 | AA31: 26765 | AB31: =AA31/$F$7 -> 0.21137049
