Workbook

Sheet 日別報廢率總表 
A1: 新豐廠半成品管理日別總表 | M1: 分析原因 (細項說明參照當日分頁) | V1: 半成品品項數
A2: 日期 | B2: 營業額 | C2: 報廢額 | D2: 報廢率 KPI 0.25% | E2: 超用額 | F2: 超用率 | G2: 廢棄前10名 | I2: 超用前10名 | K2: 共用類廢棄
G3: 金額總計 | H3: 構成比 | I3: 金額總計 | J3: 構成比 | K3: 金額總計 | L3: 構成比 KPI 15%
A4: 45901 | B4: ='0901分析標準表 '!$C$3:$C$3 -> 6002768.9 | C4: ='0901分析標準表 '!$D$5 -> 14638.26 | D4: =C4/B4 -> 0.0024385846 | E4: ='0901分析標準表 '!$F$5 -> 47054.64 | F4: =E4/B4 -> 0.0078388225 | G4: ='0901分析標準表 '!$H$5 -> 4785.13 | H4: =G4/C4 -> 0.32689199 | I4: ='0901分析標準表 '!$J$5 -> 15850.84 | J4: =I4/E4 -> 0.3368603 | K4: ='0901分析標準表 '!$L$5 -> 6583.92 | L4: =K4/C4 -> 0.44977477 | M4: 1.4i抓樣不穩 2.4i原物料規格 3.2i其他原因 | V4: 165
A5: =A4+1 -> 45902 | B5: ='0902分析標準表 '!$C$3:$C$3 -> 6639488.4 | C5: ='0902分析標準表 '!$D$5 -> 16262.18 | D5: =C5/B5 -> 0.0024493122 | E5: ='0902分析標準表 '!$F$5 -> 51882.13 | F5: =E5/B5 -> 0.0078141759 | G5: ='0902分析標準表 '!$H$5 -> 5042.42 | H5: =G5/C5 -> 0.31007036 | I5: ='0902分析標準表 '!$J$5 -> 18567.52 | J5: =I5/E5 -> 0.35787891 | K5: ='0902分析標準表 '!$L$5 -> 7506.82 | L5: =K5/C5 -> 0.46161216 | M5: 1.4i原物料規格 2.3i抓樣不穩 3.2i其他原因 4.1i研發設定 | V5: 178
A6: =A5+1 -> 45903 | B6: ='0903分析標準表 '!$C$3:$C$3 -> 6228436.4 | C6: ='0903分析標準表 '!$D$5 -> 15219.38 | D6: =C6/B6 -> 0.0024435314 | E6: ='0903分析標準表 '!$F$5 -> 47136.37 | F6: =E6/B6 -> 0.0075679299 | G6: ='0903分析標準表 '!$H$5 -> 5276.32 | H6: =G6/C6 -> 0.34668429 | I6: ='0903分析標準表 '!$J$5 -> 19380.36 | J6: =I6/E6 -> 0.41115512 | K6: ='0903分析標準表 '!$L$5 -> 5632.29 | L6: =K6/C6 -> 0.37007355 | M6: 1.5i抓樣不穩 2.2i其他原因 3.2i原物料規格 4.1i研發設定 | V6: 178
A7: =A6+1 -> 45904 | B7: ='0904分析標準表 '!$C$3:$C$3 -> 5632441.8 | C7: ='0904分析標準表 '!$D$5 -> 13697.77 | D7: =C7/B7 -> 0.0024319417 | E7: ='0904分析標準表 '!$F$5 -> 43770.74 | F7: =E7/B7 -> 0.0077711837 | G7: ='0904分析標準表 '!$H$5 -> 4621.44 | H7: =G7/C7 -> 0.3373863 | I7: ='0904分析標準表 '!$J$5 -> 20127.53 | J7: =I7/E7 -> 0.45983984 | K7: ='0904分析標準表 '!$L$5 -> 6577.66 | L7: =K7/C7 -> 0.48019933 | M7: 1.6i抓樣不穩 2.3i原物料規格 3.1i其他原因 | V7: 174
A8: =A7+1 -> 45905 | B8: ='0905分析標準表 '!$C$3:$C$3 -> 4472239 | C8: ='0905分析標準表 '!$D$5 -> 10742.35 | D8: =C8/B8 -> 0.0024020072 | E8: ='0905分析標準表 '!$F$5 -> 34687.8 | F8: =E8/B8 -> 0.0077562492 | G8: ='0905分析標準表 '!$H$5 -> 3585.64 | H8: =G8/C8 -> 0.33378544 | I8: ='0905分析標準表 '!$J$5 -> 15067.87 | J8: =I8/E8 -> 0.43438529 | K8: ='0905分析標準表 '!$L$5 -> 4360.66 | L8: =K8/C8 -> 0.40593166 | M8: 1.5i抓樣不穩 2.4i原物料規格 3.1i其他原因 | V8: 174
A9: =A8+1 -> 45906 | B9: ='0906分析標準表 '!$C$3:$C$3 -> 4788156 | C9: ='0906分析標準表 '!$D$5 -> 11490.16 | D9: =C9/B9 -> 0.0023997046 | E9: ='0906分析標準表 '!$F$5 -> 37827.68 | F9: =E9/B9 -> 0.0079002605 | G9: ='0906分析標準表 '!$H$5 -> 3417.04 | H9: =G9/C9 -> 0.29738837 | I9: ='0906分析標準表 '!$J$5 -> 14348.1 | J9: =I9/E9 -> 0.37930161 | K9: ='0906分析標準表 '!$L$5 -> 4562.06 | L9: =K9/C9 -> 0.3970406 | M9: 1.5i抓樣不穩 2.4i原物料規格 3.1i其他原因 | V9: 174
A10: =A9+1 -> 45907 | B10: ='0907分析標準表 '!$C$3:$C$3 -> 6259452.2 | C10: ='0907分析標準表 '!$D$5 -> 15270.67 | D10: =C10/B10 -> 0.0024396176 | E10: ='0907分析標準表 '!$F$5 -> 48749.27 | F10: =E10/B10 -> 0.0077881048 | G10: ='0907分析標準表 '!$H$5 -> 4584.76 | H10: =G10/C10 -> 0.30023306 | I10: ='0907分析標準表 '!$J$5 -> 21761.21 | J10: =I10/E10 -> 0.44639048 | K10: ='0907分析標準表 '!$L$5 -> 4706.26 | L10: =K10/C10 -> 0.30818949 | M10: 1.5i抓樣不穩 2.3i原物料規格 3.2i其他原因 | V10: 174
A11: =A10+1 -> 45908 | B11: ='0908分析標準表 '!$C$3:$C$3 -> 6172069 | C11: ='0908分析標準表 '!$D$5 -> 15101.96 | D11: =C11/B11 -> 0.0024468229 | E11: ='0908分析標準表 '!$F$5 -> 48706.27 | F11: =E11/B11 -> 0.0078914008 | G11: ='0908分析標準表 '!$H$5 -> 5091.89 | H11: =G11/C11 -> 0.33716749 | I11: ='0908分析標準表 '!$J$5 -> 22167.92 | J11: =I11/E11 -> 0.45513483 | K11: ='0908分析標準表 '!$L$5 -> 6595.14 | L11: =K11/C11 -> 0.43670755 | M11: 1.4i原物料規格 2.3i其他原因 3.3i抓樣不穩 | V11: 174
A12: =A11+1 -> 45909 | B12: ='0909分析標準表 '!$C$3:$C$3 -> 5945144.5 | C12: ='0909分析標準表 '!$D$5 -> 14548.48 | D12: =C12/B12 -> 0.0024471197 | E12: ='0909分析標準表 '!$F$5 -> 46684.9 | F12: =E12/B12 -> 0.0078526099 | G12: ='0909分析標準表 '!$H$5 -> 4516.72 | H12: =G12/C12 -> 0.31045992 | I12: ='0909分析標準表 '!$J$5 -> 18353.61 | J12: =I12/E12 -> 0.39313804 | K12: ='0909分析標準表 '!$L$5 -> 5807.1 | L12: =K12/C12 -> 0.3991551 | M12: 1.5i抓樣不穩 2.4i原物料規格 3.1i其他原因 | V12: 174
A13: =A12+1 -> 45910 | B13: ='0910分析標準表 '!$C$3:$C$3 -> 5803938.3 | C13: ='0910分析標準表 '!$D$5 -> 14217.51 | D13: =C13/B13 -> 0.0024496315 | E13: ='0910分析標準表 '!$F$5 -> 46279.45 | F13: =E13/B13 -> 0.0079738011 | G13: ='0910分析標準表 '!$H$5 -> 4922.48 | H13: =G13/C13 -> 0.34622659 | I13: ='0910分析標準表 '!$J$5 -> 22167.92 | J13: =I13/E13 -> 0.47900137 | K13: ='0910分析標準表 '!$L$5 -> 6156.2 | L13: =K13/C13 -> 0.43300128 | M13: 1.4i抓樣不穩 2.3i其他原因 3.2i原物料規格 4.1i研發設定 | V13: 174
A14: =A13+1 -> 45911 | B14: ='0911分析標準表 '!$C$3:$C$3 -> 5409403.6 | C14: ='0911分析標準表 '!$D$5 -> 13174.85 | D14: =C14/B14 -> 0.0024355458 | E14: ='0911分析標準表 '!$F$5 -> 43256.48 | F14: =E14/B14 -> 0.007996534 | G14: ='0911分析標準表 '!$H$5 -> 4031.68 | H14: =G14/C14 -> 0.30601335 | I14: ='0911分析標準表 '!$J$5 -> 18960.46 | J14: =I14/E14 -> 0.43832647 | K14: ='0911分析標準表 '!$L$5 -> 5740.05 | L14: =K14/C14 -> 0.43568238 | M14: 1.6i抓樣不穩 2.3i原物料規格 3.1i其他原因 | V14: 174
A15: =A14+1 -> 45912 | B15: ='0912分析標準表 '!$C$3:$C$3 -> 4572249 | C15: ='0912分析標準表 '!$D$5 -> 11169.54 | D15: =C15/B15 -> 0.0024428985 | E15: ='0912分析標準表 '!$F$5 -> 34705.8 | F15: =E15/B15 -> 0.0075905316 | G15: ='0912分析標準表 '!$H$5 -> 3939.91 | H15: =G15/C15 -> 0.352737 | I15: ='0912分析標準表 '!$J$5 -> 11846.59 | J15: =I15/E15 -> 0.34134323 | K15: ='0912分析標準表 '!$L$5 -> 4417.42 | L15: =K15/C15 -> 0.39548809 | M15: 1.5i抓樣不穩 2.3i原物料規格 3.2i其他原因 | V15: 168
A16: =A15+1 -> 45913 | B16: ='0913分析標準表 '!$C$3:$C$3 -> 4851151.9 | C16: ='0913分析標準表 '!$D$5 -> 11694.87 | D16: =C16/B16 -> 0.0024107409 | E16: ='0913分析標準表 '!$F$5 -> 38597.41 | F16: =E16/B16 -> 0.0079563392 | G16: ='0913分析標準表 '!$H$5 -> 5542.9 | H16: =G16/C16 -> 0.47395995 | I16: ='0913分析標準表 '!$J$5 -> 13624.79 | J16: =I16/E16 -> 0.35299752 | K16: ='0913分析標準表 '!$L$5 -> 3831.69 | L16: =K16/C16 -> 0.32763853 | M16: 1.6i抓樣不穩 2.2i其他原因 3.2i原物料規格 | V16: 168
A17: =A16+1 -> 45914 | B17: ='0914分析標準表 '!$C$3:$C$3 -> 6253868.8 | C17: ='0914分析標準表 '!$D$5 -> 15093.1 | D17: =C17/B17 -> 0.0024134021 | E17: ='0914分析標準表 '!$F$5 -> 47716.81 | F17: =E17/B17 -> 0.0076299666 | G17: ='0914分析標準表 '!$H$5 -> 5946.23 | H17: =G17/C17 -> 0.39397009 | I17: ='0914分析標準表 '!$J$5 -> 24315.37 | J17: =I17/E17 -> 0.5095766 | K17: ='0914分析標準表 '!$L$5 -> 5278 | L17: =K17/C17 -> 0.34969622 | M17: 1.7i抓樣不穩 2.2i原物料規格 3.1i其他原因 | V17: 163
A18: =A17+1 -> 45915 | B18: ='0915分析標準表 '!$C$3:$C$3 -> 6231365.4 | C18: ='0915分析標準表 '!$D$5 -> 15102.44 | D18: =C18/B18 -> 0.0024236165 | E18: ='0915分析標準表 '!$F$5 -> 47950.77 | F18: =E18/B18 -> 0.0076950663 | G18: ='0915分析標準表 '!$H$5 -> 5807.32 | H18: =G18/C18 -> 0.38452859 | I18: ='0915分析標準表 '!$J$5 -> 26383.56 | J18: =I18/E18 -> 0.55022182 | K18: ='0915分析標準表 '!$L$5 -> 6462.99 | L18: =K18/C18 -> 0.42794343 | M18: 1.5i抓樣不穩 2.2i其他原因 3.2i原物料規格 4.1i研發設定 | V18: 163
A19: =A18+1 -> 45916 | B19: ='0916分析標準表 '!$C$3:$C$3 -> 6265697.1 | C19: ='0916分析標準表 '!$D$5 -> 15335.71 | D19: =C19/B19 -> 0.0024475665 | E19: ='0916分析標準表 '!$F$5 -> 48098.49 | F19: =E19/B19 -> 0.0076764787 | G19: ='0916分析標準表 '!$H$5 -> 5825 | H19: =G19/C19 -> 0.37983243 | I19: ='0916分析標準表 '!$J$5 -> 20638.82 | J19: =I19/E19 -> 0.42909497 | K19: ='0916分析標準表 '!$L$5 -> 7325.93 | L19: =K19/C19 -> 0.477704 | M19: 1.5i抓樣不穩 2.3i其他原因 3.2i原物料規格 | V19: 168
A20: =A19+1 -> 45917 | B20: ='0917分析標準表 '!$C$3:$C$3 -> 6072276.3 | C20: ='0917分析標準表 '!$D$5 -> 14879.51 | D20: =C20/B20 -> 0.0024504007 | E20: ='0917分析標準表 '!$F$5 -> 45707.8 | F20: =E20/B20 -> 0.0075272926 | G20: ='0917分析標準表 '!$H$5 -> 5611.95 | H20: =G20/C20 -> 0.3771596 | I20: ='0917分析標準表 '!$J$5 -> 16065.1 | J20: =I20/E20 -> 0.35147393 | K20: ='0917分析標準表 '!$L$5 -> 4588.36 | L20: =K20/C20 -> 0.30836768 | M20: 1.6i抓樣不穩 2.2i其他原因 3.2i原物料規格 | V20: 168
A21: =A20+1 -> 45918 | B21: ='0918分析標準表 '!$C$3:$C$3 -> 5709151.7 | C21: ='0918分析標準表 '!$D$5 -> 13988.34 | D21: =C21/B21 -> 0.0024501608 | E21: ='0918分析標準表 '!$F$5 -> 42117.22 | F21: =E21/B21 -> 0.0073771415 | G21: ='0918分析標準表 '!$H$5 -> 5013.64 | H21: =G21/C21 -> 0.35841565 | I21: ='0918分析標準表 '!$J$5 -> 16166.46 | J21: =I21/E21 -> 0.38384442 | K21: ='0918分析標準表 '!$L$5 -> 5812.96 | L21: =K21/C21 -> 0.41555753 | M21: 1.5i抓樣不穩 2.4i原物料規格 3.1i其他原因 | V21: 168
A22: =A21+1 -> 45919 | B22: ='0919分析標準表 '!$C$3:$C$3 -> 4674568.3 | C22: ='0919分析標準表 '!$D$5 -> 11259.97 | D22: =C22/B22 -> 0.0024087722 | E22: ='0919分析標準表 '!$F$5 -> 35142.33 | F22: =E22/B22 -> 0.0075177701 | G22: ='0919分析標準表 '!$H$5 -> 7911.78 | H22: =G22/C22 -> 0.70264663 | I22: ='0919分析標準表 '!$J$5 -> 11626.1 | J22: =I22/E22 -> 0.33082895 | K22: ='0919分析標準表 '!$L$5 -> 8404.29 | L22: =K22/C22 -> 0.74638654 | M22: 1.5i抓樣不穩 2.3i原物料規格 3.2i其他原因 | V22: 168
A23: =A22+1 -> 45920 | B23: ='0920分析標準表 '!$C$3:$C$3 -> 4900519.3 | C23: ='0920分析標準表 '!$D$5 -> 11821.34 | D23: =C23/B23 -> 0.0024122627 | E23: ='0920分析標準表 '!$F$5 -> 35740.4 | F23: =E23/B23 -> 0.0072931863 | G23: ='0920分析標準表 '!$H$5 -> 4332.34 | H23: =G23/C23 -> 0.36648468 | I23: ='0920分析標準表 '!$J$5 -> 19739.99 | J23: =I23/E23 -> 0.55231587 | K23: ='0920分析標準表 '!$L$5 -> 5762.61 | L23: =K23/C23 -> 0.48747519 | M23: 1.5i抓樣不穩 2.3i原物料規格 3.2i其他原因 | V23: 168
A24: =A23+1 -> 45921 | B24: ='0921分析標準表 '!$C$3:$C$3 -> 6327228.9 | C24: ='0921分析標準表 '!$D$5 -> 15236.53 | D24: =C24/B24 -> 0.002408089 | E24: ='0921分析標準表 '!$F$5 -> 47269.14 | F24: =E24/B24 -> 0.0074707492 | G24: ='0921分析標準表 '!$H$5 -> 5852.16 | H24: =G24/C24 -> 0.38408745 | I24: ='0921分析標準表 '!$J$5 -> 29421.1 | J24: =I24/E24 -> 0.62241665 | K24: ='0921分析標準表 '!$L$5 -> 7145.83 | L24: =K24/C24 -> 0.46899327 | M24: 1.6i抓樣不穩 2.2i其他原因 3.2i原物料規格 | V24: 168
A25: =A24+1 -> 45922 | B25: ='0922分析標準表 '!$C$3:$C$3 -> 6192295.3 | C25: ='0922分析標準表 '!$D$5 -> 15139.46 | D25: =C25/B25 -> 0.0024448866 | E25: ='0922分析標準表 '!$F$5 -> 46173.88 | F25: =E25/B25 -> 0.0074566663 | G25: ='0922分析標準表 '!$H$5 -> 6077.39 | H25: =G25/C25 -> 0.40142713 | I25: ='0922分析標準表 '!$J$5 -> 26810.7 | J25: =I25/E25 -> 0.58064646 | K25: ='0922分析標準表 '!$L$5 -> 6900.44 | L25: =K25/C25 -> 0.45579169 | M25: 1.5i抓樣不穩 2.3i原物料規格 3.2i其他原因 | V25: 168
A26: =A25+1 -> 45923 | B26: ='0923分析標準表 '!$C$3:$C$3 -> 6204692.1 | C26: ='0923分析標準表 '!$D$5 -> 15162.66 | D26: =C26/B26 -> 0.0024437409 | E26: ='0923分析標準表 '!$F$5 -> 47064.9 | F26: =E26/B26 -> 0.0075853724 | G26: ='0923分析標準表 '!$H$5 -> 5397.74 | H26: =G26/C26 -> 0.35598899 | I26: ='0923分析標準表 '!$J$5 -> 24833.93 | J26: =I26/E26 -> 0.52765288 | K26: ='0923分析標準表 '!$L$5 -> 6848.97 | L26: =K26/C26 -> 0.45169977 | M26: 1.4i其他原因 2.3i原物料規格 3.3i抓樣不穩 | V26: 170
A27: =A26+1 -> 45924 | B27: ='0924分析標準表 '!$C$3:$C$3 -> 6068582.9 | C27: ='0924分析標準表 '!$D$5 -> 14813.97 | D27: =C27/B27 -> 0.0024410921 | E27: ='0924分析標準表 '!$F$5 -> 44604.22 | F27: =E27/B27 -> 0.0073500224 | G27: ='0924分析標準表 '!$H$5 -> 5286.27 | H27: =G27/C27 -> 0.35684357 | I27: ='0924分析標準表 '!$J$5 -> 22623.27 | J27: =I27/E27 -> 0.50720022 | K27: ='0924分析標準表 '!$L$5 -> 5923.48 | L27: =K27/C27 -> 0.3998577 | M27: 1.4i原物料規格 2.4i抓樣不穩 3.2i其他原因 | V27: 170
A28: =A27+1 -> 45925 | B28: ='0925分析標準表 '!$C$3:$C$3 -> 5545534.9 | C28: ='0925分析標準表 '!$D$5 -> 13469.4 | D28: =C28/B28 -> 0.002428873 | E28: ='0925分析標準表 '!$F$5 -> 41918.04 | F28: =E28/B28 -> 0.0075588813 | G28: ='0925分析標準表 '!$H$5 -> 9556.05 | H28: =G28/C28 -> 0.70946367 | I28: ='0925分析標準表 '!$J$5 -> 18735.58 | J28: =I28/E28 -> 0.44695744 | K28: ='0925分析標準表 '!$L$5 -> 9883.65 | L28: =K28/C28 -> 0.73378547 | M28: 1.5i抓樣不穩 2.3i其他原因 3.2i原物料規格 | V28: 170
A29: =A28+1 -> 45926 | B29: ='0926分析標準表 '!$C$3:$C$3 -> 4389261 | C29: ='0926分析標準表 '!$D$5 -> 10529.22 | D29: =C29/B29 -> 0.0023988594 | E29: ='0926分析標準表 '!$F$5 -> 33245.57 | F29: =E29/B29 -> 0.0075742978 | G29: ='0926分析標準表 '!$H$5 -> 4222.15 | H29: =G29/C29 -> 0.40099362 | I29: ='0926分析標準表 '!$J$5 -> 18059.48 | J29: =I29/E29 -> 0.54321463 | K29: ='0926分析標準表 '!$L$5 -> 3343.82 | L29: =K29/C29 -> 0.31757528 | M29: 1.5i取樣不穩 2.4i其他原因 3.1i原物料規格 | V29: 170
A30: =A29+1 -> 45927 | B30: ='0927分析標準表 '!$C$3:$C$3 -> 4423149.8 | C30: ='0927分析標準表 '!$D$5 -> 10619.51 | D30: =C30/B30 -> 0.0024008932 | E30: ='0927分析標準表 '!$F$5 -> 33137.94 | F30: =E30/B30 -> 0.0074919326 | G30: ='0927分析標準表 '!$H$5 -> 3691.15 | H30: =G30/C30 -> 0.34758195 | I30: ='0927分析標準表 '!$J$5 -> 15895.3 | J30: =I30/E30 -> 0.47967073 | K30: ='0927分析標準表 '!$L$5 -> 4273.36 | L30: =K30/C30 -> 0.40240651 | M30: 1.6i取樣不穩 2.3i原物料規格 3.1i其他原因 | V30: 170
A31: =A30+1 -> 45928 | B31: ='0928分析標準表 '!$C$3:$C$3 -> 4811205.6 | C31: ='0928分析標準表 '!$D$5 -> 11593.48 | D31: =C31/B31 -> 0.0024096829 | E31: ='0928分析標準表 '!$F$5 -> 36480.86 | F31: =E31/B31 -> 0.0075824779 | G31: ='0928分析標準表 '!$H$5 -> 4491.5 | H31: =G31/C31 -> 0.38741603 | I31: ='0928分析標準表 '!$J$5 -> 26313.58 | J31: =I31/E31 -> 0.72129824 | K31: ='0928分析標準表 '!$L$5 -> 4670.33 | L31: =K31/C31 -> 0.40284108 | M31: 1.5i取樣不穩 2.3i其他原因 3.2i原物料規格 | V31: 170
A32: =A31+1 -> 45929 | B32: ='0929分析標準表 '!$C$3:$C$3 -> 6458150 | C32: ='0929分析標準表 '!$D$5 -> 15820.38 | D32: =C32/B32 -> 0.0024496768 | E32: ='0929分析標準表 '!$F$5 -> 49069.36 | F32: =E32/B32 -> 0.0075980521 | G32: ='0929分析標準表 '!$H$5 -> 5971.09 | H32: =G32/C32 -> 0.37743025 | I32: ='0929分析標準表 '!$J$5 -> 36921.98 | J32: =I32/E32 -> 0.7524447 | K32: ='0929分析標準表 '!$L$5 -> 6866.83 | L32: =K32/C32 -> 0.43404962 | M32: 1.5i取樣不穩 2.3i其他原因 3.2i原物料規格 | V32: 170
A33: =A32+1 -> 45930 | B33: ='0930分析標準表 '!$C$3:$C$3 -> 6240376.6 | C33: ='0930分析標準表 '!$D$5 -> 15252.09 | D33: =C33/B33 -> 0.0024440977 | E33: ='0930分析標準表 '!$F$5 -> 47299.72 | F33: =E33/B33 -> 0.0075796259 | G33: ='0930分析標準表 '!$H$5 -> 6038.19 | H33: =G33/C33 -> 0.39589263 | I33: ='0930分析標準表 '!$J$5 -> 30851.15 | J33: =I33/E33 -> 0.65224805 | K33: ='0930分析標準表 '!$L$5 -> 6747.82 | L33: =K33/C33 -> 0.44241937 | M33: 1.6i取樣不穩 2.3i原物料規格 3.1i其他原因 | V33: 170
A34: ※淺黃色為工廠自填項目
A35: ※日期紅色為新品日

Sheet 0930分析標準表 
A1: 新豐廠半成品管理分析
A2: 日期 | C2: 營業額 | D2: 報廢展開 | F2: 超用展開 | H2: 報廢展開 | J2: 超用展開 | L2: 報廢展開
A3: 45930 | C3: 6240376.6 | D3: 總報廢 | F3: 總超用 | H3: 報廢-前10名 | J3: 超用-前10名 | L3: 共用類-總報廢
D4: 金額 | E4: 占比(營業額) | F4: 金額 | G4: 占比(營業額) | H4: 金額 | I4: 占比(總報廢) | J4: 金額 | K4: 占比(總超用) | L4: 金額 | M4: 占比(總報廢)
A5: 年度KPI目標0.25% | D5: 15252.09 | E5: =D5/C3 -> 0.0024440977 | F5: 47299.72 | G5: =F5/C3 -> 0.0075796259 | H5: =SUM(C12:C21) -> 6038.19 | I5: =H5/D5 -> 0.39589263 | J5: =SUM(C28:C37) -> 30851.15 | K5: =J5/F5 -> 0.65224805 | L5: 6747.82 | M5: =L5/D5 -> 0.44241937
A7: 報廢金額前十名半成品
A8: 明細展開 | D8: 生產資訊 | O8: 類別 | P8: 分析原因 (請填寫8大原因) | Q8: 其他原因說明 | R8: 備註-商品名稱
A9: 排序 | B9: 半成品 | D9: 生產端 | J9: 組合端
B10: 名稱 | C10: 報廢金額 排序 | D10: 產出量 | J10: 報廢 | L10: 超用
D11: 訂單需求 (kg) | E11: 實際產出 (kg) | F11: 補單 (kg) | G11: 單價 (元) | H11: 實際生產 (對比訂單需求) | I11: 差異 (元) | J11: kg | K11: 占比 | L11: kg | M11: 占比 | N11: 金額 (元)
A12: 1 | B12: 墨西哥餅皮-原味(8英吋)新 | C12: 2803.08 | D12: 7764 | E12: 7764 | F12: 426 | G12: 6.58 | H12: =(E12+F12)/D12 -> 1.0548686 | I12: 2803.08 | J12: 426 | K12: =J12/D12 -> 0.054868624 | L12: =((E12+F12)-D12)-J12 -> 0 | M12: =L12/D12 -> 0 | N12: =L12*G12 -> 0 | O12: 原物料 | P12: 原物料規格 | Q12: 菜梗太硬導致捲的時候破損 | R12: 共用類
A13: 2 | B13: 義美業務用馬芬堡 | C13: 986.06 | D13: 15900 | E13: 15900 | F13: 170.01 | G13: 5.8 | H13: =(E13+F13)/D13 -> 1.0106925 | I13: 986.06 | J13: 170.01 | K13: =J13/D13 -> 0.010692453 | L13: =((E13+F13)-D13)-J13 -> 2.2737368e-13 | M13: =L13/D13 -> 1.4300231e-17 | N13: =L13*G13 -> 1.3187673e-12 | O13: 組合端 | P13: 其他原因 | Q13: 1.包材過於貼體2.堡體無完全切斷分離，人員抓破損壞 | R13: 共用類
A14: 3 | B14: 拌經典總匯雞蛋沙拉CL | C14: 512.22 | D14: 95.06 | E14: 95.06 | F14: 9 | G14: 119.12 | H14: =(E14+F14)/D14 -> 1.094677 | I14: 1072.08 | J14: 4.3 | K14: =J14/D14 -> 0.045234589 | L14: =((E14+F14)-D14)-J14 -> 4.7 | M14: =L14/D14 -> 0.049442457 | N14: =L14*G14 -> 559.864 | O14: 組合端 | P14: 取樣不穩 | Q14: 人員冰杓定量手法不穩 | R14: 經典總匯三明治
A15: 4 | B15: 墨西哥餅皮-菠菜(8英吋)新 | C15: 374.85 | D15: 8712 | E15: 8712 | F15: 53.55 | G15: 7 | H15: =(E15+F15)/D15 -> 1.0061467 | I15: 374.85 | J15: 53.55 | K15: =J15/D15 -> 0.0061466942 | L15: =((E15+F15)-D15)-J15 -> -7.2475359e-13 | M15: =L15/D15 -> -8.3190265e-17 | N15: =L15*G15 -> -5.0732751e-12 | O15: 原物料 | P15: 原物料規格 | Q15: 菜梗太硬導致捲的時候破損 | R15: 共用類
A16: 5 | B16: 電解消毒混合蔥鹽蔬菜絲 | C16: 277.25 | D16: 50.48 | E16: 50.48 | F16: 4.94 | G16: 118.99 | H16: =(E16+F16)/D16 -> 1.0978605 | I16: 587.81 | J16: 2.33 | K16: =J16/D16 -> 0.046156894 | L16: =((E16+F16)-D16)-J16 -> 2.61 | M16: =L16/D16 -> 0.051703645 | N16: =L16*G16 -> 310.5639 | O16: 組合端 | P16: 取樣不穩 | Q16: 人員抓樣手感不穩 | R16: 蔥鹽雞肉麵沙拉(114年)
A17: 6 | B17: 煮螺旋麵(沙拉用) | C17: 277.04 | D17: 168.25 | E17: 168.25 | F17: 14.3 | G17: 39.02 | H17: =(E17+F17)/D17 -> 1.0849926 | I17: 557.99 | J17: 7.1 | K17: =J17/D17 -> 0.042199108 | L17: =((E17+F17)-D17)-J17 -> 7.2 | M17: =L17/D17 -> 0.042793462 | N17: =L17*G17 -> 280.944 | O17: 組合端 | P17: 取樣不穩 | Q17: 秤重物料，秤重精準度須持續校正 | R17: 蔥鹽雞肉麵沙拉(114年)
A18: 7 | B18: 超HOT沙拉醬 | C18: 227.44 | D18: 41.28 | E18: 41.28 | F18: 4.01 | G18: 113.72 | H18: =(E18+F18)/D18 -> 1.0971415 | I18: 456.02 | J18: 2 | K18: =J18/D18 -> 0.048449612 | L18: =((E18+F18)-D18)-J18 -> 2.01 | M18: =L18/D18 -> 0.04869186 | N18: =L18*G18 -> 228.5772 | O18: 組合端 | P18: 取樣不穩 | Q18: 人員冰杓定量手法不穩 | R18: 超HOT雞腿堡(114年)
A19: 8 | B19: 煮咖哩紅蘿蔔丁(112年) | C19: 204.87 | D19: 58.28 | E19: 58.28 | F19: 5.76 | G19: 74.23 | H19: =(E19+F19)/D19 -> 1.0988332 | I19: 427.56 | J19: 2.76 | K19: =J19/D19 -> 0.047357584 | L19: =((E19+F19)-D19)-J19 -> 3 | M19: =L19/D19 -> 0.051475635 | N19: =L19*G19 -> 222.69 | O19: 原物料 | P19: 原物料規格 | Q19: 原物料廠商無過篩，大小差異大 | R19: 二配金咖哩果香甘口咖哩飯
A20: 9 | B20: 烤鹹蛋黃碎 | C20: 188.12 | D20: 9.16 | E20: 9.16 | F20: 0.28 | G20: 1567.63 | H20: =(E20+F20)/D20 -> 1.0305677 | I20: 438.94 | J20: 0.12 | K20: =J20/D20 -> 0.013100437 | L20: =((E20+F20)-D20)-J20 -> 0.16 | M20: =L20/D20 -> 0.017467249 | N20: =L20*G20 -> 250.8208 | O20: 組合端 | P20: 取樣不穩 | Q20: 人員抓樣手感不穩 | R20: 二配美味蟹煲
A21: 10 | B21: 川燙醃嫩化淨零碳排牛肉片 | C21: 187.26 | D21: 38.42 | E21: 38.42 | F21: 2.3 | G21: 814.16 | H21: =(E21+F21)/D21 -> 1.0598647 | I21: 1872.57 | J21: 0.23 | K21: =J21/D21 -> 0.0059864654 | L21: =((E21+F21)-D21)-J21 -> 2.07 | M21: =L21/D21 -> 0.053878188 | N21: =L21*G21 -> 1685.3112 | O21: 組合端 | P21: 取樣不穩 | Q21: 秤重物料，秤重精準度須持續校正 | R21: 二配港式香滑嫩蛋牛肉燴飯
A23: 超用金額前十名半成品
A24: 明細展開 | D24: 生產資訊 | O24: 類別 | P24: 分析原因 (請填寫8大原因) | Q24: 其他原因說明 | R24: 備註-商品名稱
A25: 排序 | B25: 半成品 | D25: 生產端 | J25: 組合端
B26: 名稱 | C26: 超用金額 排序 | D26: 產出量 | J26: 報廢 | M26: 超用
D27: 訂單需求 (kg) | E27: 實際產出 (kg) | F27: 補單 (kg) | G27: 單價 (元) | H27: 實際生產 (對比訂單需求) | I27: 差異 (元) | J27: kg | K27: 占比 | L27: 金額 (元) | M27: kg | N27: 占比
A28: 1 | B28: 電解消毒牛蕃茄切片(中) | C28: 14726.36 | D28: 115.68 | E28: 167.91 | F28: 0.6 | G28: 278.75 | H28: =(E28+F28)/D28 -> 1.4566909 | I28: 14726.36 | J28: 0 | K28: =J28/D28 -> 0 | L28: =J28*G28 -> 0 | M28: =((E28+F28)-D28)-J28 -> 52.83 | N28: =M28/D28 -> 0.45669087 | R28: 共用類
A29: 2 | B29: 烤卜蜂紐奧良腿排(減鈉版) | C29: 3550 | D29: 10712 | E29: 10712 | F29: 200 | G29: 17.75 | H29: =(E29+F29)/D29 -> 1.0186706 | I29: 3550 | J29: 0 | K29: =J29/D29 -> 0 | L29: =J29*G29 -> 0 | M29: =((E29+F29)-D29)-J29 -> 200 | N29: =M29/D29 -> 0.01867065 | R29: 紐奧良風味烤雞鮮蔬三明治
A30: 3 | B30: 電解消毒對切整葉廣東A | C30: 2007.04 | D30: 116.46 | E30: 116.46 | F30: 6.99 | G30: 313.6 | H30: =(E30+F30)/D30 -> 1.0600206 | I30: 2192.06 | J30: 0.59 | K30: =J30/D30 -> 0.0050661171 | L30: =J30*G30 -> 185.024 | M30: =((E30+F30)-D30)-J30 -> 6.4 | N30: =M30/D30 -> 0.054954491 | R30: 共用類
A31: 4 | B31: 炒壽喜燒牛培根 | C31: 1874.93 | D31: 82.24 | E31: 82.24 | F31: 4.93 | G31: 417.58 | H31: =(E31+F31)/D31 -> 1.0599465 | I31: 2058.67 | J31: 0.44 | K31: =J31/D31 -> 0.0053501946 | L31: =J31*G31 -> 183.7352 | M31: =((E31+F31)-D31)-J31 -> 4.49 | N31: =M31/D31 -> 0.054596304 | R31: 白味噌壽喜燒飯
A32: 5 | B32: 鮪魚沙拉(113.05) | C32: 1769.64 | D32: 239.73 | E32: 239.73 | F32: 10.07 | G32: 194.04 | H32: =(E32+F32)/D32 -> 1.0420056 | I32: 1953.98 | J32: 0.95 | K32: =J32/D32 -> 0.0039627915 | L32: =J32*G32 -> 184.338 | M32: =((E32+F32)-D32)-J32 -> 9.12 | N32: =M32/D32 -> 0.038042798 | R32: 鮪魚起司溏心蛋三明治
A33: 6 | B33: 川燙醃嫩化淨零碳排牛肉片 | C33: 1685.31 | D33: 38.42 | E33: 38.42 | F33: 2.3 | G33: 814.16 | H33: =(E33+F33)/D33 -> 1.0598647 | I33: 1872.57 | J33: 0.23 | K33: =J33/D33 -> 0.0059864654 | L33: =J33*G33 -> 187.2568 | M33: =((E33+F33)-D33)-J33 -> 2.07 | N33: =M33/D33 -> 0.053878188 | R33: 二配港式香滑嫩蛋牛肉燴飯
A34: 7 | B34: 打發QQ泰奶 | C34: 1342.7 | D34: 162.55 | E34: 162.55 | F34: 7.8 | G34: 195.73 | H34: =(E34+F34)/D34 -> 1.0479852 | I34: 1526.69 | J34: 0.94 | K34: =J34/D34 -> 0.0057828361 | L34: =J34*G34 -> 183.9862 | M34: =((E34+F34)-D34)-J34 -> 6.86 | N34: =M34/D34 -> 0.042202399 | R34: 泰奶奶蓋QQ三明治
A35: 8 | B35: 蒸基礎風味雞肉絲 | C35: 1333.02 | D35: 102.84 | E35: 102.84 | F35: 3.7 | G35: 410.16 | H35: =(E35+F35)/D35 -> 1.0359782 | I35: 1517.59 | J35: 0.45 | K35: =J35/D35 -> 0.0043757293 | L35: =J35*G35 -> 184.572 | M35: =((E35+F35)-D35)-J35 -> 3.25 | N35: =M35/D35 -> 0.031602489 | R35: 共用類
A36: 9 | B36: 電解消毒美生菜(三明治用) | C36: 1320.71 | D36: 123.43 | E36: 123.43 | F36: 7.4 | G36: 203.5 | H36: =(E36+F36)/D36 -> 1.059953 | I36: 1505.9 | J36: 0.91 | K36: =J36/D36 -> 0.0073725999 | L36: =J36*G36 -> 185.185 | M36: =((E36+F36)-D36)-J36 -> 6.49 | N36: =M36/D36 -> 0.05258041 | R36: 共用類
A37: 10 | B37: 油亮蒜味香腸片 | C37: 1241.44 | D37: 93.24 | E37: 93.24 | F37: 4.48 | G37: 318.32 | H37: =(E37+F37)/D37 -> 1.048048 | I37: 1426.07 | J37: 0.58 | K37: =J37/D37 -> 0.0062205062 | L37: =J37*G37 -> 184.6256 | M37: =((E37+F37)-D37)-J37 -> 3.9 | N37: =M37/D37 -> 0.041827542 | R37: 二配香辣醬蒜味香腸蛋炒飯
A39: 共用類報廢金額前十名半成品
A40: 明細展開
A41: 排序 | B41: 半成品
B42: 名稱 | C42: 報廢金額 排序 | D42: 共用類總金額 占比
A44: 1 | B44: 墨西哥餅皮-原味(8英吋)新 | C44: 2803.08 | D44: =C44/$L$5 -> 0.41540527
...

Sheet 0929分析標準表 
A1: 新豐廠半成品管理分析
A2: 日期 | C2: 營業額 | D2: 報廢展開 | F2: 超用展開 | H2: 報廢展開 | J2: 超用展開 | L2: 報廢展開
A3: 45929 | C3: 6458150 | D3: 總報廢 | F3: 總超用 | H3: 報廢-前10名 | J3: 超用-前10名 | L3: 共用類-總報廢
D4: 金額 | E4: 占比(營業額) | F4: 金額 | G4: 占比(營業額) | H4: 金額 | I4: 占比(總報廢) | J4: 金額 | K4: 占比(總超用) | L4: 金額 | M4: 占比(總報廢)
A5: 年度KPI目標0.25% | D5: 15820.38 | E5: =D5/C3 -> 0.0024496768 | F5: 49069.36 | G5: =F5/C3 -> 0.0075980521 | H5: =SUM(C12:C21) -> 5971.09 | I5: =H5/D5 -> 0.37743025 | J5: =SUM(C28:C37) -> 36921.98 | K5: =J5/F5 -> 0.7524447 | L5: 6866.83 | M5: =L5/D5 -> 0.43404962
A7: 報廢金額前十名半成品
A8: 明細展開 | D8: 生產資訊 | O8: 類別 | P8: 分析原因 (請填寫8大原因) | Q8: 其他原因說明 | R8: 備註-商品名稱
A9: 排序 | B9: 半成品 | D9: 生產端 | J9: 組合端
B10: 名稱 | C10: 報廢金額 排序 | D10: 產出量 | J10: 報廢 | L10: 超用
D11: 訂單需求 (kg) | E11: 實際產出 (kg) | F11: 補單 (kg) | G11: 單價 (元) | H11: 實際生產 (對比訂單需求) | I11: 差異 (元) | J11: kg | K11: 占比 | L11: kg | M11: 占比 | N11: 金額 (元)
A12: 1 | B12: 墨西哥餅皮-原味(8英吋)新 | C12: 1882.54 | D12: 7891 | E12: 7891 | F12: 286.1 | G12: 6.58 | H12: =(E12+F12)/D12 -> 1.0362565 | I12: 1882.54 | J12: 286.1 | K12: =J12/D12 -> 0.036256495 | L12: =((E12+F12)-D12)-J12 -> 0 | M12: =L12/D12 -> 0 | N12: =L12*G12 -> 0 | O12: 原物料 | P12: 原物料規格 | Q12: 菜梗太硬導致捲的時候破損 | R12: 共用類
A13: 2 | B13: 義美業務用馬芬堡 | C13: 1516.7 | D13: 16819 | E13: 16819 | F13: 261.5 | G13: 5.8 | H13: =(E13+F13)/D13 -> 1.0155479 | I13: 1516.7 | J13: 261.5 | K13: =J13/D13 -> 0.015547892 | L13: =((E13+F13)-D13)-J13 -> 0 | M13: =L13/D13 -> 0 | N13: =L13*G13 -> 0 | O13: 組合端 | P13: 其他原因 | Q13: 1.包材過於貼體2.堡體無完全切斷分離，人員抓破損壞 | R13: 共用類
A14: 3 | B14: (V)電解消毒小黃瓜絲 | C14: 797.69 | D14: 100.7 | E14: 100.7 | F14: 10.02 | G14: 160.5 | H14: =(E14+F14)/D14 -> 1.0995035 | I14: 1608.21 | J14: 4.97 | K14: =J14/D14 -> 0.049354518 | L14: =((E14+F14)-D14)-J14 -> 5.05 | M14: =L14/D14 -> 0.050148957 | N14: =L14*G14 -> 810.525 | O14: 組合端 | P14: 取樣不穩 | Q14: 人員抓樣手感不穩 | R14: 共用類
A15: 4 | B15: 拌經典總匯雞蛋沙拉CL | C15: 385.95 | D15: 90.75 | E15: 90.75 | F15: 6.5 | G15: 119.12 | H15: =(E15+F15)/D15 -> 1.0716253 | I15: 774.28 | J15: 3.24 | K15: =J15/D15 -> 0.035702479 | L15: =((E15+F15)-D15)-J15 -> 3.26 | M15: =L15/D15 -> 0.035922865 | N15: =L15*G15 -> 388.3312 | O15: 組合端 | P15: 取樣不穩 | Q15: 人員冰杓定量手法不穩 | R15: 經典總匯三明治
A16: 5 | B16: 炒辛口紅蘿蔔丁(112年) | C16: 297.33 | D16: 73.27 | E16: 73.27 | F16: 7.21 | G16: 90.1 | H16: =(E16+F16)/D16 -> 1.0984032 | I16: 649.62 | J16: 3.3 | K16: =J16/D16 -> 0.045038897 | L16: =((E16+F16)-D16)-J16 -> 3.91 | M16: =L16/D16 -> 0.053364269 | N16: =L16*G16 -> 352.291 | O16: 原物料 | P16: 原物料規格 | Q16: 原物料廠商無過篩，大小差異大 | R16: 二配金咖哩濃厚辛辣咖哩飯
A17: 6 | B17: 電解消毒混合蔥鹽蔬菜絲 | C17: 282.01 | D17: 51.21 | E17: 51.21 | F17: 4.9 | G17: 118.99 | H17: =(E17+F17)/D17 -> 1.0956844 | I17: 583.05 | J17: 2.37 | K17: =J17/D17 -> 0.046280023 | L17: =((E17+F17)-D17)-J17 -> 2.53 | M17: =L17/D17 -> 0.049404413 | N17: =L17*G17 -> 301.0447 | O17: 組合端 | P17: 取樣不穩 | Q17: 人員抓樣手感不穩 | R17: 蔥鹽雞肉麵沙拉(114年)
A18: 7 | B18: 義美4吋芝麻漢堡 | C18: 256.65 | D18: 6112 | E18: 6112 | F18: 58.33 | G18: 4.4 | H18: =(E18+F18)/D18 -> 1.0095435 | I18: 256.65 | J18: 58.33 | K18: =J18/D18 -> 0.0095435209 | L18: =((E18+F18)-D18)-J18 -> -7.1054274e-14 | M18: =L18/D18 -> -1.1625372e-17 | N18: =L18*G18 -> -3.126388e-13 | O18: 組合端 | P18: 其他原因 | Q18: 包材過於貼體 | R18: 共用類
A19: 8 | B19: 電解消毒紫洋蔥(去皮)切絲 | C19: 191.27 | D19: 35.67 | E19: 35.67 | F19: 3.43 | G19: 113.18 | H19: =(E19+F19)/D19 -> 1.0961592 | I19: 388.21 | J19: 1.69 | K19: =J19/D19 -> 0.04737875 | L19: =((E19+F19)-D19)-J19 -> 1.74 | M19: =L19/D19 -> 0.048780488 | N19: =L19*G19 -> 196.9332 | O19: 組合端 | P19: 取樣不穩 | Q19: 人員抓樣手感不穩 | R19: 莎莎烤雞麵沙拉
A20: 9 | B20: 炒紅K洋蔥片 | C20: 181.51 | D20: 33.45 | E20: 33.45 | F20: 3.21 | G20: 112.74 | H20: =(E20+F20)/D20 -> 1.0959641 | I20: 361.9 | J20: 1.61 | K20: =J20/D20 -> 0.04813154 | L20: =((E20+F20)-D20)-J20 -> 1.6 | M20: =L20/D20 -> 0.047832586 | N20: =L20*G20 -> 180.384 | O20: 組合端 | P20: 取樣不穩 | Q20: 人員抓樣手感不穩 | R20: 白味噌壽喜燒飯
A21: 10 | B21: 四吋芝麻漢堡 | C21: 179.44 | D21: 5288 | E21: 5288 | F21: 41.25 | G21: 4.35 | H21: =(E21+F21)/D21 -> 1.0078007 | I21: 179.44 | J21: 41.25 | K21: =J21/D21 -> 0.0078006808 | L21: =((E21+F21)-D21)-J21 -> 0 | M21: =L21/D21 -> 0 | N21: =L21*G21 -> 0 | O21: 組合端 | P21: 其他原因 | Q21: 包材過於貼體 | R21: 經典雙牛起司堡(113年)
A23: 超用金額前十名半成品
A24: 明細展開 | D24: 生產資訊 | O24: 類別 | P24: 分析原因 (請填寫8大原因) | Q24: 其他原因說明 | R24: 備註-商品名稱
A25: 排序 | B25: 半成品 | D25: 生產端 | J25: 組合端
B26: 名稱 | C26: 超用金額 排序 | D26: 產出量 | J26: 報廢 | M26: 超用
D27: 訂單需求 (kg) | E27: 實際產出 (kg) | F27: 補單 (kg) | G27: 單價 (元) | H27: 實際生產 (對比訂單需求) | I27: 差異 (元) | J27: kg | K27: 占比 | L27: 金額 (元) | M27: kg | N27: 占比
A28: 1 | B28: 電解消毒牛蕃茄切片(中) | C28: 23741.14 | D28: 121.57 | E28: 206.26 | F28: 0.48 | G28: 278.75 | H28: =(E28+F28)/D28 -> 1.700584 | I28: 23741.14 | J28: 0 | K28: =J28/D28 -> 0 | L28: =J28*G28 -> 0 | M28: =((E28+F28)-D28)-J28 -> 85.17 | N28: =M28/D28 -> 0.70058403 | O28: 原物料 | P28: 原物料規格 | Q28: 物料規格過大(商品1顆開10片)，造成重量投入過多 | R28: 共用類
A29: 2 | B29: 烤卜蜂紐奧良腿排(減鈉版) | C29: 5325 | D29: 10726 | E29: 10726 | F29: 300 | G29: 17.75 | H29: =(E29+F29)/D29 -> 1.0279694 | I29: 5325 | J29: 0 | K29: =J29/D29 -> 0 | L29: =J29*G29 -> 0 | M29: =((E29+F29)-D29)-J29 -> 300 | N29: =M29/D29 -> 0.02796942 | O29: 原物料 | P29: 原物料規格 | Q29: 塊肉過畸形，MD強制尾端補肉 | R29: 紐奧良風味烤雞鮮蔬三明治
A30: 3 | B30: 電解消毒十字切美生菜 | C30: 1421.54 | D30: 342.34 | E30: 342.34 | F30: 10.17 | G30: 156.73 | H30: =(E30+F30)/D30 -> 1.0297073 | I30: 1593.94 | J30: 1.1 | K30: =J30/D30 -> 0.0032131799 | L30: =J30*G30 -> 172.403 | M30: =((E30+F30)-D30)-J30 -> 9.07 | N30: =M30/D30 -> 0.026494129 | O30: 組合室 | P30: 取樣不穩 | Q30: 原物料特性，梗葉比例重量差異，抓樣不穩 | R30: 共用類
A31: 4 | B31: 炒壽喜燒牛培根 | C31: 1056.48 | D31: 89.2 | E31: 89.2 | F31: 2.94 | G31: 417.58 | H31: =(E31+F31)/D31 -> 1.0329596 | I31: 1227.69 | J31: 0.41 | K31: =J31/D31 -> 0.0045964126 | L31: =J31*G31 -> 171.2078 | M31: =((E31+F31)-D31)-J31 -> 2.53 | N31: =M31/D31 -> 0.028363229 | O31: 組合室 | P31: 取樣不穩 | Q31: 秤重物料，秤重精準度須持續校正 | R31: 白味噌壽喜燒飯
A32: 5 | B32: 電解消毒對切整葉廣東A | C32: 1053.7 | D32: 118.37 | E32: 118.37 | F32: 3.91 | G32: 313.6 | H32: =(E32+F32)/D32 -> 1.033032 | I32: 1226.18 | J32: 0.55 | K32: =J32/D32 -> 0.0046464476 | L32: =J32*G32 -> 172.48 | M32: =((E32+F32)-D32)-J32 -> 3.36 | N32: =M32/D32 -> 0.028385571 | O32: 組合室 | P32: 取樣不穩 | Q32: 原物料特性，梗葉比例重量差異，抓樣不穩 | R32: 共用類
A33: 6 | B33: 川燙醃嫩化淨零碳排牛肉片 | C33: 928.15 | D33: 40.79 | E33: 40.79 | F33: 1.35 | G33: 814.16 | H33: =(E33+F33)/D33 -> 1.0330963 | I33: 1099.12 | J33: 0.21 | K33: =J33/D33 -> 0.0051483207 | L33: =J33*G33 -> 170.9736 | M33: =((E33+F33)-D33)-J33 -> 1.14 | N33: =M33/D33 -> 0.027948026 | O33: 組合室 | P33: 研發設定 | Q33: 秤重物料，秤重精準度須持續校正(過多難剝除) | R33: 二配港式香滑嫩蛋牛肉燴飯
A34: 7 | B34: 電解消毒切段美生菜2-3cm | C34: 898.12 | D34: 229.91 | E34: 229.91 | F34: 6.83 | G34: 156.74 | H34: =(E34+F34)/D34 -> 1.0297073 | I34: 1070.53 | J34: 1.1 | K34: =J34/D34 -> 0.0047844809 | L34: =J34*G34 -> 172.414 | M34: =((E34+F34)-D34)-J34 -> 5.73 | N34: =M34/D34 -> 0.024922796 | O34: 組合室 | P34: 取樣不穩 | Q34: 原物料特性，梗葉比例重量差異，抓樣不穩 | R34: 共用類
A35: 8 | B35: 鮪魚沙拉(113.05) | C35: 882.88 | D35: 235.59 | E35: 235.59 | F35: 5.44 | G35: 194.04 | H35: =(E35+F35)/D35 -> 1.023091 | I35: 1055.58 | J35: 0.89 | K35: =J35/D35 -> 0.0037777495 | L35: =J35*G35 -> 172.6956 | M35: =((E35+F35)-D35)-J35 -> 4.55 | N35: =M35/D35 -> 0.019313214 | O35: 組合室 | P35: 取樣不穩 | Q35: 冰杓定量挖取(使用量上會較起伏)，持續上抽測確認人員使用準確度 | R35: 鮪魚起司溏心蛋三明治
A36: 9 | B36: (V)電解消毒小黃瓜絲 | C36: 810.52 | D36: 100.7 | E36: 100.7 | F36: 10.02 | G36: 160.5 | H36: =(E36+F36)/D36 -> 1.0995035 | I36: 1608.21 | J36: 4.97 | K36: =J36/D36 -> 0.049354518 | L36: =J36*G36 -> 797.685 | M36: =((E36+F36)-D36)-J36 -> 5.05 | N36: =M36/D36 -> 0.050148957 | O36: 組合端 | P36: 取樣不穩 | Q36: 人員抓樣手感不穩 | R36: 共用類
A37: 10 | B37: 打發QQ泰奶 | C37: 804.45 | D37: 188.95 | E37: 188.95 | F37: 4.99 | G37: 195.73 | H37: =(E37+F37)/D37 -> 1.0264091 | I37: 976.69 | J37: 0.88 | K37: =J37/D37 -> 0.0046573168 | L37: =J37*G37 -> 172.2424 | M37: =((E37+F37)-D37)-J37 -> 4.11 | N37: =M37/D37 -> 0.021751786 | O37: 組合室 | P37: 取樣不穩 | Q37: 冰杓定量挖取(使用量上會較起伏)，持續上抽測確認人員使用準確度 | R37: 泰奶奶蓋QQ三明治
A39: 共用類報廢金額前十名半成品
A40: 明細展開
A41: 排序 | B41: 半成品
B42: 名稱 | C42: 報廢金額 排序 | D42: 共用類總金額 占比
A44: 1 | B44: 墨西哥餅皮-原味(8英吋)新 | C44: 1882.54 | D44: =C44/$L$5 -> 0.27414979
...

Sheet 0928分析標準表 
A1: 新豐廠半成品管理分析
A2: 日期 | C2: 營業額 | D2: 報廢展開 | F2: 超用展開 | H2: 報廢展開 | J2: 超用展開 | L2: 報廢展開
A3: 45928 | C3: 4811205.6 | D3: 總報廢 | F3: 總超用 | H3: 報廢-前10名 | J3: 超用-前10名 | L3: 共用類-總報廢
D4: 金額 | E4: 占比(營業額) | F4: 金額 | G4: 占比(營業額) | H4: 金額 | I4: 占比(總報廢) | J4: 金額 | K4: 占比(總超用) | L4: 金額 | M4: 占比(總報廢)
A5: 年度KPI目標0.25% | D5: 11593.48 | E5: =D5/C3 -> 0.0024096829 | F5: 36480.86 | G5: =F5/C3 -> 0.0075824779 | H5: =SUM(C12:C21) -> 4491.5 | I5: =H5/D5 -> 0.38741603 | J5: =SUM(C28:C37) -> 26313.58 | K5: =J5/F5 -> 0.72129824 | L5: 4670.33 | M5: =L5/D5 -> 0.40284108
A7: 報廢金額前十名半成品
A8: 明細展開 | D8: 生產資訊 | O8: 類別 | P8: 分析原因 (請填寫8大原因) | Q8: 其他原因說明 | R8: 備註-商品名稱
A9: 排序 | B9: 半成品 | D9: 生產端 | J9: 組合端
B10: 名稱 | C10: 報廢金額 排序 | D10: 產出量 | J10: 報廢 | L10: 超用
D11: 訂單需求 (kg) | E11: 實際產出 (kg) | F11: 補單 (kg) | G11: 單價 (元) | H11: 實際生產 (對比訂單需求) | I11: 差異 (元) | J11: kg | K11: 占比 | L11: kg | M11: 占比 | N11: 金額 (元)
A12: 1 | B12: 墨西哥餅皮-原味(8英吋)新 | C12: 1367.32 | D12: 5316 | E12: 5316 | F12: 207.8 | G12: 6.58 | H12: =(E12+F12)/D12 -> 1.0390895 | I12: 1367.32 | J12: 207.8 | K12: =J12/D12 -> 0.039089541 | L12: =((E12+F12)-D12)-J12 -> 0 | M12: =L12/D12 -> 0 | N12: =L12*G12 -> 0 | O12: 原物料 | P12: 原物料規格 | Q12: 菜梗太硬導致捲的時候破損 | R12: 共用類
A13: 2 | B13: 義美業務用馬芬堡 | C13: 704.06 | D13: 12896 | E13: 12896 | F13: 121.39 | G13: 5.8 | H13: =(E13+F13)/D13 -> 1.009413 | I13: 704.06 | J13: 121.39 | K13: =J13/D13 -> 0.0094129963 | L13: =((E13+F13)-D13)-J13 -> -5.8264504e-13 | M13: =L13/D13 -> -4.5180292e-17 | N13: =L13*G13 -> -3.3793413e-12 | O13: 組合端 | P13: 其他原因 | Q13: 1.包材過於貼體2.堡體無完全切斷分離，人員抓破損壞 | R13: 共用類
A14: 3 | B14: 全熟香雞堡CL(全) | C14: 606.31 | D14: 2662 | E14: 2662 | F14: 84.21 | G14: 7.2 | H14: =(E14+F14)/D14 -> 1.0316341 | I14: 606.31 | J14: 84.21 | K14: =J14/D14 -> 0.03163411 | L14: =((E14+F14)-D14)-J14 -> 0 | M14: =L14/D14 -> 0 | N14: =L14*G14 -> 0 | O14: 組合端 | P14: 其他原因 | Q14: 包材過於貼體 | R14: 香雞蛋堡(112年)
A15: 4 | B15: 拌水果莎莎醬1.2細麵 | C15: 491.23 | D15: 259.7 | E15: 259.7 | F15: 16 | G15: 61.25 | H15: =(E15+F15)/D15 -> 1.0616095 | I15: 980 | J15: 8.02 | K15: =J15/D15 -> 0.030881787 | L15: =((E15+F15)-D15)-J15 -> 7.98 | M15: =L15/D15 -> 0.030727763 | N15: =L15*G15 -> 488.775 | O15: 組合端 | P15: 取樣不穩 | Q15: 秤重物料，秤重精準度須持續校正 | R15: 莎莎烤雞麵沙拉
A16: 5 | B16: 墨西哥餅皮-菠菜(8英吋)新 | C16: 322.14 | D16: 6468 | E16: 6468 | F16: 46.02 | G16: 7 | H16: =(E16+F16)/D16 -> 1.007115 | I16: 322.14 | J16: 46.02 | K16: =J16/D16 -> 0.0071150278 | L16: =((E16+F16)-D16)-J16 -> 4.3343107e-13 | M16: =L16/D16 -> 6.7011606e-17 | N16: =L16*G16 -> 3.0340175e-12 | O16: 原物料 | P16: 原物料規格 | Q16: 菜梗太硬導致捲的時候破損 | R16: 共用類
A17: 6 | B17: 切新重煙燻火腿0.9mm | C17: 223.53 | D17: 101.08 | E17: 101.08 | F17: 2.1 | G17: 212.89 | H17: =(E17+F17)/D17 -> 1.0207756 | I17: 447.07 | J17: 1.05 | K17: =J17/D17 -> 0.010387812 | L17: =((E17+F17)-D17)-J17 -> 1.05 | M17: =L17/D17 -> 0.010387812 | N17: =L17*G17 -> 223.5345 | O17: 組合端 | P17: 取樣不穩 | Q17: 人員抓樣手感不穩 | R17: 共用類
A18: 7 | B18: 電解消毒混合紅K高麗絲 | C18: 207.58 | D18: 75.48 | E18: 75.48 | F18: 4.07 | G18: 104.84 | H18: =(E18+F18)/D18 -> 1.0539216 | I18: 426.7 | J18: 1.98 | K18: =J18/D18 -> 0.026232114 | L18: =((E18+F18)-D18)-J18 -> 2.09 | M18: =L18/D18 -> 0.027689454 | N18: =L18*G18 -> 219.1156 | O18: 組合端 | P18: 取樣不穩 | Q18: 人員抓樣手感不穩 | R18: 共用類
A19: 8 | B19: 義美4吋芝麻漢堡 | C19: 191.84 | D19: 5507 | E19: 5507 | F19: 43.6 | G19: 4.4 | H19: =(E19+F19)/D19 -> 1.0079172 | I19: 191.84 | J19: 43.6 | K19: =J19/D19 -> 0.0079171963 | L19: =((E19+F19)-D19)-J19 -> 3.623768e-13 | M19: =L19/D19 -> 6.5802941e-17 | N19: =L19*G19 -> 1.5944579e-12 | O19: 組合端 | P19: 其他原因 | Q19: 包材過於貼體 | R19: 共用類
A20: 9 | B20: 韓式泡菜豆腐蘿蔔絲 | C20: 189.37 | D20: 67.35 | E20: 67.35 | F20: 3.63 | G20: 110.1 | H20: =(E20+F20)/D20 -> 1.0538976 | I20: 399.66 | J20: 1.72 | K20: =J20/D20 -> 0.025538233 | L20: =((E20+F20)-D20)-J20 -> 1.91 | M20: =L20/D20 -> 0.028359317 | N20: =L20*G20 -> 210.291 | O20: 組合端 | P20: 取樣不穩 | Q20: 秤重物料，秤重精準度須持續校正 | R20: 共用類
A21: 10 | B21: 烤鹹蛋黃碎 | C21: 188.12 | D21: 9.17 | E21: 9.17 | F21: 0.24 | G21: 1567.63 | H21: =(E21+F21)/D21 -> 1.0261723 | I21: 376.23 | J21: 0.12 | K21: =J21/D21 -> 0.01308615 | L21: =((E21+F21)-D21)-J21 -> 0.12 | M21: =L21/D21 -> 0.01308615 | N21: =L21*G21 -> 188.1156 | O21: 組合端 | P21: 取樣不穩 | Q21: 人員抓樣手感不穩 | R21: 二配美味蟹煲
A23: 超用金額前十名半成品
A24: 明細展開 | D24: 生產資訊 | O24: 類別 | P24: 分析原因 (請填寫8大原因) | Q24: 其他原因說明 | R24: 備註-商品名稱
A25: 排序 | B25: 半成品 | D25: 生產端 | J25: 組合端
B26: 名稱 | C26: 超用金額 排序 | D26: 產出量 | J26: 報廢 | M26: 超用
D27: 訂單需求 (kg) | E27: 實際產出 (kg) | F27: 補單 (kg) | G27: 單價 (元) | H27: 實際生產 (對比訂單需求) | I27: 差異 (元) | J27: kg | K27: 占比 | L27: 金額 (元) | M27: kg | N27: 占比
A28: 1 | B28: 電解消毒牛蕃茄切片(中) | C28: 8933.94 | D28: 76.19 | E28: 108.24 | F28: 0 | G28: 278.75 | H28: =(E28+F28)/D28 -> 1.4206589 | I28: 8933.94 | J28: 0 | K28: =J28/D28 -> 0 | L28: =J28*G28 -> 0 | M28: =((E28+F28)-D28)-J28 -> 32.05 | N28: =M28/D28 -> 0.42065888 | O28: 原物料 | P28: 原物料規格 | Q28: 物料規格過大(商品1顆開10片)，造成重量投入過多 | R28: 共用類
A29: 2 | B29: 烤卜蜂紐奧良腿排(減鈉版) | C29: 5325 | D29: 7064 | E29: 7064 | F29: 300 | G29: 17.75 | H29: =(E29+F29)/D29 -> 1.0424689 | I29: 5325 | J29: 0 | K29: =J29/D29 -> 0 | L29: =J29*G29 -> 0 | M29: =((E29+F29)-D29)-J29 -> 300 | N29: =M29/D29 -> 0.042468856 | O29: 原物料 | P29: 原物料規格 | Q29: 塊肉過畸形，MD強制尾端補肉 | R29: 紐奧良風味烤雞鮮蔬三明治
A30: 3 | B30: 川燙醃嫩化淨零碳排牛肉片 | C30: 2108.67 | D30: 36.46 | E30: 36.46 | F30: 2.81 | G30: 814.16 | H30: =(E30+F30)/D30 -> 1.0770708 | I30: 2287.79 | J30: 0.22 | K30: =J30/D30 -> 0.0060340099 | L30: =J30*G30 -> 179.1152 | M30: =((E30+F30)-D30)-J30 -> 2.59 | N30: =M30/D30 -> 0.071036753 | O30: 組合室 | P30: 研發設定 | Q30: 秤重物料，秤重精準度須持續校正(過多難剝除) | R30: 二配港式香滑嫩蛋牛肉燴飯
A31: 4 | B31: 炒壽喜燒牛培根 | C31: 1879.11 | D31: 64.16 | E31: 64.16 | F31: 4.94 | G31: 417.58 | H31: =(E31+F31)/D31 -> 1.076995 | I31: 2062.85 | J31: 0.44 | K31: =J31/D31 -> 0.0068578554 | L31: =J31*G31 -> 183.7352 | M31: =((E31+F31)-D31)-J31 -> 4.5 | N31: =M31/D31 -> 0.070137157 | O31: 組合室 | P31: 取樣不穩 | Q31: 秤重物料，秤重精準度須持續校正 | R31: 白味噌壽喜燒飯
A32: 5 | B32: 電解消毒對切整葉廣東A | C32: 1743.61 | D32: 79.75 | E32: 79.75 | F32: 6.14 | G32: 313.6 | H32: =(E32+F32)/D32 -> 1.0769906 | I32: 1925.5 | J32: 0.58 | K32: =J32/D32 -> 0.0072727273 | L32: =J32*G32 -> 181.888 | M32: =((E32+F32)-D32)-J32 -> 5.56 | N32: =M32/D32 -> 0.069717868 | O32: 組合室 | P32: 取樣不穩 | Q32: 原物料特性，梗葉比例重量差異，抓樣不穩 | R32: 共用類
A33: 6 | B33: 油亮蒜味香腸片 | C33: 1486.56 | D33: 85.06 | E33: 85.06 | F33: 5.24 | G33: 318.32 | H33: =(E33+F33)/D33 -> 1.0616036 | I33: 1668 | J33: 0.57 | K33: =J33/D33 -> 0.0067011521 | L33: =J33*G33 -> 181.4424 | M33: =((E33+F33)-D33)-J33 -> 4.67 | N33: =M33/D33 -> 0.054902422 | O33: 組合室 | P33: 研發設定 | Q33: 秤重物料，秤重精準度須持續校正(過多難剝除) | R33: 二配香辣醬蒜味香腸蛋炒飯
A34: 7 | B34: 辛口咖哩豬肉(112年) | C34: 1298.87 | D34: 72.12 | E34: 72.12 | F34: 4.44 | G34: 333.9 | H34: =(E34+F34)/D34 -> 1.0615641 | I34: 1482.52 | J34: 0.55 | K34: =J34/D34 -> 0.0076261786 | L34: =J34*G34 -> 183.645 | M34: =((E34+F34)-D34)-J34 -> 3.89 | N34: =M34/D34 -> 0.053937881 | O34: 組合室 | P34: 研發設定 | Q34: 秤重物料，秤重精準度須持續校正(過多難剝除) | R34: 二配金咖哩濃厚辛辣咖哩飯
A35: 8 | B35: 蒸鼎泰豐香辣醬 | C35: 1265.29 | D35: 25.29 | E35: 25.29 | F35: 1.56 | G35: 930.36 | H35: =(E35+F35)/D35 -> 1.0616845 | I35: 1451.36 | J35: 0.2 | K35: =J35/D35 -> 0.0079082641 | L35: =J35*G35 -> 186.072 | M35: =((E35+F35)-D35)-J35 -> 1.36 | N35: =M35/D35 -> 0.053776196 | O35: 組合室 | P35: 取樣不穩 | Q35: 冰杓定量挖取(使用量上會較起伏)，持續上抽測確認人員使用準確度 | R35: 二配香辣醬蒜味香腸蛋炒飯
A36: 9 | B36: 蒸基礎風味雞肉絲 | C36: 1246.89 | D36: 75.48 | E36: 75.48 | F36: 3.49 | G36: 410.16 | H36: =(E36+F36)/D36 -> 1.0462374 | I36: 1431.46 | J36: 0.45 | K36: =J36/D36 -> 0.0059618442 | L36: =J36*G36 -> 184.572 | M36: =((E36+F36)-D36)-J36 -> 3.04 | N36: =M36/D36 -> 0.04027557 | O36: 組合室 | P36: 取樣不穩 | Q36: 秤重物料，秤重精準度須持續校正 | R36: 共用類
A37: 10 | B37: 電解消毒美生菜(三明治用) | C37: 1025.64 | D37: 77.09 | E37: 77.09 | F37: 5.94 | G37: 203.5 | H37: =(E37+F37)/D37 -> 1.0770528 | I37: 1208.79 | J37: 0.9 | K37: =J37/D37 -> 0.011674666 | L37: =J37*G37 -> 183.15 | M37: =((E37+F37)-D37)-J37 -> 5.04 | N37: =M37/D37 -> 0.065378129 | O37: 組合室 | P37: 取樣不穩 | Q37: 原物料特性，梗葉比例重量差異，抓樣不穩 | R37: 共用類
A39: 共用類報廢金額前十名半成品
A40: 明細展開
A41: 排序 | B41: 半成品
B42: 名稱 | C42: 報廢金額 排序 | D42: 共用類總金額 占比
A44: 1 | B44: 墨西哥餅皮-原味(8英吋)新 | C44: 1367.32 | D44: =C44/$L$5 -> 0.29276732
...

Sheet 0927分析標準表 
A1: 新豐廠半成品管理分析
A2: 日期 | C2: 營業額 | D2: 報廢展開 | F2: 超用展開 | H2: 報廢展開 | J2: 超用展開 | L2: 報廢展開
A3: 45927 | C3: 4423149.8 | D3: 總報廢 | F3: 總超用 | H3: 報廢-前10名 | J3: 超用-前10名 | L3: 共用類-總報廢
D4: 金額 | E4: 占比(營業額) | F4: 金額 | G4: 占比(營業額) | H4: 金額 | I4: 占比(總報廢) | J4: 金額 | K4: 占比(總超用) | L4: 金額 | M4: 占比(總報廢)
A5: 年度KPI目標0.25% | D5: 10619.51 | E5: =D5/C3 -> 0.0024008932 | F5: 33137.94 | G5: =F5/C3 -> 0.0074919326 | H5: =SUM(C12:C21) -> 3691.15 | I5: =H5/D5 -> 0.34758195 | J5: =SUM(C28:C37) -> 15895.3 | K5: =J5/F5 -> 0.47967073 | L5: 4273.36 | M5: =L5/D5 -> 0.40240651
A7: 報廢金額前十名半成品
A8: 明細展開 | D8: 生產資訊 | O8: 類別 | P8: 分析原因 (請填寫8大原因) | Q8: 其他原因說明 | R8: 備註-商品名稱
A9: 排序 | B9: 半成品 | D9: 生產端 | J9: 組合端
B10: 名稱 | C10: 報廢金額 排序 | D10: 產出量 | J10: 報廢 | L10: 超用
D11: 訂單需求 (kg) | E11: 實際產出 (kg) | F11: 補單 (kg) | G11: 單價 (元) | H11: 實際生產 (對比訂單需求) | I11: 差異 (元) | J11: kg | K11: 占比 | L11: kg | M11: 占比 | N11: 金額 (元)
A12: 1 | B12: 墨西哥餅皮-原味(8英吋)新 | C12: 1380.75 | D12: 4830 | E12: 4830 | F12: 209.84 | G12: 6.58 | H12: =(E12+F12)/D12 -> 1.0434451 | I12: 1380.75 | J12: 209.84 | K12: =J12/D12 -> 0.043445135 | L12: =((E12+F12)-D12)-J12 -> 0 | M12: =L12/D12 -> 0 | N12: =L12*G12 -> 0 | O12: 原物料 | P12: 原物料規格 | Q12: 菜梗太硬導致捲的時候破損 | R12: 共用類
A13: 2 | B13: 義美業務用馬芬堡 | C13: 765.66 | D13: 11603 | E13: 11603 | F13: 132.01 | G13: 5.8 | H13: =(E13+F13)/D13 -> 1.0113772 | I13: 765.66 | J13: 132.01 | K13: =J13/D13 -> 0.01137723 | L13: =((E13+F13)-D13)-J13 -> 2.2737368e-13 | M13: =L13/D13 -> 1.9596111e-17 | N13: =L13*G13 -> 1.3187673e-12 | O13: 組合端 | P13: 其他原因 | Q13: 1.包材過於貼體2.堡體無完全切斷分離，人員抓破損壞 | R13: 共用類
A14: 3 | B14: 墨西哥餅皮-菠菜(8英吋)新 | C14: 381.57 | D14: 6254 | E14: 6254 | F14: 54.51 | G14: 7 | H14: =(E14+F14)/D14 -> 1.008716 | I14: 381.57 | J14: 54.51 | K14: =J14/D14 -> 0.0087160217 | L14: =((E14+F14)-D14)-J14 -> 2.2026825e-13 | M14: =L14/D14 -> 3.5220379e-17 | N14: =L14*G14 -> 1.5418777e-12 | O14: 原物料 | P14: 原物料規格 | Q14: 菜梗太硬導致捲的時候破損 | R14: 共用類
A15: 4 | B15: 拌總匯雞蛋沙拉CL(112年) | C15: 297.46 | D15: 183.52 | E15: 183.52 | F15: 10 | G15: 95.34 | H15: =(E15+F15)/D15 -> 1.05449 | I15: 953.4 | J15: 3.12 | K15: =J15/D15 -> 0.017000872 | L15: =((E15+F15)-D15)-J15 -> 6.88 | M15: =L15/D15 -> 0.037489102 | N15: =L15*G15 -> 655.9392 | O15: 組合端 | P15: 取樣不穩 | Q15: 人員冰杓定量手法不穩 | R15: 共用類
A16: 5 | B16: 炒辛口紅蘿蔔丁(112年) | C16: 268.5 | D16: 60.79 | E16: 60.79 | F16: 6.07 | G16: 90.1 | H16: =(E16+F16)/D16 -> 1.0998519 | I16: 546.91 | J16: 2.98 | K16: =J16/D16 -> 0.049021221 | L16: =((E16+F16)-D16)-J16 -> 3.09 | M16: =L16/D16 -> 0.050830729 | N16: =L16*G16 -> 278.409 | O16: 原物料 | P16: 原物料規格 | Q16: 原物料廠商無過篩，大小差異大 | R16: 二配金咖哩濃厚辛辣咖哩飯
A17: 6 | B17: 電解消毒混合蔥鹽蔬菜絲 | C17: 204.66 | D17: 35.07 | E17: 35.07 | F17: 3.5 | G17: 118.99 | H17: =(E17+F17)/D17 -> 1.0998004 | I17: 416.47 | J17: 1.72 | K17: =J17/D17 -> 0.049044768 | L17: =((E17+F17)-D17)-J17 -> 1.78 | M17: =L17/D17 -> 0.050755632 | N17: =L17*G17 -> 211.8022 | O17: 組合端 | P17: 取樣不穩 | Q17: 人員抓樣手感不穩 | R17: 蔥鹽雞肉麵沙拉(114年)
A18: 7 | B18: 電解消毒雙色高麗菜絲(7:3) | C18: 115.97 | D18: 169.05 | E18: 169.05 | F18: 3.67 | G18: 99.12 | H18: =(E18+F18)/D18 -> 1.0217096 | I18: 363.77 | J18: 1.17 | K18: =J18/D18 -> 0.0069210293 | L18: =((E18+F18)-D18)-J18 -> 2.5 | M18: =L18/D18 -> 0.014788524 | N18: =L18*G18 -> 247.8 | O18: 組合端 | P18: 取樣不穩 | Q18: 人員抓樣手感不穩 | R18: 共用類
A19: 8 | B19: 炒紅K洋蔥片 | C19: 113.87 | D19: 24.2 | E19: 24.2 | F19: 2.42 | G19: 112.74 | H19: =(E19+F19)/D19 -> 1.1 | I19: 272.83 | J19: 1.01 | K19: =J19/D19 -> 0.041735537 | L19: =((E19+F19)-D19)-J19 -> 1.41 | M19: =L19/D19 -> 0.058264463 | N19: =L19*G19 -> 158.9634 | O19: 組合端 | P19: 取樣不穩 | Q19: 人員抓樣手感不穩 | R19: 白味噌壽喜燒飯
A20: 9 | B20: 電解消毒紫洋蔥(去皮)切絲 | C20: 88.28 | D20: 26.04 | E20: 26.04 | F20: 1.81 | G20: 113.18 | H20: =(E20+F20)/D20 -> 1.0695084 | I20: 204.86 | J20: 0.78 | K20: =J20/D20 -> 0.029953917 | L20: =((E20+F20)-D20)-J20 -> 1.03 | M20: =L20/D20 -> 0.039554531 | N20: =L20*G20 -> 116.5754 | O20: 組合端 | P20: 取樣不穩 | Q20: 人員抓樣手感不穩 | R20: 莎莎烤雞麵沙拉
A21: 10 | B21: 蒸鼎泰豐香辣醬 | C21: 74.43 | D21: 21.97 | E21: 21.97 | F21: 0.55 | G21: 930.36 | H21: =(E21+F21)/D21 -> 1.0250341 | I21: 511.7 | J21: 0.08 | K21: =J21/D21 -> 0.0036413291 | L21: =((E21+F21)-D21)-J21 -> 0.47 | M21: =L21/D21 -> 0.021392808 | N21: =L21*G21 -> 437.2692 | O21: 組合端 | P21: 取樣不穩 | Q21: 人員冰杓定量手法不穩 | R21: 二配香辣醬蒜味香腸蛋炒飯
A23: 超用金額前十名半成品
A24: 明細展開 | D24: 生產資訊 | O24: 類別 | P24: 分析原因 (請填寫8大原因) | Q24: 其他原因說明 | R24: 備註-商品名稱
A25: 排序 | B25: 半成品 | D25: 生產端 | J25: 組合端
B26: 名稱 | C26: 超用金額 排序 | D26: 產出量 | J26: 報廢 | M26: 超用
D27: 訂單需求 (kg) | E27: 實際產出 (kg) | F27: 補單 (kg) | G27: 單價 (元) | H27: 實際生產 (對比訂單需求) | I27: 差異 (元) | J27: kg | K27: 占比 | L27: 金額 (元) | M27: kg | N27: 占比
A28: 1 | B28: 電解消毒牛蕃茄切片(中) | C28: 7637.75 | D28: 67.51 | E28: 94.91 | F28: 0 | G28: 278.75 | H28: =(E28+F28)/D28 -> 1.4058658 | I28: 7637.75 | J28: 0 | K28: =J28/D28 -> 0 | L28: =J28*G28 -> 0 | M28: =((E28+F28)-D28)-J28 -> 27.4 | N28: =M28/D28 -> 0.4058658 | O28: 原物料 | P28: 原物料規格 | Q28: 物料規格過大(商品1顆開10片)，造成重量投入過多 | R28: 共用類
A29: 2 | B29: 烤卜蜂紐奧良腿排(減鈉版) | C29: 1775 | D29: 5607 | E29: 5607 | F29: 100 | G29: 17.75 | H29: =(E29+F29)/D29 -> 1.0178348 | I29: 1775 | J29: 0 | K29: =J29/D29 -> 0 | L29: =J29*G29 -> 0 | M29: =((E29+F29)-D29)-J29 -> 100 | N29: =M29/D29 -> 0.017834849 | O29: 原物料 | P29: 原物料規格 | Q29: 塊肉過畸形，MD強制尾端補肉 | R29: 紐奧良風味烤雞鮮蔬三明治
A30: 3 | B30: 果香甘口咖哩醬 | C30: 826.29 | D30: 513.73 | E30: 513.73 | F30: 11.38 | G30: 78.77 | H30: =(E30+F30)/D30 -> 1.0221517 | I30: 896.4 | J30: 0.89 | K30: =J30/D30 -> 0.0017324275 | L30: =J30*G30 -> 70.1053 | M30: =((E30+F30)-D30)-J30 -> 10.49 | N30: =M30/D30 -> 0.020419286 | O30: 組合室 | P30: 取樣不穩 | Q30: 注餡機使用(機器出料就有落差)，人員持續於線上不定時抽測重量 | R30: 二配金咖哩果香甘口咖哩飯
A31: 4 | B31: 鼎泰豐-煮麻婆豆腐(113年) | C31: 812.65 | D31: 283.3 | E31: 283.3 | F31: 6.59 | G31: 133.88 | H31: =(E31+F31)/D31 -> 1.0232616 | I31: 882.27 | J31: 0.52 | K31: =J31/D31 -> 0.0018355101 | L31: =J31*G31 -> 69.6176 | M31: =((E31+F31)-D31)-J31 -> 6.07 | N31: =M31/D31 -> 0.02142605 | O31: 組合室 | P31: 取樣不穩 | Q31: 秤重物料，秤重精準度須持續校正 | R31: 二配川味麻婆燒豆腐燴飯
A32: 5 | B32: 蟹粉燴汁(114年) | C32: 809.28 | D32: 419.68 | E32: 419.68 | F32: 11.51 | G32: 76.42 | H32: =(E32+F32)/D32 -> 1.0274257 | I32: 879.59 | J32: 0.92 | K32: =J32/D32 -> 0.0021921464 | L32: =J32*G32 -> 70.3064 | M32: =((E32+F32)-D32)-J32 -> 10.59 | N32: =M32/D32 -> 0.025233511 | O32: 組合室 | P32: 取樣不穩 | Q32: 冰杓定量挖取(使用量上會較起伏)，持續上抽測確認人員使用準確度 | R32: 二配美味蟹煲
A33: 6 | B33: 打發QQ泰奶 | C33: 808.37 | D33: 195.24 | E33: 195.24 | F33: 4.49 | G33: 195.73 | H33: =(E33+F33)/D33 -> 1.0229973 | I33: 878.83 | J33: 0.36 | K33: =J33/D33 -> 0.0018438844 | L33: =J33*G33 -> 70.4628 | M33: =((E33+F33)-D33)-J33 -> 4.13 | N33: =M33/D33 -> 0.021153452 | O33: 組合室 | P33: 取樣不穩 | Q33: 冰杓定量挖取(使用量上會較起伏)，持續上抽測確認人員使用準確度 | R33: 泰奶奶蓋QQ三明治
A34: 7 | B34: 濃辛辣咖哩醬 | C34: 808.11 | D34: 455.94 | E34: 455.94 | F34: 11.05 | G34: 79.46 | H34: =(E34+F34)/D34 -> 1.0242356 | I34: 878.03 | J34: 0.88 | K34: =J34/D34 -> 0.0019300785 | L34: =J34*G34 -> 69.9248 | M34: =((E34+F34)-D34)-J34 -> 10.17 | N34: =M34/D34 -> 0.022305567 | O34: 組合室 | P34: 取樣不穩 | Q34: 注餡機使用(機器出料就有落差)，人員持續於線上不定時抽測重量 | R34: 二配金咖哩濃厚辛辣咖哩飯
A35: 8 | B35: 鼎泰豐-黃金蛋炒飯(112年) | C35: 807.46 | D35: 559.16 | E35: 559.16 | F35: 14.4 | G35: 60.94 | H35: =(E35+F35)/D35 -> 1.0257529 | I35: 877.54 | J35: 1.15 | K35: =J35/D35 -> 0.0020566564 | L35: =J35*G35 -> 70.081 | M35: =((E35+F35)-D35)-J35 -> 13.25 | N35: =M35/D35 -> 0.023696259 | O35: 組合室 | P35: 取樣不穩 | Q35: 秤重物料，秤重精準度須持續校正 | R35: 二配香辣醬蒜味香腸蛋炒飯
A36: 9 | B36: 川燙醃嫩化淨零碳排牛肉片 | C36: 806.02 | D36: 34.87 | E36: 34.87 | F36: 1.08 | G36: 814.16 | H36: =(E36+F36)/D36 -> 1.0309722 | I36: 879.29 | J36: 0.09 | K36: =J36/D36 -> 0.0025810152 | L36: =J36*G36 -> 73.2744 | M36: =((E36+F36)-D36)-J36 -> 0.99 | N36: =M36/D36 -> 0.028391167 | O36: 組合室 | P36: 研發設定 | Q36: 秤重物料，秤重精準度須持續校正(過多難剝除) | R36: 二配港式香滑嫩蛋牛肉燴飯
A37: 10 | B37: 海鮮醬炒飯 | C37: 804.37 | D37: 403.38 | E37: 403.38 | F37: 10.23 | G37: 85.48 | H37: =(E37+F37)/D37 -> 1.0253607 | I37: 874.46 | J37: 0.82 | K37: =J37/D37 -> 0.0020328226 | L37: =J37*G37 -> 70.0936 | M37: =((E37+F37)-D37)-J37 -> 9.41 | N37: =M37/D37 -> 0.023327879 | O37: 組合室 | P37: 取樣不穩 | Q37: 秤重物料，秤重精準度須持續校正 | R37: 二配香拌海鮮醬肉絲蛋炒飯
A39: 共用類報廢金額前十名半成品
A40: 明細展開
A41: 排序 | B41: 半成品
B42: 名稱 | C42: 報廢金額 排序 | D42: 共用類總金額 占比
A44: 1 | B44: 墨西哥餅皮-原味(8英吋)新 | C44: 1380.75 | D44: =C44/$L$5 -> 0.32310641
...

Sheet 0926分析標準表 
A1: 新豐廠半成品管理分析
A2: 日期 | C2: 營業額 | D2: 報廢展開 | F2: 超用展開 | H2: 報廢展開 | J2: 超用展開 | L2: 報廢展開
A3: 45926 | C3: 4389261 | D3: 總報廢 | F3: 總超用 | H3: 報廢-前10名 | J3: 超用-前10名 | L3: 共用類-總報廢
D4: 金額 | E4: 占比(營業額) | F4: 金額 | G4: 占比(營業額) | H4: 金額 | I4: 占比(總報廢) | J4: 金額 | K4: 占比(總超用) | L4: 金額 | M4: 占比(總報廢)
A5: 年度KPI目標0.25% | D5: 10529.22 | E5: =D5/C3 -> 0.0023988594 | F5: 33245.57 | G5: =F5/C3 -> 0.0075742978 | H5: =SUM(C12:C21) -> 4222.15 | I5: =H5/D5 -> 0.40099362 | J5: =SUM(C28:C37) -> 18059.48 | K5: =J5/F5 -> 0.54321463 | L5: 3343.82 | M5: =L5/D5 -> 0.31757528
A7: 報廢金額前十名半成品
A8: 明細展開 | D8: 生產資訊 | O8: 類別 | P8: 分析原因 (請填寫8大原因) | Q8: 其他原因說明 | R8: 備註-商品名稱
A9: 排序 | B9: 半成品 | D9: 生產端 | J9: 組合端
B10: 名稱 | C10: 報廢金額 排序 | D10: 產出量 | J10: 報廢 | L10: 超用
D11: 訂單需求 (kg) | E11: 實際產出 (kg) | F11: 補單 (kg) | G11: 單價 (元) | H11: 實際生產 (對比訂單需求) | I11: 差異 (元) | J11: kg | K11: 占比 | L11: kg | M11: 占比 | N11: 金額 (元)
A12: 1 | B12: 義美業務用馬芬堡 | C12: 1532.71 | D12: 11714 | E12: 11714 | F12: 264.26 | G12: 5.8 | H12: =(E12+F12)/D12 -> 1.0225593 | I12: 1532.71 | J12: 264.26 | K12: =J12/D12 -> 0.022559331 | L12: =((E12+F12)-D12)-J12 -> 0 | M12: =L12/D12 -> 0 | N12: =L12*G12 -> 0 | O12: 組合端 | P12: 其他原因 | Q12: 1.包材過於貼體2.堡體無完全切斷分離，人員抓破損壞 | R12: 共用類
A13: 2 | B13: 打發QQ植鮮 | C13: 951.81 | D13: 151.09 | E13: 151.09 | F13: 12.26 | G13: 155.27 | H13: =(E13+F13)/D13 -> 1.0811437 | I13: 1903.61 | J13: 6.13 | K13: =J13/D13 -> 0.040571845 | L13: =((E13+F13)-D13)-J13 -> 6.13 | M13: =L13/D13 -> 0.040571845 | N13: =L13*G13 -> 951.8051 | O13: 組合端 | P13: 取樣不穩 | Q13: 人員冰杓定量手法不穩 | R13: 泰奶奶蓋QQ三明治
A14: 3 | B14: 打發QQ泰奶 | C14: 825.98 | D14: 172.68 | E14: 172.68 | F14: 9.19 | G14: 195.73 | H14: =(E14+F14)/D14 -> 1.0532198 | I14: 1798.76 | J14: 4.22 | K14: =J14/D14 -> 0.024438267 | L14: =((E14+F14)-D14)-J14 -> 4.97 | M14: =L14/D14 -> 0.028781561 | N14: =L14*G14 -> 972.7781 | O14: 組合端 | P14: 取樣不穩 | Q14: 人員冰杓定量手法不穩 | R14: 泰奶奶蓋QQ三明治
A15: 4 | B15: 墨西哥餅皮-菠菜(8英吋)新 | C15: 335.58 | D15: 6043 | E15: 6043 | F15: 47.94 | G15: 7 | H15: =(E15+F15)/D15 -> 1.0079331 | I15: 335.58 | J15: 47.94 | K15: =J15/D15 -> 0.0079331458 | L15: =((E15+F15)-D15)-J15 -> -3.9790393e-13 | M15: =L15/D15 -> -6.584543e-17 | N15: =L15*G15 -> -2.7853275e-12 | O15: 原物料 | P15: 原物料規格 | Q15: 菜梗太硬導致捲的時候破損 | R15: 共用類
A16: 5 | B16: 義美4吋芝麻漢堡 | C16: 220.53 | D16: 4993 | E16: 4993 | F16: 50.12 | G16: 4.4 | H16: =(E16+F16)/D16 -> 1.0100381 | I16: 220.53 | J16: 50.12 | K16: =J16/D16 -> 0.010038053 | L16: =((E16+F16)-D16)-J16 -> -1.0658141e-13 | M16: =L16/D16 -> -2.1346167e-17 | N16: =L16*G16 -> -4.6895821e-13 | O16: 組合端 | P16: 其他原因 | Q16: 包材過於貼體 | R16: 共用類
A17: 6 | B17: 四吋芝麻漢堡 | C17: 89.78 | D17: 3983 | E17: 3983 | F17: 20.64 | G17: 4.35 | H17: =(E17+F17)/D17 -> 1.005182 | I17: 89.78 | J17: 20.64 | K17: =J17/D17 -> 0.0051820236 | L17: =((E17+F17)-D17)-J17 -> -1.2789769e-13 | M17: =L17/D17 -> -3.2110894e-17 | N17: =L17*G17 -> -5.5635496e-13 | O17: 組合端 | P17: 其他原因 | Q17: 包材過於貼體 | R17: 經典雙牛起司堡(113年)
A18: 7 | B18: 自製花生奶油霜 | C18: 82.37 | D18: 34.51 | E18: 34.51 | F18: 0.72 | G18: 316.8 | H18: =(E18+F18)/D18 -> 1.0208635 | I18: 228.1 | J18: 0.26 | K18: =J18/D18 -> 0.0075340481 | L18: =((E18+F18)-D18)-J18 -> 0.46 | M18: =L18/D18 -> 0.01332947 | N18: =L18*G18 -> 145.728 | O18: 組合端 | P18: 取樣不穩 | Q18: 人員冰杓定量手法不穩 | R18: 花生芝麻麻糬三明治
A19: 8 | B19: 烤鹹蛋黃碎 | C19: 62.71 | D19: 7.42 | E19: 7.42 | F19: 0.1 | G19: 1567.63 | H19: =(E19+F19)/D19 -> 1.0134771 | I19: 156.76 | J19: 0.04 | K19: =J19/D19 -> 0.0053908356 | L19: =((E19+F19)-D19)-J19 -> 0.06 | M19: =L19/D19 -> 0.0080862534 | N19: =L19*G19 -> 94.0578 | O19: 組合端 | P19: 取樣不穩 | Q19: 人員抓樣手感不穩 | R19: 二配美味蟹煲
A20: 9 | B20: 韓式泡菜豆腐蘿蔔絲 | C20: 60.56 | D20: 62.3 | E20: 62.3 | F20: 1.13 | G20: 110.1 | H20: =(E20+F20)/D20 -> 1.018138 | I20: 124.41 | J20: 0.55 | K20: =J20/D20 -> 0.0088282504 | L20: =((E20+F20)-D20)-J20 -> 0.58 | M20: =L20/D20 -> 0.0093097913 | N20: =L20*G20 -> 63.858 | O20: 組合端 | P20: 取樣不穩 | Q20: 秤重物料，秤重精準度須持續校正 | R20: 共用類
A21: 10 | B21: 全熟香雞堡CL(全) | C21: 60.12 | D21: 2378 | E21: 2378 | F21: 8.35 | G21: 7.2 | H21: =(E21+F21)/D21 -> 1.0035114 | I21: 60.12 | J21: 8.35 | K21: =J21/D21 -> 0.0035113541 | L21: =((E21+F21)-D21)-J21 -> -9.0594199e-14 | M21: =L21/D21 -> -3.8096804e-17 | N21: =L21*G21 -> -6.5227823e-13 | O21: 組合端 | P21: 其他原因 | Q21: 包材過於貼體 | R21: 香雞蛋堡(112年)
A23: 超用金額前十名半成品
A24: 明細展開 | D24: 生產資訊 | O24: 類別 | P24: 分析原因 (請填寫8大原因) | Q24: 其他原因說明 | R24: 備註-商品名稱
A25: 排序 | B25: 半成品 | D25: 生產端 | J25: 組合端
B26: 名稱 | C26: 超用金額 排序 | D26: 產出量 | J26: 報廢 | M26: 超用
D27: 訂單需求 (kg) | E27: 實際產出 (kg) | F27: 補單 (kg) | G27: 單價 (元) | H27: 實際生產 (對比訂單需求) | I27: 差異 (元) | J27: kg | K27: 占比 | L27: 金額 (元) | M27: kg | N27: 占比
A28: 1 | B28: 電解消毒牛蕃茄切片(中) | C28: 8259.36 | D28: 69.97 | E28: 99.6 | F28: 0 | G28: 278.75 | H28: =(E28+F28)/D28 -> 1.4234672 | I28: 8259.36 | J28: 0 | K28: =J28/D28 -> 0 | L28: =J28*G28 -> 0 | M28: =((E28+F28)-D28)-J28 -> 29.63 | N28: =M28/D28 -> 0.4234672 | O28: 原物料 | P28: 原物料規格 | Q28: 物料規格過大(商品1顆開10片)，造成重量投入過多 | R28: 共用類
A29: 2 | B29: 烤卜蜂紐奧良腿排(減鈉版) | C29: 3550 | D29: 6513 | E29: 6513 | F29: 200 | G29: 17.75 | H29: =(E29+F29)/D29 -> 1.0307078 | I29: 3550 | J29: 0 | K29: =J29/D29 -> 0 | L29: =J29*G29 -> 0 | M29: =((E29+F29)-D29)-J29 -> 200 | N29: =M29/D29 -> 0.030707815 | O29: 原物料 | P29: 原物料規格 | Q29: 塊肉過畸形，MD強制尾端補肉 | R29: 紐奧良風味烤雞鮮蔬三明治
A30: 3 | B30: 打發QQ泰奶 | C30: 972.78 | D30: 172.68 | E30: 172.68 | F30: 9.19 | G30: 195.73 | H30: =(E30+F30)/D30 -> 1.0532198 | I30: 1798.76 | J30: 4.22 | K30: =J30/D30 -> 0.024438267 | L30: =J30*G30 -> 825.9806 | M30: =((E30+F30)-D30)-J30 -> 4.97 | N30: =M30/D30 -> 0.028781561 | O30: 組合室 | P30: 取樣不穩 | Q30: 冰杓定量挖取(使用量上會較起伏)，持續上抽測確認人員使用準確度 | R30: 泰奶奶蓋QQ三明治
A31: 4 | B31: 打發QQ植鮮 | C31: 951.8 | D31: 151.09 | E31: 151.09 | F31: 12.26 | G31: 155.27 | H31: =(E31+F31)/D31 -> 1.0811437 | I31: 1903.61 | J31: 6.13 | K31: =J31/D31 -> 0.040571845 | L31: =J31*G31 -> 951.8051 | M31: =((E31+F31)-D31)-J31 -> 6.13 | N31: =M31/D31 -> 0.040571845 | O31: 組合室 | P31: 取樣不穩 | Q31: 冰杓定量挖取(使用量上會較起伏)，持續上抽測確認人員使用準確度 | R31: 泰奶奶蓋QQ三明治
A32: 5 | B32: 果香甘口咖哩醬 | C32: 779.82 | D32: 511.87 | E32: 511.87 | F32: 10.65 | G32: 78.77 | H32: =(E32+F32)/D32 -> 1.0208061 | I32: 838.9 | J32: 0.75 | K32: =J32/D32 -> 0.0014652158 | L32: =J32*G32 -> 59.0775 | M32: =((E32+F32)-D32)-J32 -> 9.9 | N32: =M32/D32 -> 0.019340848 | O32: 組合室 | P32: 取樣不穩 | Q32: 注餡機使用(機器出料就有落差)，人員持續於線上不定時抽測重量 | R32: 二配金咖哩果香甘口咖哩飯
A33: 6 | B33: 鼎泰豐-黃金蛋炒飯(112年) | C33: 773.33 | D33: 525.28 | E33: 525.28 | F33: 13.66 | G33: 60.94 | H33: =(E33+F33)/D33 -> 1.0260052 | I33: 832.44 | J33: 0.97 | K33: =J33/D33 -> 0.0018466342 | L33: =J33*G33 -> 59.1118 | M33: =((E33+F33)-D33)-J33 -> 12.69 | N33: =M33/D33 -> 0.024158544 | O33: 組合室 | P33: 取樣不穩 | Q33: 秤重物料，秤重精準度須持續校正 | R33: 二配香辣醬蒜味香腸蛋炒飯
A34: 7 | B34: 鼎泰豐-煮麻婆豆腐(113年) | C34: 740.35 | D34: 255.37 | E34: 255.37 | F34: 5.97 | G34: 133.88 | H34: =(E34+F34)/D34 -> 1.0233778 | I34: 799.26 | J34: 0.44 | K34: =J34/D34 -> 0.0017229902 | L34: =J34*G34 -> 58.9072 | M34: =((E34+F34)-D34)-J34 -> 5.53 | N34: =M34/D34 -> 0.021654854 | O34: 組合室 | P34: 取樣不穩 | Q34: 秤重物料，秤重精準度須持續校正 | R34: 二配川味麻婆燒豆腐燴飯
A35: 8 | B35: 炒壽喜燒牛培根 | C35: 689.01 | D35: 68.88 | E35: 68.88 | F35: 1.79 | G35: 417.58 | H35: =(E35+F35)/D35 -> 1.0259872 | I35: 747.47 | J35: 0.14 | K35: =J35/D35 -> 0.0020325203 | L35: =J35*G35 -> 58.4612 | M35: =((E35+F35)-D35)-J35 -> 1.65 | N35: =M35/D35 -> 0.023954704 | O35: 組合室 | P35: 取樣不穩 | Q35: 秤重物料，秤重精準度須持續校正 | R35: 白味噌壽喜燒飯
A36: 9 | B36: 濃辛辣咖哩醬 | C36: 672.23 | D36: 442.44 | E36: 442.44 | F36: 9.2 | G36: 79.46 | H36: =(E36+F36)/D36 -> 1.0207938 | I36: 731.03 | J36: 0.74 | K36: =J36/D36 -> 0.0016725432 | L36: =J36*G36 -> 58.8004 | M36: =((E36+F36)-D36)-J36 -> 8.46 | N36: =M36/D36 -> 0.019121237 | O36: 組合室 | P36: 取樣不穩 | Q36: 注餡機使用(機器出料就有落差)，人員持續於線上不定時抽測重量 | R36: 二配金咖哩濃厚辛辣咖哩飯
A37: 10 | B37: 電解消毒十字切美生菜 | C37: 670.8 | D37: 199.15 | E37: 199.15 | F37: 4.66 | G37: 156.73 | H37: =(E37+F37)/D37 -> 1.0233994 | I37: 730.36 | J37: 0.38 | K37: =J37/D37 -> 0.0019081095 | L37: =J37*G37 -> 59.5574 | M37: =((E37+F37)-D37)-J37 -> 4.28 | N37: =M37/D37 -> 0.021491338 | O37: 組合室 | P37: 取樣不穩 | Q37: 原物料特性，梗葉比例重量差異，抓樣不穩 | R37: 共用類
A39: 共用類報廢金額前十名半成品
A40: 明細展開
A41: 排序 | B41: 半成品
B42: 名稱 | C42: 報廢金額 排序 | D42: 共用類總金額 占比
A44: 1 | B44: 義美業務用馬芬堡 | C44: 1532.71 | D44: =C44/$L$5 -> 0.45837096
...

Sheet 0925分析標準表 
A1: 新豐廠半成品管理分析
A2: 日期 | C2: 營業額 | D2: 報廢展開 | F2: 超用展開 | H2: 報廢展開 | J2: 超用展開 | L2: 報廢展開
A3: 45925 | C3: 5545534.9 | D3: 總報廢 | F3: 總超用 | H3: 報廢-前10名 | J3: 超用-前10名 | L3: 共用類-總報廢
D4: 金額 | E4: 占比(營業額) | F4: 金額 | G4: 占比(營業額) | H4: 金額 | I4: 占比(總報廢) | J4: 金額 | K4: 占比(總超用) | L4: 金額 | M4: 占比(總報廢)
A5: 年度KPI目標0.25% | D5: 13469.4 | E5: =D5/C3 -> 0.002428873 | F5: 41918.04 | G5: =F5/C3 -> 0.0075588813 | H5: =SUM(C12:C21) -> 9556.05 | I5: =H5/D5 -> 0.70946367 | J5: =SUM(C28:C37) -> 18735.58 | K5: =J5/F5 -> 0.44695744 | L5: 9883.65 | M5: =L5/D5 -> 0.73378547
A7: 報廢金額前十名半成品
A8: 明細展開 | D8: 生產資訊 | O8: 類別 | P8: 分析原因 (請填寫8大原因) | Q8: 其他原因說明 | R8: 備註-商品名稱
A9: 排序 | B9: 半成品 | D9: 生產端 | J9: 組合端
B10: 名稱 | C10: 報廢金額 排序 | D10: 產出量 | J10: 報廢 | L10: 超用
D11: 訂單需求 (kg) | E11: 實際產出 (kg) | F11: 補單 (kg) | G11: 單價 (元) | H11: 實際生產 (對比訂單需求) | I11: 差異 (元) | J11: kg | K11: 占比 | L11: kg | M11: 占比 | N11: 金額 (元)
A12: 1 | B12: 義美業務用馬芬堡 | C12: 7269.14 | D12: 14358 | E12: 14358 | F12: 1253.3 | G12: 5.8 | H12: =(E12+F12)/D12 -> 1.0872893 | I12: 7269.14 | J12: 1253.3 | K12: =J12/D12 -> 0.087289316 | L12: =((E12+F12)-D12)-J12 -> 0 | M12: =L12/D12 -> 0 | N12: =L12*G12 -> 0 | O12: 組合端 | P12: 其他原因 | Q12: 1.包材過於貼體2.堡體無完全切斷分離，人員抓破損壞 | R12: 共用類
A13: 2 | B13: 墨西哥餅皮-菠菜(8英吋)新 | C13: 952.49 | D13: 7973 | E13: 7973 | F13: 136.07 | G13: 7 | H13: =(E13+F13)/D13 -> 1.0170663 | I13: 952.49 | J13: 136.07 | K13: =J13/D13 -> 0.017066349 | L13: =((E13+F13)-D13)-J13 -> -2.8421709e-13 | M13: =L13/D13 -> -3.5647447e-17 | N13: =L13*G13 -> -1.9895197e-12 | O13: 原物料 | P13: 原物料規格 | Q13: 菜梗太硬導致捲的時候破損 | R13: 共用類
A14: 3 | B14: 電解消毒美生菜(三明治用) | C14: 427.35 | D14: 99.14 | E14: 99.14 | F14: 4.72 | G14: 203.5 | H14: =(E14+F14)/D14 -> 1.0476094 | I14: 960.52 | J14: 2.1 | K14: =J14/D14 -> 0.021182167 | L14: =((E14+F14)-D14)-J14 -> 2.62 | M14: =L14/D14 -> 0.026427275 | N14: =L14*G14 -> 533.17 | O14: 原物料 | P14: 原物料規格 | Q14: 原物料特性，梗葉比例重量差異大 | R14: 共用類
A15: 4 | B15: 義美4吋芝麻漢堡 | C15: 406.56 | D15: 5439 | E15: 5439 | F15: 92.4 | G15: 4.4 | H15: =(E15+F15)/D15 -> 1.0169884 | I15: 406.56 | J15: 92.4 | K15: =J15/D15 -> 0.016988417 | L15: =((E15+F15)-D15)-J15 -> -3.6948222e-13 | M15: =L15/D15 -> -6.7932014e-17 | N15: =L15*G15 -> -1.6257218e-12 | O15: 組合端 | P15: 其他原因 | Q15: 包材過於貼體 | R15: 共用類
A16: 5 | B16: 煮螺旋麵(沙拉用) | C16: 175.59 | D16: 148.85 | E16: 148.85 | F16: 9.04 | G16: 39.02 | H16: =(E16+F16)/D16 -> 1.0607323 | I16: 352.74 | J16: 4.5 | K16: =J16/D16 -> 0.030231777 | L16: =((E16+F16)-D16)-J16 -> 4.54 | M16: =L16/D16 -> 0.030500504 | N16: =L16*G16 -> 177.1508 | O16: 組合端 | P16: 抓樣不穩 | Q16: 秤重物料，秤重精準度須持續校正 | R16: 蔥鹽雞肉麵沙拉(114年)
A17: 6 | B17: 電解消毒雙色高麗菜絲(7:3) | C17: 107.05 | D17: 223.83 | E17: 223.83 | F17: 2.09 | G17: 99.12 | H17: =(E17+F17)/D17 -> 1.0093374 | I17: 207.16 | J17: 1.08 | K17: =J17/D17 -> 0.0048250905 | L17: =((E17+F17)-D17)-J17 -> 1.01 | M17: =L17/D17 -> 0.0045123531 | N17: =L17*G17 -> 100.1112 | O17: 組合端 | P17: 抓樣不穩 | Q17: 人員抓樣手感不穩 | R17: 共用類
A18: 7 | B18: 四吋芝麻漢堡 | C18: 79.04 | D18: 4539 | E18: 4539 | F18: 18.17 | G18: 4.35 | H18: =(E18+F18)/D18 -> 1.0040031 | I18: 79.04 | J18: 18.17 | K18: =J18/D18 -> 0.0040030844 | L18: =((E18+F18)-D18)-J18 -> 7.1054274e-14 | M18: =L18/D18 -> 1.5654169e-17 | N18: =L18*G18 -> 3.0908609e-13 | O18: 組合端 | P18: 其他原因 | Q18: 包材過於貼體 | R18: 經典雙牛起司堡(113年)
A19: 8 | B19: 韓式泡菜豆腐蘿蔔絲 | C19: 53.95 | D19: 85.8 | E19: 85.8 | F19: 0.99 | G19: 110.1 | H19: =(E19+F19)/D19 -> 1.0115385 | I19: 109 | J19: 0.49 | K19: =J19/D19 -> 0.0057109557 | L19: =((E19+F19)-D19)-J19 -> 0.5 | M19: =L19/D19 -> 0.0058275058 | N19: =L19*G19 -> 55.05 | O19: 組合端 | P19: 抓樣不穩 | Q19: 秤重物料，秤重精準度須持續校正 | R19: 共用類
A20: 9 | B20: 電解消毒混合紅K高麗絲 | C20: 47.18 | D20: 90.82 | E20: 90.82 | F20: 1.03 | G20: 104.84 | H20: =(E20+F20)/D20 -> 1.0113411 | I20: 107.99 | J20: 0.45 | K20: =J20/D20 -> 0.0049548558 | L20: =((E20+F20)-D20)-J20 -> 0.58 | M20: =L20/D20 -> 0.0063862585 | N20: =L20*G20 -> 60.8072 | O20: 組合端 | P20: 抓樣不穩 | Q20: 人員抓樣手感不穩 | R20: 共用類
A21: 10 | B21: 油亮後腿肉絲 | C21: 37.7 | D21: 41.41 | E21: 41.41 | F21: 1.09 | G21: 342.75 | H21: =(E21+F21)/D21 -> 1.0263221 | I21: 373.6 | J21: 0.11 | K21: =J21/D21 -> 0.0026563632 | L21: =((E21+F21)-D21)-J21 -> 0.98 | M21: =L21/D21 -> 0.023665781 | N21: =L21*G21 -> 335.895 | O21: 組合端 | P21: 抓樣不穩 | Q21: 秤重物料，秤重精準度須持續校正 | R21: 二配香拌海鮮醬肉絲蛋炒飯
A23: 超用金額前十名半成品
A24: 明細展開 | D24: 生產資訊 | O24: 類別 | P24: 分析原因 (請填寫8大原因) | Q24: 其他原因說明 | R24: 備註-商品名稱
A25: 排序 | B25: 半成品 | D25: 生產端 | J25: 組合端
B26: 名稱 | C26: 超用金額 排序 | D26: 產出量 | J26: 報廢 | M26: 超用
D27: 訂單需求 (kg) | E27: 實際產出 (kg) | F27: 補單 (kg) | G27: 單價 (元) | H27: 實際生產 (對比訂單需求) | I27: 差異 (元) | J27: kg | K27: 占比 | L27: 金額 (元) | M27: kg | N27: 占比
A28: 1 | B28: 電解消毒牛蕃茄切片(中) | C28: 8939.51 | D28: 104.33 | E28: 136.4 | F28: 0 | G28: 278.75 | H28: =(E28+F28)/D28 -> 1.30739 | I28: 8939.51 | J28: 0 | K28: =J28/D28 -> 0 | L28: =J28*G28 -> 0 | M28: =((E28+F28)-D28)-J28 -> 32.07 | N28: =M28/D28 -> 0.30739001 | O28: 原物料 | P28: 原物料規格 | Q28: 物料規格過大(商品1顆開10片)，造成重量投入過多 | R28: 共用類
A29: 2 | B29: 電解消毒十字切美生菜 | C29: 1352.58 | D29: 298.32 | E29: 298.32 | F29: 8.86 | G29: 156.73 | H29: =(E29+F29)/D29 -> 1.0296997 | I29: 1388.63 | J29: 0.23 | K29: =J29/D29 -> 0.00077098418 | L29: =J29*G29 -> 36.0479 | M29: =((E29+F29)-D29)-J29 -> 8.63 | N29: =M29/D29 -> 0.028928667 | O29: 組合室 | P29: 取樣不穩 | Q29: 原物料特性，梗葉比例重量差異，抓樣不穩 | R29: 共用類
A30: 3 | B30: 炒壽喜燒牛培根 | C30: 1223.51 | D30: 91.64 | E30: 91.64 | F30: 3.02 | G30: 417.58 | H30: =(E30+F30)/D30 -> 1.032955 | I30: 1261.09 | J30: 0.09 | K30: =J30/D30 -> 0.00098210388 | L30: =J30*G30 -> 37.5822 | M30: =((E30+F30)-D30)-J30 -> 2.93 | N30: =M30/D30 -> 0.031972938 | O30: 組合室 | P30: 取樣不穩 | Q30: 秤重物料，秤重精準度須持續校正 | R30: 白味噌壽喜燒飯
