Workbook

Sheet 日別報廢率總表 
A1: 新豐廠半成品管理日別總表 | M1: 分析原因 (細項說明參照當日分頁) | V1: 半成品品項數
A2: 日期 | B2: 營業額 | C2: 報廢額 | D2: 報廢率 KPI 0.25% | E2: 超用額 | F2: 超用率 | G2: 廢棄前10名 | I2: 超用前10名 | K2: 共用類廢棄
G3: 金額總計 | H3: 構成比 | I3: 金額總計 | J3: 構成比 | K3: 金額總計 | L3: 構成比 KPI 15%
A4: 45870 | B4: ='0801分析標準表 '!$C$3:$C$3 -> 4376902.4 | C4: ='0801分析標準表 '!$D$5 -> 10523.37 | D4: =C4/B4 -> 0.0024042963 | E4: ='0801分析標準表 '!$F$5 -> 37623.41 | F4: =E4/B4 -> 0.0085958988 | G4: ='0801分析標準表 '!$H$5 -> 4612 | H4: =G4/C4 -> 0.43826265 | I4: ='0801分析標準表 '!$J$5 -> 24597.24 | J4: =I4/E4 -> 0.65377487 | K4: ='0801分析標準表 '!$L$5 -> 3500.18 | L4: =K4/C4 -> 0.33261018 | M4: 1.5i調理多產 2.1i原物料特性，梗葉比例重量差異，抓樣不穩 3.1i原物料特性，調理後持續出水導致殘水率高 4.1i調理製程，狀態細碎 5.1i組裝量少，人員抓樣不穩 6.1i生產餘料，人員抓樣不穩 | V4: 187
A5: =A4+1 -> 45871 | B5: ='0802分析標準表 '!$C$3:$C$3 -> 4635761.7 | C5: ='0802分析標準表 '!$D$5 -> 11154.77 | D5: =C5/B5 -> 0.0024062432 | E5: ='0802分析標準表 '!$F$5 -> 39836.48 | F5: =E5/B5 -> 0.0085932975 | G5: ='0802分析標準表 '!$H$5 -> 5425.18 | H5: =G5/C5 -> 0.48635516 | I5: ='0802分析標準表 '!$J$5 -> 22087.9 | J5: =I5/E5 -> 0.55446415 | K5: ='0802分析標準表 '!$L$5 -> 3858.11 | L5: =K5/C5 -> 0.34587087 | M5: 1.2i人員抓樣手感不穩 2.2i組合補單退回 3.2i調理多產預留超用量 4.2i調理後持續出水導致殘水率高 5.1i原物料特性，梗葉比例重量差異大 6.1i組合抓樣使用時會有破損狀況發生 | V5: 187
A6: =A5+1 -> 45872 | B6: ='0803分析標準表 '!$C$3:$C$3 -> 5941913.1 | C6: ='0803分析標準表 '!$D$5 -> 14483.44 | D6: =C6/B6 -> 0.0024375045 | E6: ='0803分析標準表 '!$F$5 -> 50877.05 | F6: =E6/B6 -> 0.0085624022 | G6: ='0803分析標準表 '!$H$5 -> 7244.99 | H6: =G6/C6 -> 0.50022578 | I6: ='0803分析標準表 '!$J$5 -> 30134.4 | J6: =I6/E6 -> 0.59229849 | K6: ='0803分析標準表 '!$L$5 -> 5115.9 | L6: =K6/C6 -> 0.3532241 | M6: 1.4i調理多產預留超用量 2.2i人員抓樣手感不穩 3.2i組合補單退回 4.1i原果重量大小差異 5.1i調理後持續出水導致殘水率高 | V6: 187
A7: =A6+1 -> 45873 | B7: ='0804分析標準表 '!$C$3:$C$3 -> 5873416.1 | C7: ='0804分析標準表 '!$D$5 -> 14310.17 | D7: =C7/B7 -> 0.0024364305 | E7: ='0804分析標準表 '!$F$5 -> 50296.24 | F7: =E7/B7 -> 0.0085633708 | G7: ='0804分析標準表 '!$H$5 -> 6706.8 | H7: =G7/C7 -> 0.46867368 | I7: ='0804分析標準表 '!$J$5 -> 21071.86 | J7: =I7/E7 -> 0.41895498 | K7: ='0804分析標準表 '!$L$5 -> 6101.4 | L7: =K7/C7 -> 0.4263681 | M7: 1.2i原物料特性，梗葉比例重量差異大 2.2i組合補單退回 3.2i調理後持續出水導致殘水率高 4.2i調理多產預留超用量 5.1i原果重量大小差異 6.1i人員抓樣手感不穩 | V7: 187
A8: =A7+1 -> 45874 | B8: ='0805分析標準表 '!$C$3:$C$3 -> 6182700.2 | C8: ='0805分析標準表 '!$D$5 -> 15148.47 | D8: =C8/B8 -> 0.0024501382 | E8: ='0805分析標準表 '!$F$5 -> 52860.81 | F8: =E8/B8 -> 0.0085497936 | G8: ='0805分析標準表 '!$H$5 -> 6868.12 | H8: =G8/C8 -> 0.45338704 | I8: ='0805分析標準表 '!$J$5 -> 32989.23 | J8: =I8/E8 -> 0.62407727 | K8: ='0805分析標準表 '!$L$5 -> 7031.67 | L8: =K8/C8 -> 0.46418351 | M8: 1.3i調理多產預留超用量 2.3i組合補單退回 3.2i人員抓樣手感不穩 4.1i原物料特性，梗葉比例重量差異大 5.1i調理後持續出水導致殘水率高 | V8: 188
A9: =A8+1 -> 45875 | B9: ='0806分析標準表 '!$C$3:$C$3 -> 6008483.6 | C9: ='0806分析標準表 '!$D$5 -> 14657.26 | D9: =C9/B9 -> 0.0024394275 | E9: ='0806分析標準表 '!$F$5 -> 51434.52 | F9: =E9/B9 -> 0.0085603163 | G9: ='0806分析標準表 '!$H$5 -> 5758.71 | H9: =G9/C9 -> 0.3928913 | I9: ='0806分析標準表 '!$J$5 -> 34249.94 | J9: =I9/E9 -> 0.66589403 | K9: ='0806分析標準表 '!$L$5 -> 6660.99 | L9: =K9/C9 -> 0.45444988 | M9: 1.4i人員抓樣手感不穩 2.2i調理多產預留超用量 3.2i調理後持續出水導致殘水率高 4.1i組合補單退回 5.1i原物料特性，梗葉比例重量差異大 6.0i | V9: 187
A10: =A9+1 -> 45876 | B10: ='0807分析標準表 '!$C$3:$C$3 -> 5578775.7 | C10: ='0807分析標準表 '!$D$5 -> 13552.55 | D10: =C10/B10 -> 0.0024293054 | E10: ='0807分析標準表 '!$F$5 -> 47813.48 | F10: =E10/B10 -> 0.0085706045 | G10: ='0807分析標準表 '!$H$5 -> 6153.94 | H10: =G10/C10 -> 0.45407986 | I10: ='0807分析標準表 '!$J$5 -> 23508.46 | J10: =I10/E10 -> 0.49167013 | K10: ='0807分析標準表 '!$L$5 -> 5911.59 | L10: =K10/C10 -> 0.43619762 | M10: 1.3i人員抓樣手感不穩 2.2i原物料製程未過篩，調理製程後較細碎 3.2i調理多產預留超用量 4.1i原物料特性，梗葉比例重量差異大 5.1i原物料特性，調理製程後較細碎 6.1i原果重量大小差異 | V10: 187
A11: =A10+1 -> 45877 | B11: ='0808分析標準表 '!$C$3:$C$3 -> 4540704.5 | C11: ='0808分析標準表 '!$D$5 -> 10914.96 | D11: =C11/B11 -> 0.0024038032 | E11: ='0808分析標準表 '!$F$5 -> 39033.47 | F11: =E11/B11 -> 0.0085963468 | G11: ='0808分析標準表 '!$H$5 -> 5153.95 | H11: =G11/C11 -> 0.47219138 | I11: ='0808分析標準表 '!$J$5 -> 22698.01 | J11: =I11/E11 -> 0.58150121 | K11: ='0808分析標準表 '!$L$5 -> 6163.69 | L11: =K11/C11 -> 0.56470111 | M11: 1.6i人員抓樣手感不穩 2.1i原物料特性，梗葉比例重量差異大 3.1i調理後持續出水導致殘水率高 4.1i調理多產預留超用量 5.1i原物料特性，調理製程後較細碎 | V11: 187
A12: =A11+1 -> 45878 | B12: ='0809分析標準表 '!$C$3:$C$3 -> 4698363 | C12: ='0809分析標準表 '!$D$5 -> 11309.07 | D12: =C12/B12 -> 0.0024070235 | E12: ='0809分析標準表 '!$F$5 -> 40372.56 | F12: =E12/B12 -> 0.0085928994 | G12: ='0809分析標準表 '!$H$5 -> 5527.1 | H12: =G12/C12 -> 0.48873161 | I12: ='0809分析標準表 '!$J$5 -> 25619.47 | J12: =I12/E12 -> 0.63457631 | K12: ='0809分析標準表 '!$L$5 -> 2388.04 | L12: =K12/C12 -> 0.21116148 | M12: 1.3i人員抓樣手感不穩 2.2i組合補單退回 3.2i原物料製程未過篩，調理製程後較細碎 4.2i調理多產預留超用量 5.1i原物料特性，調理製程後較細碎 | V12: 187
A13: =A12+1 -> 45879 | B13: ='0810分析標準表 '!$C$3:$C$3 -> 6020434.1 | C13: ='0810分析標準表 '!$D$5 -> 14686.58 | D13: =C13/B13 -> 0.0024394553 | E13: ='0810分析標準表 '!$F$5 -> 51535.8 | F13: =E13/B13 -> 0.0085601469 | G13: ='0810分析標準表 '!$H$5 -> 5452.34 | H13: =G13/C13 -> 0.3712464 | I13: ='0810分析標準表 '!$J$5 -> 30066.08 | J13: =I13/E13 -> 0.58340183 | K13: ='0810分析標準表 '!$L$5 -> 6411.28 | L13: =K13/C13 -> 0.43654002 | M13: 1.4i調理多產預留超用量 2.2i原物料特性，梗葉比例重量差異大 3.2i人員抓樣手感不穩 4.1i調理後持續出水導致殘水率高 5.1i原物料特性，調理製程後較細碎 | V13: 186
A14: =A13+1 -> 45880 | B14: ='0811分析標準表 '!$C$3:$C$3 -> 5944516 | C14: ='0811分析標準表 '!$D$5 -> 14564.22 | D14: =C14/B14 -> 0.0024500262 | E14: ='0811分析標準表 '!$F$5 -> 50823.56 | F14: =E14/B14 -> 0.0085496548 | G14: ='0811分析標準表 '!$H$5 -> 5918.32 | H14: =G14/C14 -> 0.40636024 | I14: ='0811分析標準表 '!$J$5 -> 32770.51 | J14: =I14/E14 -> 0.64478974 | K14: ='0811分析標準表 '!$L$5 -> 5762.81 | L14: =K14/C14 -> 0.39568271 | M14: 1.2i調理多產預留超用量 2.2i原物料特性，梗葉比例重量差異大 3.2i人員抓樣手感不穩 4.2i原物料製程未過篩，調理製程後較細碎 5.1i調理後持續出水導致殘水率高 6.1i原物料特性，調理製程後較細碎 | V14: 187
A15: =A14+1 -> 45881 | B15: ='0812分析標準表 '!$C$3:$C$3 -> 5571060 | C15: ='0812分析標準表 '!$D$5 -> 13534.12 | D15: =C15/B15 -> 0.0024293618 | E15: ='0812分析標準表 '!$F$5 -> 47748.03 | F15: =E15/B15 -> 0.0085707263 | G15: ='0812分析標準表 '!$H$5 -> 6650.97 | H15: =G15/C15 -> 0.49142242 | I15: ='0812分析標準表 '!$J$5 -> 26859.18 | J15: =I15/E15 -> 0.56251912 | K15: ='0812分析標準表 '!$L$5 -> 4519.45 | L15: =K15/C15 -> 0.3339301 | M15: 1.4i調理多產預留超用量 2.3i人員抓樣手感不穩 3.2i原物料製程未過篩，調理製程後較細碎 4.1i組合補單退回 | V15: 186
A16: =A15+1 -> 45882 | B16: ='0813分析標準表 '!$C$3:$C$3 -> 5601894.3 | C16: ='0813分析標準表 '!$D$5 -> 13442.58 | D16: =C16/B16 -> 0.002399649 | E16: ='0813分析標準表 '!$F$5 -> 48178.07 | F16: =E16/B16 -> 0.0086003176 | G16: ='0813分析標準表 '!$H$5 -> 5323.97 | H16: =G16/C16 -> 0.39605269 | I16: ='0813分析標準表 '!$J$5 -> 26653.8 | J16: =I16/E16 -> 0.55323511 | K16: ='0813分析標準表 '!$L$5 -> 4897.14 | L16: =K16/C16 -> 0.3643006 | M16: 1.5i人員抓樣手感不穩 2.2i組合補單退回 3.1i原物料特性，梗葉比例重量差異大 4.1i原物料製程未過篩，調理製程後較細碎 5.1i調理後持續出水導致殘水率高 | V16: 181
A17: =A16+1 -> 45883 | B17: ='0814分析標準表 '!$C$3:$C$3 -> 5220507.7 | C17: ='0814分析標準表 '!$D$5 -> 12531.16 | D17: =C17/B17 -> 0.0024003719 | E17: ='0814分析標準表 '!$F$5 -> 44895.03 | F17: =E17/B17 -> 0.0085997441 | G17: ='0814分析標準表 '!$H$5 -> 5238.95 | H17: =G17/C17 -> 0.41807383 | I17: ='0814分析標準表 '!$J$5 -> 26429.35 | J17: =I17/E17 -> 0.58869211 | K17: ='0814分析標準表 '!$L$5 -> 4639.55 | L17: =K17/C17 -> 0.37024106 | M17: 1.6i抓樣不穩 2.3i展開量105% 3.1i原物料規格 | V17: 181
A18: =A17+1 -> 45884 | B18: ='0815分析標準表 '!$C$3:$C$3 -> 4456648 | C18: ='0815分析標準表 '!$D$5 -> 10695.08 | D18: =C18/B18 -> 0.0023998036 | E18: ='0815分析標準表 '!$F$5 -> 38326.7 | F18: =E18/B18 -> 0.0085998938 | G18: ='0815分析標準表 '!$H$5 -> 4755.1 | H18: =G18/C18 -> 0.4446063 | I18: ='0815分析標準表 '!$J$5 -> 23717.95 | J18: =I18/E18 -> 0.61883622 | K18: ='0815分析標準表 '!$L$5 -> 5570.39 | L18: =K18/C18 -> 0.52083668 | M18: 1.6i抓樣不穩 2.3i展開量105% 3.1i原物料規格 | V18: 181
A19: =A18+1 -> 45885 | B19: ='0816分析標準表 '!$C$3:$C$3 -> 4483117.5 | C19: ='0816分析標準表 '!$D$5 -> 10769.01 | D19: =C19/B19 -> 0.0024021253 | E19: ='0816分析標準表 '!$F$5 -> 38544.86 | F19: =E19/B19 -> 0.0085977805 | G19: ='0816分析標準表 '!$H$5 -> 5301.32 | H19: =G19/C19 -> 0.49227552 | I19: ='0816分析標準表 '!$J$5 -> 26226.56 | J19: =I19/E19 -> 0.68041653 | K19: ='0816分析標準表 '!$L$5 -> 2679.56 | L19: =K19/C19 -> 0.24882139 | M19: 1.6i抓樣不穩 2.2i展開量105% 3.1i其他原因 4.1i原物料規格 | V19: 175
A20: =A19+1 -> 45886 | B20: ='0817分析標準表 '!$C$3:$C$3 -> 5735188.3 | C20: ='0817分析標準表 '!$D$5 -> 13950.53 | D20: =C20/B20 -> 0.002432445 | E20: ='0817分析標準表 '!$F$5 -> 49138.1 | F20: =E20/B20 -> 0.0085678268 | G20: ='0817分析標準表 '!$H$5 -> 5915.6 | H20: =G20/C20 -> 0.42404124 | I20: ='0817分析標準表 '!$J$5 -> 37558.52 | J20: =I20/E20 -> 0.7643462 | K20: ='0817分析標準表 '!$L$5 -> 5576.01 | L20: =K20/C20 -> 0.39969879 | M20: 1.5i抓樣不穩 2.3i展開量105% 3.2i原物料規格 | V20: 169
A21: =A20+1 -> 45887 | B21: ='0818分析標準表 '!$C$3:$C$3 -> 5701317.8 | C21: ='0818分析標準表 '!$D$5 -> 13867.02 | D21: =C21/B21 -> 0.0024322482 | E21: ='0818分析標準表 '!$F$5 -> 48846.1 | F21: =E21/B21 -> 0.0085675104 | G21: ='0818分析標準表 '!$H$5 -> 4742.45 | H21: =G21/C21 -> 0.34199489 | I21: ='0818分析標準表 '!$J$5 -> 32506.15 | J21: =I21/E21 -> 0.66548097 | K21: ='0818分析標準表 '!$L$5 -> 2450.88 | L21: =K21/C21 -> 0.17674165 | M21: 1.6i抓樣不穩 2.3i原物料規格 3.1i展開量105% | V21: 169
A22: =A21+1 -> 45888 | B22: ='0819分析標準表 '!$C$3:$C$3 -> 6939236.5 | C22: ='0819分析標準表 '!$D$5 -> 17003.49 | D22: =C22/B22 -> 0.0024503402 | E22: ='0819分析標準表 '!$F$5 -> 59330.15 | F22: =E22/B22 -> 0.0085499535 | G22: ='0819分析標準表 '!$H$5 -> 7155.3 | H22: =G22/C22 -> 0.42081361 | I22: ='0819分析標準表 '!$J$5 -> 16978.46 | J22: =I22/E22 -> 0.28616917 | K22: ='0819分析標準表 '!$L$5 -> 8190.55 | L22: =K22/C22 -> 0.48169817 | M22: 1.4i抓樣不穩 2.2i其他原因 3.2i原物料規格 4.2i展開量105% | V22: 174
A23: =A22+1 -> 45889 | B23: ='0820分析標準表 '!$C$3:$C$3 -> 6333786.4 | C23: ='0820分析標準表 '!$D$5 -> 15433.27 | D23: =C23/B23 -> 0.0024366578 | E23: ='0820分析標準表 '!$F$5 -> 54238.01 | F23: =E23/B23 -> 0.0085632838 | G23: ='0820分析標準表 '!$H$5 -> 4575.1135 | H23: =G23/C23 -> 0.29644486 | I23: ='0820分析標準表 '!$J$5 -> 14483.215 | J23: =I23/E23 -> 0.26703071 | K23: ='0820分析標準表 '!$L$5 -> 7981.86 | L23: =K23/C23 -> 0.51718528 | M23: 1.8i抓樣不穩 2.1i原物料規格 3.1i其他原因 | V23: 174
A24: =A23+1 -> 45890 | B24: ='0821分析標準表 '!$C$3:$C$3 -> 5963895.7 | C24: ='0821分析標準表 '!$D$5 -> 14483.7 | D24: =C24/B24 -> 0.0024285636 | E24: ='0821分析標準表 '!$F$5 -> 51116.98 | F24: =E24/B24 -> 0.0085710722 | G24: ='0821分析標準表 '!$H$5 -> 4221.63 | H24: =G24/C24 -> 0.29147455 | I24: ='0821分析標準表 '!$J$5 -> 11496.08 | J24: =I24/E24 -> 0.22489748 | K24: ='0821分析標準表 '!$L$5 -> 6589.54 | L24: =K24/C24 -> 0.45496248 | M24: 1.7i抓樣不穩 2.2i原物料規格 3.1i其他原因 | V24: 174
A25: =A24+1 -> 45891 | B25: ='0822分析標準表 '!$C$3:$C$3 -> 4909451 | C25: ='0822分析標準表 '!$D$5 -> 11842.7 | D25: =C25/B25 -> 0.0024122249 | E25: ='0822分析標準表 '!$F$5 -> 42159.59 | F25: =E25/B25 -> 0.0085874348 | G25: ='0822分析標準表 '!$H$5 -> 3010.82 | H25: =G25/C25 -> 0.25423425 | I25: ='0822分析標準表 '!$J$5 -> 9001.06 | J25: =I25/E25 -> 0.2134997 | K25: ='0822分析標準表 '!$L$5 -> 6480.14 | L25: =K25/C25 -> 0.54718434 | M25: 1.5i抓樣不穩 2.4i原物料規格 3.1i其他原因 | V25: 174
A26: =A25+1 -> 45892 | B26: ='0823分析標準表 '!$C$3:$C$3 -> 5147138.7 | C26: ='0823分析標準表 '!$D$5 -> 12468.09 | D26: =C26/B26 -> 0.0024223342 | E26: ='0823分析標準表 '!$F$5 -> 44152.76 | F26: =E26/B26 -> 0.0085781175 | G26: ='0823分析標準表 '!$H$5 -> 3597.55 | H26: =G26/C26 -> 0.28854059 | I26: ='0823分析標準表 '!$J$5 -> 9252.35 | J26: =I26/E26 -> 0.20955315 | K26: ='0823分析標準表 '!$L$5 -> 6270.17 | L26: =K26/C26 -> 0.5028974 | M26: 1.6i抓樣不穩 2.2i其他原因 3.2i原物料規格 | V26: 174
A27: =A26+1 -> 45893 | B27: ='0824分析標準表 '!$C$3:$C$3 -> 6385967.1 | C27: ='0824分析標準表 '!$D$5 -> 15627.19 | D27: =C27/B27 -> 0.0024471141 | E27: ='0824分析標準表 '!$F$5 -> 54615.92 | F27: =E27/B27 -> 0.00855249 | G27: ='0824分析標準表 '!$H$5 -> 4182.57 | H27: =G27/C27 -> 0.26764697 | I27: ='0824分析標準表 '!$J$5 -> 11190.04 | J27: =I27/E27 -> 0.20488605 | K27: ='0824分析標準表 '!$L$5 -> 8286.44 | L27: =K27/C27 -> 0.53025784 | M27: 1.9i抓樣不穩 2.1i其他原因 | V27: 174
A28: =A27+1 -> 45894 | B28: ='0825分析標準表 '!$C$3:$C$3 -> 6110563.6 | C28: ='0825分析標準表 '!$D$5 -> 14920.72 | D28: =C28/B28 -> 0.0024417911 | E28: ='0825分析標準表 '!$F$5 -> 48957.46 | F28: =E28/B28 -> 0.0080119385 | G28: ='0825分析標準表 '!$H$5 -> 4555.26 | H28: =G28/C28 -> 0.3052976 | I28: ='0825分析標準表 '!$J$5 -> 9093.95 | J28: =I28/E28 -> 0.18575208 | K28: ='0825分析標準表 '!$L$5 -> 7181.79 | L28: =K28/C28 -> 0.48132999 | M28: 1.8i抓樣不穩 2.1i其他原因 3.1i原物料規格 | V28: 170
A29: =A28+1 -> 45895 | B29: ='0826分析標準表 '!$C$3:$C$3 -> 5751890.8 | C29: ='0826分析標準表 '!$D$5 -> 13980.76 | D29: =C29/B29 -> 0.0024306372 | E29: ='0826分析標準表 '!$F$5 -> 44448.19 | F29: =E29/B29 -> 0.0077275789 | G29: ='0826分析標準表 '!$H$5 -> 4161.68 | H29: =G29/C29 -> 0.29767194 | I29: ='0826分析標準表 '!$J$5 -> 10846.39 | J29: =I29/E29 -> 0.24402321 | K29: ='0826分析標準表 '!$L$5 -> 8407.66 | L29: =K29/C29 -> 0.6013736 | M29: 1.6i抓樣不穩 2.3i原物料規格 3.1i其他原因 | V29: 167
A30: =A29+1 -> 45896 | B30: ='0827分析標準表 '!$C$3:$C$3 -> 5656058.4 | C30: ='0827分析標準表 '!$D$5 -> 13725.69 | D30: =C30/B30 -> 0.0024267235 | E30: ='0827分析標準表 '!$F$5 -> 43410.63 | F30: =E30/B30 -> 0.0076750676 | G30: ='0827分析標準表 '!$H$5 -> 3800.4 | H30: =G30/C30 -> 0.27688226 | I30: ='0827分析標準表 '!$J$5 -> 12041.49 | J30: =I30/E30 -> 0.27738575 | K30: ='0827分析標準表 '!$L$5 -> 6230.94 | L30: =K30/C30 -> 0.45396188 | M30: 1.6i抓樣不穩 2.3i原物料規格 3.1i其他原因 | V30: 167
A31: =A30+1 -> 45897 | B31: ='0828分析標準表 '!$C$3:$C$3 -> 5359266.3 | C31: ='0828分析標準表 '!$D$5 -> 13027.68 | D31: =C31/B31 -> 0.0024308701 | E31: ='0828分析標準表 '!$F$5 -> 40204.63 | F31: =E31/B31 -> 0.0075018907 | G31: ='0828分析標準表 '!$H$5 -> 3495.16 | H31: =G31/C31 -> 0.26828722 | I31: ='0828分析標準表 '!$J$5 -> 12036.15 | J31: =I31/E31 -> 0.29937224 | K31: ='0828分析標準表 '!$L$5 -> 6563.25 | L31: =K31/C31 -> 0.50379269 | M31: 1.5i抓樣不穩 2.4i原物料規格 3.1i其他原因 | V31: 167
A32: =A31+1 -> 45898 | B32: ='0829分析標準表 '!$C$3:$C$3 -> 4553981.3 | C32: ='0829分析標準表 '!$D$5 -> 10947.77 | D32: =C32/B32 -> 0.0024039998 | E32: ='0829分析標準表 '!$F$5 -> 34339.96 | F32: =E32/B32 -> 0.0075406459 | G32: ='0829分析標準表 '!$H$5 -> 3230.2 | H32: =G32/C32 -> 0.29505552 | I32: ='0829分析標準表 '!$J$5 -> 9489.09 | J32: =I32/E32 -> 0.27632793 | K32: ='0829分析標準表 '!$L$5 -> 4961.59 | L32: =K32/C32 -> 0.45320554 | M32: 1.5i抓樣不穩 2.4i原物料規格 3.1i其他原因 | V32: 167
A33: =A32+1 -> 45899 | B33: ='0831分析標準表 '!$C$3:$C$3 -> 6112909.4 | C33: ='0831分析標準表 '!$D$5 -> 14926.06 | D33: =C33/B33 -> 0.0024417277 | E33: ='0831分析標準表 '!$F$5 -> 48350.19 | F33: =E33/B33 -> 0.0079095218 | G33: ='0831分析標準表 '!$H$5 -> 5167.93 | H33: =G33/C33 -> 0.34623538 | I33: ='0831分析標準表 '!$J$5 -> 17693.09 | J33: =I33/E33 -> 0.36593631 | K33: ='0831分析標準表 '!$L$5 -> 7137.45 | L33: =K33/C33 -> 0.47818714 | V33: 167
A34: =A33+1 -> 45900 | B34: ='0831分析標準表 '!$C$3:$C$3 -> 6112909.4 | C34: ='0831分析標準表 '!$D$5 -> 14926.06 | D34: =C34/B34 -> 0.0024417277 | E34: ='0831分析標準表 '!$F$5 -> 48350.19 | F34: =E34/B34 -> 0.0079095218 | G34: ='0831分析標準表 '!$H$5 -> 5167.93 | H34: =G34/C34 -> 0.34623538 | I34: ='0831分析標準表 '!$J$5 -> 17693.09 | J34: =I34/E34 -> 0.36593631 | K34: ='0831分析標準表 '!$L$5 -> 7137.45 | L34: =K34/C34 -> 0.47818714 | V34: 167
A35: ※淺黃色為工廠自填項目
A36: ※日期紅色為新品日

Sheet 0831分析標準表 
A1: 新豐廠半成品管理分析
A2: 日期 | C2: 營業額 | D2: 報廢展開 | F2: 超用展開 | H2: 報廢展開 | J2: 超用展開 | L2: 報廢展開
A3: 45900 | C3: 6112909.4 | D3: 總報廢 | F3: 總超用 | H3: 報廢-前10名 | J3: 超用-前10名 | L3: 共用類-總報廢
D4: 金額 | E4: 占比(營業額) | F4: 金額 | G4: 占比(營業額) | H4: 金額 | I4: 占比(總報廢) | J4: 金額 | K4: 占比(總超用) | L4: 金額 | M4: 占比(總報廢)
A5: 年度KPI目標0.25% | D5: 14926.06 | E5: =D5/C3 -> 0.0024417277 | F5: 48350.19 | G5: =F5/C3 -> 0.0079095218 | H5: =SUM(C12:C21) -> 5167.93 | I5: =H5/D5 -> 0.34623538 | J5: =SUM(C28:C37) -> 17693.09 | K5: =J5/F5 -> 0.36593631 | L5: 7137.45 | M5: =L5/D5 -> 0.47818714
A7: 報廢金額前十名半成品
A8: 明細展開 | D8: 生產資訊 | O8: 類別 | P8: 分析原因 (請填寫8大原因) | Q8: 其他原因說明 | R8: 備註-商品名稱
A9: 排序 | B9: 半成品 | D9: 生產端 | J9: 組合端
B10: 名稱 | C10: 報廢金額 排序 | D10: 產出量 | J10: 報廢 | L10: 超用
D11: 訂單需求 (kg) | E11: 實際產出 (kg) | F11: 補單 (kg) | G11: 單價 (元) | H11: 實際生產 (對比訂單需求) | I11: 差異 (元) | J11: kg | K11: 占比 | L11: kg | M11: 占比 | N11: 金額 (元)
A12: 1 | B12: 義美業務用馬芬堡 | C12: 1929.49 | D12: 14429 | E12: 14429 | F12: 332.67 | G12: 5.8 | H12: =(E12+F12)/D12 -> 1.0230557 | I12: 1929.49 | J12: 332.67 | K12: =J12/D12 -> 0.023055652 | L12: =((E12+F12)-D12)-J12 -> 0 | M12: =L12/D12 -> 0 | N12: =L12*G12 -> 0 | R12: 共用類
A13: 2 | B13: 墨西哥餅皮-原味(8英吋)新 | C13: 1039.64 | D13: 7319 | E13: 7319 | F13: 158 | G13: 6.58 | H13: =(E13+F13)/D13 -> 1.0215876 | I13: 1039.64 | J13: 158 | K13: =J13/D13 -> 0.021587649 | L13: =((E13+F13)-D13)-J13 -> 0 | M13: =L13/D13 -> 0 | N13: =L13*G13 -> 0 | R13: 共用類
A14: 3 | B14: 電解消毒切段美生菜2-3cm | C14: 537.62 | D14: 396.67 | E14: 396.67 | F14: 18.21 | G14: 156.74 | H14: =(E14+F14)/D14 -> 1.0459072 | I14: 2854.24 | J14: 3.43 | K14: =J14/D14 -> 0.0086469862 | L14: =((E14+F14)-D14)-J14 -> 14.78 | M14: =L14/D14 -> 0.037260191 | N14: =L14*G14 -> 2316.6172 | R14: 共用類
A15: 4 | B15: 義美4吋無芝麻漢堡 | C15: 358.53 | D15: 6331 | E15: 6331 | F15: 83.38 | G15: 4.3 | H15: =(E15+F15)/D15 -> 1.0131701 | I15: 358.53 | J15: 83.38 | K15: =J15/D15 -> 0.013170115 | L15: =((E15+F15)-D15)-J15 -> 1.1368684e-13 | M15: =L15/D15 -> 1.7957169e-17 | N15: =L15*G15 -> 4.888534e-13 | R15: 共用類
A16: 5 | B16: 墨西哥餅皮-蕃茄(8英吋)新 | C16: 338.94 | D16: 4265 | E16: 4265 | F16: 48.42 | G16: 7 | H16: =(E16+F16)/D16 -> 1.0113529 | I16: 338.94 | J16: 48.42 | K16: =J16/D16 -> 0.011352872 | L16: =((E16+F16)-D16)-J16 -> 7.1054274e-14 | M16: =L16/D16 -> 1.6659853e-17 | N16: =L16*G16 -> 4.9737992e-13 | R16: 共用類
A17: 6 | B17: 電解消毒雙色高麗菜絲(7:3) | C17: 306.28 | D17: 256.17 | E17: 256.17 | F17: 9.14 | G17: 99.12 | H17: =(E17+F17)/D17 -> 1.0356794 | I17: 905.96 | J17: 3.09 | K17: =J17/D17 -> 0.012062302 | L17: =((E17+F17)-D17)-J17 -> 6.05 | M17: =L17/D17 -> 0.023617129 | N17: =L17*G17 -> 599.676 | R17: 共用類
A18: 7 | B18: 電解消毒十字切美生菜 | C18: 304.06 | D18: 294.87 | E18: 294.87 | F18: 13.54 | G18: 156.73 | H18: =(E18+F18)/D18 -> 1.0459185 | I18: 2122.12 | J18: 1.94 | K18: =J18/D18 -> 0.0065791705 | L18: =((E18+F18)-D18)-J18 -> 11.6 | M18: =L18/D18 -> 0.03933937 | N18: =L18*G18 -> 1818.068 | R18: 共用類
A19: 8 | B19: 墨西哥餅皮-菠菜(8英吋)新 | C19: 136.36 | D19: 5223 | E19: 5223 | F19: 19.48 | G19: 7 | H19: =(E19+F19)/D19 -> 1.0037297 | I19: 136.36 | J19: 19.48 | K19: =J19/D19 -> 0.0037296573 | L19: =((E19+F19)-D19)-J19 -> -4.3698378e-13 | M19: =L19/D19 -> -8.3665285e-17 | N19: =L19*G19 -> -3.0588865e-12 | R19: 共用類
A20: 9 | B20: 烤鹹蛋黃碎 | C20: 109.73 | D20: 11 | E20: 11 | F20: 0.28 | G20: 1567.63 | H20: =(E20+F20)/D20 -> 1.0254545 | I20: 438.94 | J20: 0.07 | K20: =J20/D20 -> 0.0063636364 | L20: =((E20+F20)-D20)-J20 -> 0.21 | M20: =L20/D20 -> 0.019090909 | N20: =L20*G20 -> 329.2023 | R20: 二配美味蟹煲
A21: 10 | B21: (V)電解消毒細切紅蘿蔔絲 | C21: 107.28 | D21: 42.65 | E21: 42.65 | F21: 1.09 | G21: 100.26 | H21: =(E21+F21)/D21 -> 1.0255569 | I21: 109.28 | J21: 1.07 | K21: =J21/D21 -> 0.025087925 | L21: =((E21+F21)-D21)-J21 -> 0.02 | M21: =L21/D21 -> 0.00046893318 | N21: =L21*G21 -> 2.0052 | R21: 共用類
A23: 超用金額前十名半成品
A24: 明細展開 | D24: 生產資訊 | O24: 類別 | P24: 分析原因 (請填寫8大原因) | Q24: 其他原因說明 | R24: 備註-商品名稱
A25: 排序 | B25: 半成品 | D25: 生產端 | J25: 組合端
B26: 名稱 | C26: 超用金額 排序 | D26: 產出量 | J26: 報廢 | M26: 超用
D27: 訂單需求 (kg) | E27: 實際產出 (kg) | F27: 補單 (kg) | G27: 單價 (元) | H27: 實際生產 (對比訂單需求) | I27: 差異 (元) | J27: kg | K27: 占比 | L27: 金額 (元) | M27: kg | N27: 占比
A28: 1 | B28: 電解消毒切段美生菜2-3cm | C28: 2316.62 | D28: 396.67 | E28: 396.67 | F28: 18.21 | G28: 156.74 | H28: =(E28+F28)/D28 -> 1.0459072 | I28: 2854.24 | J28: 3.43 | K28: =J28/D28 -> 0.0086469862 | L28: =J28*G28 -> 537.6182 | M28: =((E28+F28)-D28)-J28 -> 14.78 | N28: =M28/D28 -> 0.037260191 | R28: 共用類
A29: 2 | B29: 鼎泰豐-煮麻婆豆腐(113年) | C29: 2115.3 | D29: 361.14 | E29: 361.14 | F29: 16.58 | G29: 133.88 | H29: =(E29+F29)/D29 -> 1.0459102 | I29: 2219.73 | J29: 0.78 | K29: =J29/D29 -> 0.0021598272 | L29: =J29*G29 -> 104.4264 | M29: =((E29+F29)-D29)-J29 -> 15.8 | N29: =M29/D29 -> 0.043750346 | R29: 二配川味麻婆燒豆腐燴飯
A30: 3 | B30: 蟹粉燴汁(114年) | C30: 1954.06 | D30: 586.72 | E30: 586.72 | F30: 26.93 | G30: 76.42 | H30: =(E30+F30)/D30 -> 1.0458992 | I30: 2057.99 | J30: 1.36 | K30: =J30/D30 -> 0.0023179711 | L30: =J30*G30 -> 103.9312 | M30: =((E30+F30)-D30)-J30 -> 25.57 | N30: =M30/D30 -> 0.043581265 | R30: 二配美味蟹煲
A31: 4 | B31: 果香甘口咖哩醬 | C31: 1818.8 | D31: 598.36 | E31: 598.36 | F31: 24.41 | G31: 78.77 | H31: =(E31+F31)/D31 -> 1.0407948 | I31: 1922.78 | J31: 1.32 | K31: =J31/D31 -> 0.0022060298 | L31: =J31*G31 -> 103.9764 | M31: =((E31+F31)-D31)-J31 -> 23.09 | N31: =M31/D31 -> 0.038588809 | R31: 二配金咖哩果香甘口咖哩飯
A32: 5 | B32: 電解消毒十字切美生菜 | C32: 1818.06 | D32: 294.87 | E32: 294.87 | F32: 13.54 | G32: 156.73 | H32: =(E32+F32)/D32 -> 1.0459185 | I32: 2122.12 | J32: 1.94 | K32: =J32/D32 -> 0.0065791705 | L32: =J32*G32 -> 304.0562 | M32: =((E32+F32)-D32)-J32 -> 11.6 | N32: =M32/D32 -> 0.03933937 | R32: 共用類
A33: 6 | B33: 海鮮醬炒飯 | C33: 1747.21 | D33: 471.92 | E33: 471.92 | F33: 21.66 | G33: 85.48 | H33: =(E33+F33)/D33 -> 1.0458976 | I33: 1851.5 | J33: 1.22 | K33: =J33/D33 -> 0.0025851839 | L33: =J33*G33 -> 104.2856 | M33: =((E33+F33)-D33)-J33 -> 20.44 | N33: =M33/D33 -> 0.043312426 | R33: 二配香拌海鮮醬肉絲蛋炒飯
A34: 7 | B34: 濃辛辣咖哩醬 | C34: 1602.71 | D34: 526.5 | E34: 526.5 | F34: 21.48 | G34: 79.46 | H34: =(E34+F34)/D34 -> 1.0407977 | I34: 1706.8 | J34: 1.31 | K34: =J34/D34 -> 0.0024881292 | L34: =J34*G34 -> 104.0926 | M34: =((E34+F34)-D34)-J34 -> 20.17 | N34: =M34/D34 -> 0.038309592 | R34: 二配金咖哩濃厚辛辣咖哩飯
A35: 8 | B35: 川燙醃嫩化淨零碳排牛肉片 | C35: 1595.75 | D35: 40.87 | E35: 40.87 | F35: 2.09 | G35: 814.16 | H35: =(E35+F35)/D35 -> 1.0511378 | I35: 1701.59 | J35: 0.13 | K35: =J35/D35 -> 0.0031808172 | L35: =J35*G35 -> 105.8408 | M35: =((E35+F35)-D35)-J35 -> 1.96 | N35: =M35/D35 -> 0.047956937 | R35: 二配港式香滑嫩蛋牛肉燴飯
A36: 9 | B36: 鮪魚沙拉(113.05) | C36: 1381.57 | D36: 214.62 | E36: 214.62 | F36: 7.66 | G36: 194.04 | H36: =(E36+F36)/D36 -> 1.035691 | I36: 1486.35 | J36: 0.54 | K36: =J36/D36 -> 0.0025160749 | L36: =J36*G36 -> 104.7816 | M36: =((E36+F36)-D36)-J36 -> 7.12 | N36: =M36/D36 -> 0.033174914 | R36: 鮪魚起司溏心蛋三明治
A37: 10 | B37: 114年自製芋頭餡 | C37: 1343.01 | D37: 189.32 | E37: 189.32 | F37: 8.69 | G37: 166.42 | H37: =(E37+F37)/D37 -> 1.0459011 | I37: 1446.19 | J37: 0.62 | K37: =J37/D37 -> 0.0032748785 | L37: =J37*G37 -> 103.1804 | M37: =((E37+F37)-D37)-J37 -> 8.07 | N37: =M37/D37 -> 0.042626241 | R37: 起司芋見肉鬆三明治
A39: 共用類報廢金額前十名半成品
A40: 明細展開
A41: 排序 | B41: 半成品
B42: 名稱 | C42: 報廢金額 排序 | D42: 共用類總金額 占比
A44: 1 | B44: 義美業務用馬芬堡 | C44: 1929.49 | D44: =C44/$L$5 -> 0.27033324
...

Sheet 0830分析標準表 
A1: 新豐廠半成品管理分析
A2: 日期 | C2: 營業額 | D2: 報廢展開 | F2: 超用展開 | H2: 報廢展開 | J2: 超用展開 | L2: 報廢展開
A3: 45899 | C3: 4840642 | D3: 總報廢 | F3: 總超用 | H3: 報廢-前10名 | J3: 超用-前10名 | L3: 共用類-總報廢
D4: 金額 | E4: 占比(營業額) | F4: 金額 | G4: 占比(營業額) | H4: 金額 | I4: 占比(總報廢) | J4: 金額 | K4: 占比(總超用) | L4: 金額 | M4: 占比(總報廢)
A5: 年度KPI目標0.25% | D5: 11814.09 | E5: =D5/C3 -> 0.0024406039 | F5: 36952.24 | G5: =F5/C3 -> 0.0076337477 | H5: =SUM(C12:C21) -> 4021.58 | I5: =H5/D5 -> 0.3404054 | J5: =SUM(C28:C37) -> 15694.5 | K5: =J5/F5 -> 0.42472391 | L5: 4909.42 | M5: =L5/D5 -> 0.41555634
A7: 報廢金額前十名半成品
A8: 明細展開 | D8: 生產資訊 | O8: 類別 | P8: 分析原因 (請填寫8大原因) | Q8: 其他原因說明 | R8: 備註-商品名稱
A9: 排序 | B9: 半成品 | D9: 生產端 | J9: 組合端
B10: 名稱 | C10: 報廢金額 排序 | D10: 產出量 | J10: 報廢 | L10: 超用
D11: 訂單需求 (kg) | E11: 實際產出 (kg) | F11: 補單 (kg) | G11: 單價 (元) | H11: 實際生產 (對比訂單需求) | I11: 差異 (元) | J11: kg | K11: 占比 | L11: kg | M11: 占比 | N11: 金額 (元)
A12: 1 | B12: 義美業務用馬芬堡 | C12: 1226.99 | D12: 10847 | E12: 11058.55 | F12: 0 | G12: 5.8 | H12: =(E12+F12)/D12 -> 1.0195031 | I12: 1226.99 | J12: 211.55 | K12: =J12/D12 -> 0.019503088 | L12: =((E12+F12)-D12)-J12 -> -7.3896445e-13 | M12: =L12/D12 -> -6.8126159e-17 | N12: =L12*G12 -> -4.2859938e-12 | R12: 共用類
A13: 2 | B13: 鮪魚沙拉(113.05) | C13: 620.93 | D13: 141.75 | E13: 141.75 | F13: 6.35 | G13: 194.04 | H13: =(E13+F13)/D13 -> 1.0447972 | I13: 1232.15 | J13: 3.2 | K13: =J13/D13 -> 0.022574956 | L13: =((E13+F13)-D13)-J13 -> 3.15 | M13: =L13/D13 -> 0.022222222 | N13: =L13*G13 -> 611.226 | R13: 鮪魚起司溏心蛋三明治
A14: 3 | B14: 電解消毒切段美生菜2-3cm | C14: 568.97 | D14: 300.18 | E14: 300.18 | F14: 17.29 | G14: 156.74 | H14: =(E14+F14)/D14 -> 1.0575988 | I14: 2710.03 | J14: 3.63 | K14: =J14/D14 -> 0.012092744 | L14: =((E14+F14)-D14)-J14 -> 13.66 | M14: =L14/D14 -> 0.04550603 | N14: =L14*G14 -> 2141.0684 | R14: 共用類
A15: 4 | B15: 墨西哥餅皮-原味(8英吋)新 | C15: 516.27 | D15: 5342 | E15: 5342 | F15: 78.46 | G15: 6.58 | H15: =(E15+F15)/D15 -> 1.0146874 | I15: 516.27 | J15: 78.46 | K15: =J15/D15 -> 0.014687383 | L15: =((E15+F15)-D15)-J15 -> 0 | M15: =L15/D15 -> 0 | N15: =L15*G15 -> 0 | R15: 共用類
A16: 5 | B16: 拌總匯雞蛋沙拉CL(112年) | C16: 362.29 | D16: 197.61 | E16: 197.61 | F16: 7.59 | G16: 95.34 | H16: =(E16+F16)/D16 -> 1.038409 | I16: 723.63 | J16: 3.8 | K16: =J16/D16 -> 0.019229796 | L16: =((E16+F16)-D16)-J16 -> 3.79 | M16: =L16/D16 -> 0.019179191 | N16: =L16*G16 -> 361.3386 | R16: 共用類
A17: 6 | B17: 五吋芝麻漢堡 | C17: 198.34 | D17: 1744 | E17: 1744 | F17: 27.17 | G17: 7.3 | H17: =(E17+F17)/D17 -> 1.0155791 | I17: 198.34 | J17: 27.17 | K17: =J17/D17 -> 0.015579128 | L17: =((E17+F17)-D17)-J17 -> 7.1054274e-14 | M17: =L17/D17 -> 4.0742129e-17 | N17: =L17*G17 -> 5.186962e-13 | R17: 美式起司巨牛堡
A18: 7 | B18: 義美4吋芝麻漢堡 | C18: 176.22 | D18: 5075 | E18: 5075 | F18: 40.05 | G18: 4.4 | H18: =(E18+F18)/D18 -> 1.0078916 | I18: 176.22 | J18: 40.05 | K18: =J18/D18 -> 0.0078916256 | L18: =((E18+F18)-D18)-J18 -> 1.8474111e-13 | M18: =L18/D18 -> 3.6402189e-17 | N18: =L18*G18 -> 8.1286089e-13 | R18: 共用類
A19: 8 | B19: 電解消毒雙色高麗菜絲(7:3) | C19: 126.87 | D19: 186.98 | E19: 186.98 | F19: 8.38 | G19: 99.12 | H19: =(E19+F19)/D19 -> 1.0448176 | I19: 830.63 | J19: 1.28 | K19: =J19/D19 -> 0.0068456519 | L19: =((E19+F19)-D19)-J19 -> 7.1 | M19: =L19/D19 -> 0.037971976 | N19: =L19*G19 -> 703.752 | R19: 共用類
A20: 9 | B20: 墨西哥餅皮-菠菜(8英吋)新 | C20: 114.66 | D20: 4042 | E20: 4042 | F20: 16.38 | G20: 7 | H20: =(E20+F20)/D20 -> 1.0040524 | I20: 114.66 | J20: 16.38 | K20: =J20/D20 -> 0.0040524493 | L20: =((E20+F20)-D20)-J20 -> 1.1013412e-13 | M20: =L20/D20 -> 2.7247433e-17 | N20: =L20*G20 -> 7.7093887e-13 | R20: 共用類
A21: 10 | B21: 蒸海鮮醬(料) | C21: 110.04 | D21: 14.81 | E21: 14.81 | F21: 0.76 | G21: 846.44 | H21: =(E21+F21)/D21 -> 1.0513167 | I21: 643.29 | J21: 0.13 | K21: =J21/D21 -> 0.0087778528 | L21: =((E21+F21)-D21)-J21 -> 0.63 | M21: =L21/D21 -> 0.042538825 | N21: =L21*G21 -> 533.2572 | R21: 二配香拌海鮮醬肉絲蛋炒飯
A23: 超用金額前十名半成品
A24: 明細展開 | D24: 生產資訊 | O24: 類別 | P24: 分析原因 (請填寫8大原因) | Q24: 其他原因說明 | R24: 備註-商品名稱
A25: 排序 | B25: 半成品 | D25: 生產端 | J25: 組合端
B26: 名稱 | C26: 超用金額 排序 | D26: 產出量 | J26: 報廢 | M26: 超用
D27: 訂單需求 (kg) | E27: 實際產出 (kg) | F27: 補單 (kg) | G27: 單價 (元) | H27: 實際生產 (對比訂單需求) | I27: 差異 (元) | J27: kg | K27: 占比 | L27: 金額 (元) | M27: kg | N27: 占比
A28: 1 | B28: 鼎泰豐-煮麻婆豆腐(113年) | C28: 2503.56 | D28: 338.52 | E28: 338.52 | F28: 19.5 | G28: 133.88 | H28: =(E28+F28)/D28 -> 1.0576037 | I28: 2610.66 | J28: 0.8 | K28: =J28/D28 -> 0.0023632282 | L28: =J28*G28 -> 107.104 | M28: =((E28+F28)-D28)-J28 -> 18.7 | N28: =M28/D28 -> 0.055240458 | R28: 二配川味麻婆燒豆腐燴飯
A29: 2 | B29: 電解消毒切段美生菜2-3cm | C29: 2141.06 | D29: 300.18 | E29: 300.18 | F29: 17.29 | G29: 156.74 | H29: =(E29+F29)/D29 -> 1.0575988 | I29: 2710.03 | J29: 3.63 | K29: =J29/D29 -> 0.012092744 | L29: =J29*G29 -> 568.9662 | M29: =((E29+F29)-D29)-J29 -> 13.66 | N29: =M29/D29 -> 0.04550603 | R29: 共用類
A30: 3 | B30: 川燙醃嫩化淨零碳排牛肉片 | C30: 2084.25 | D30: 41.95 | E30: 41.95 | F30: 2.69 | G30: 814.16 | H30: =(E30+F30)/D30 -> 1.064124 | I30: 2190.09 | J30: 0.13 | K30: =J30/D30 -> 0.0030989273 | L30: =J30*G30 -> 105.8408 | M30: =((E30+F30)-D30)-J30 -> 2.56 | N30: =M30/D30 -> 0.06102503 | R30: 二配港式香滑嫩蛋牛肉燴飯
A31: 4 | B31: 電解消毒十字切美生菜 | C31: 1736.56 | D31: 204.07 | E31: 204.07 | F31: 11.76 | G31: 156.73 | H31: =(E31+F31)/D31 -> 1.0576273 | I31: 1843.14 | J31: 0.68 | K31: =J31/D31 -> 0.0033321899 | L31: =J31*G31 -> 106.5764 | M31: =((E31+F31)-D31)-J31 -> 11.08 | N31: =M31/D31 -> 0.054295095 | R31: 共用類
A32: 5 | B32: 溏心洋芋沙拉(113.06) | C32: 1371.1 | D32: 296.6 | E32: 296.6 | F32: 13.29 | G32: 111.2 | H32: =(E32+F32)/D32 -> 1.0448078 | I32: 1477.85 | J32: 0.96 | K32: =J32/D32 -> 0.0032366824 | L32: =J32*G32 -> 106.752 | M32: =((E32+F32)-D32)-J32 -> 12.33 | N32: =M32/D32 -> 0.04157114 | R32: 溏心蛋洋芋沙拉
A33: 6 | B33: 油亮蒜味香腸片 | C33: 1219.16 | D33: 81.33 | E33: 81.33 | F33: 4.17 | G33: 318.32 | H33: =(E33+F33)/D33 -> 1.0512726 | I33: 1327.39 | J33: 0.34 | K33: =J33/D33 -> 0.0041804992 | L33: =J33*G33 -> 108.2288 | M33: =((E33+F33)-D33)-J33 -> 3.83 | N33: =M33/D33 -> 0.047092094 | R33: 二配香辣醬蒜味香腸蛋炒飯
A34: 7 | B34: 114年自製芋頭餡 | C34: 1189.9 | D34: 135.2 | E34: 135.2 | F34: 7.79 | G34: 166.42 | H34: =(E34+F34)/D34 -> 1.0576183 | I34: 1296.41 | J34: 0.64 | K34: =J34/D34 -> 0.0047337278 | L34: =J34*G34 -> 106.5088 | M34: =((E34+F34)-D34)-J34 -> 7.15 | N34: =M34/D34 -> 0.052884615 | R34: 起司芋見肉鬆三明治
A35: 8 | B35: 蒸基礎風味雞肉絲 | C35: 1164.86 | D35: 80.84 | E35: 80.84 | F35: 3.1 | G35: 410.16 | H35: =(E35+F35)/D35 -> 1.0383474 | I35: 1271.5 | J35: 0.26 | K35: =J35/D35 -> 0.0032162296 | L35: =J35*G35 -> 106.6416 | M35: =((E35+F35)-D35)-J35 -> 2.84 | N35: =M35/D35 -> 0.035131123 | R35: 共用類
A36: 9 | B36: 拌芥末雞蛋沙拉(114.07) | C36: 1145.45 | D36: 188.94 | E36: 188.94 | F36: 8.47 | G36: 147.8 | H36: =(E36+F36)/D36 -> 1.044829 | I36: 1251.87 | J36: 0.72 | K36: =J36/D36 -> 0.0038107336 | L36: =J36*G36 -> 106.416 | M36: =((E36+F36)-D36)-J36 -> 7.75 | N36: =M36/D36 -> 0.041018313 | R36: 日式芥末蛋沙拉三明治
A37: 10 | B37: 辛口咖哩豬肉(112年) | C37: 1138.6 | D37: 72.93 | E37: 72.93 | F37: 3.73 | G37: 333.9 | H37: =(E37+F37)/D37 -> 1.0511449 | I37: 1245.45 | J37: 0.32 | K37: =J37/D37 -> 0.0043877691 | L37: =J37*G37 -> 106.848 | M37: =((E37+F37)-D37)-J37 -> 3.41 | N37: =M37/D37 -> 0.046757164 | R37: 二配金咖哩濃厚辛辣咖哩飯
A39: 共用類報廢金額前十名半成品
A40: 明細展開
A41: 排序 | B41: 半成品
B42: 名稱 | C42: 報廢金額 排序 | D42: 共用類總金額 占比
A44: 1 | B44: 義美業務用馬芬堡 | C44: 1226.99 | D44: =C44/$L$5 -> 0.24992565
...

Sheet 0829分析標準表 
A1: 新豐廠半成品管理分析
A2: 日期 | C2: 營業額 | D2: 報廢展開 | F2: 超用展開 | H2: 報廢展開 | J2: 超用展開 | L2: 報廢展開
A3: 45898 | C3: 4553981.3 | D3: 總報廢 | F3: 總超用 | H3: 報廢-前10名 | J3: 超用-前10名 | L3: 共用類-總報廢
D4: 金額 | E4: 占比(營業額) | F4: 金額 | G4: 占比(營業額) | H4: 金額 | I4: 占比(總報廢) | J4: 金額 | K4: 占比(總超用) | L4: 金額 | M4: 占比(總報廢)
A5: 年度KPI目標0.25% | D5: 10947.77 | E5: =D5/C3 -> 0.0024039998 | F5: 34339.96 | G5: =F5/C3 -> 0.0075406459 | H5: =SUM(C12:C21) -> 3230.2 | I5: =H5/D5 -> 0.29505552 | J5: =SUM(C28:C37) -> 9489.09 | K5: =J5/F5 -> 0.27632793 | L5: 4961.59 | M5: =L5/D5 -> 0.45320554
A7: 報廢金額前十名半成品
A8: 明細展開 | D8: 生產資訊 | O8: 類別 | P8: 分析原因 (請填寫8大原因) | Q8: 其他原因說明 | R8: 備註-商品名稱
A9: 排序 | B9: 半成品 | D9: 生產端 | J9: 組合端
B10: 名稱 | C10: 報廢金額 排序 | D10: 產出量 | J10: 報廢 | L10: 超用
D11: 訂單需求 (kg) | E11: 實際產出 (kg) | F11: 補單 (kg) | G11: 單價 (元) | H11: 實際生產 (對比訂單需求) | I11: 差異 (元) | J11: kg | K11: 占比 | L11: kg | M11: 占比 | N11: 金額 (元)
A12: 1 | B12: 鮪魚沙拉(113.05) | C12: 1300.07 | D12: 143.13 | E12: 143.13 | F12: 14.3 | G12: 194.04 | H12: =(E12+F12)/D12 -> 1.0999092 | I12: 2774.77 | J12: 6.7 | K12: =J12/D12 -> 0.046810592 | L12: =((E12+F12)-D12)-J12 -> 7.6 | M12: =L12/D12 -> 0.053098582 | N12: =L12*G12 -> 1474.704 | O12: 組合端 | P12: 抓樣不穩 | Q12: 人員冰杓定量手法不穩 | R12: 鮪魚起司溏心蛋三明治
A13: 2 | B13: 炒素鬆(新豐113.04) | C13: 325.88 | D13: 32.81 | E13: 32.81 | F13: 3.14 | G13: 271.57 | H13: =(E13+F13)/D13 -> 1.0957025 | I13: 852.73 | J13: 1.2 | K13: =J13/D13 -> 0.036574215 | L13: =((E13+F13)-D13)-J13 -> 1.94 | M13: =L13/D13 -> 0.059128315 | N13: =L13*G13 -> 526.8458 | O13: 組合端 | P13: 抓樣不穩 | Q13: 人員冰杓定量手法不穩 | R13: 共用類
A14: 3 | B14: 蒸紫米薏仁 | C14: 287.64 | D14: 99.23 | E14: 99.23 | F14: 9.87 | G14: 64.93 | H14: =(E14+F14)/D14 -> 1.0994659 | I14: 640.86 | J14: 4.43 | K14: =J14/D14 -> 0.044643757 | L14: =((E14+F14)-D14)-J14 -> 5.44 | M14: =L14/D14 -> 0.05482213 | N14: =L14*G14 -> 353.2192 | O14: 組合端 | P14: 抓樣不穩 | Q14: 人員抓樣手感不穩 | R14: 共用類
A15: 4 | B15: 義美業務用馬芬堡 | C15: 218.08 | D15: 10682 | E15: 10682 | F15: 75.31 | G15: 5.8 | H15: =(E15+F15)/D15 -> 1.0070502 | I15: 436.8 | J15: 37.6 | K15: =J15/D15 -> 0.0035199401 | L15: =((E15+F15)-D15)-J15 -> 37.71 | M15: =L15/D15 -> 0.0035302378 | N15: =L15*G15 -> 218.718 | O15: 原物料 | P15: 原物料規格 | Q15: 原物料特性，梗葉比例重量差異大 | R15: 共用類
A16: 5 | B16: 電解消毒混合紅K高麗絲 | C16: 205.49 | D16: 79.38 | E16: 79.38 | F16: 7.8 | G16: 104.84 | H16: =(E16+F16)/D16 -> 1.0982615 | I16: 817.75 | J16: 1.96 | K16: =J16/D16 -> 0.024691358 | L16: =((E16+F16)-D16)-J16 -> 5.84 | M16: =L16/D16 -> 0.073570169 | N16: =L16*G16 -> 612.2656 | O16: 原物料 | P16: 原物料規格 | Q16: 原物料製程未過篩，調理製程後較細碎 | R16: 共用類
A17: 6 | B17: 超HOT沙拉醬 | C17: 204.7 | D17: 37.98 | E17: 37.98 | F17: 3.76 | G17: 113.72 | H17: =(E17+F17)/D17 -> 1.0989995 | I17: 427.59 | J17: 1.8 | K17: =J17/D17 -> 0.047393365 | L17: =((E17+F17)-D17)-J17 -> 1.96 | M17: =L17/D17 -> 0.051606108 | N17: =L17*G17 -> 222.8912 | O17: 組合端 | P17: 抓樣不穩 | Q17: 人員抓樣手感不穩 | R17: 超HOT雞腿堡(114年)
A18: 7 | B18: 電解消毒切段甜脆 | C18: 197.01 | D18: 10.34 | E18: 10.34 | F18: 1.02 | G18: 469.08 | H18: =(E18+F18)/D18 -> 1.098646 | I18: 478.46 | J18: 0.42 | K18: =J18/D18 -> 0.040618956 | L18: =((E18+F18)-D18)-J18 -> 0.6 | M18: =L18/D18 -> 0.058027079 | N18: =L18*G18 -> 281.448 | O18: 原物料 | P18: 原物料規格 | Q18: 原物料特性，梗葉比例重量差異大 | R18: 蔥鹽雞肉麵沙拉(114年)
A19: 8 | B19: 拌水果莎莎醬1.2細麵 | C19: 168.44 | D19: 288.4 | E19: 288.4 | F19: 11.92 | G19: 61.25 | H19: =(E19+F19)/D19 -> 1.0413315 | I19: 730.1 | J19: 2.75 | K19: =J19/D19 -> 0.0095353675 | L19: =((E19+F19)-D19)-J19 -> 9.17 | M19: =L19/D19 -> 0.031796117 | N19: =L19*G19 -> 561.6625 | O19: 組合端 | P19: 其他原因 | Q19: 包材過於貼體 | R19: 莎莎烤雞麵沙拉
A20: 9 | B20: 龍蝦沙拉(114.08) | C20: 164.58 | D20: 85.88 | E20: 87.6 | F20: 3.94 | G20: 228.58 | H20: =(E20+F20)/D20 -> 1.0659059 | I20: 1293.76 | J20: 0.72 | K20: =J20/D20 -> 0.0083837913 | L20: =((E20+F20)-D20)-J20 -> 4.94 | M20: =L20/D20 -> 0.057522124 | N20: =L20*G20 -> 1129.1852 | O20: 原物料 | P20: 原物料規格 | Q20: 菜梗太硬導致捲的時候破損 | R20: 龍蝦風味總匯三明治
A21: 10 | B21: 電解消毒切段美生菜2-3cm | C21: 158.31 | D21: 292.49 | E21: 292.49 | F21: 4.61 | G21: 156.74 | H21: =(E21+F21)/D21 -> 1.0157612 | I21: 722.57 | J21: 1.01 | K21: =J21/D21 -> 0.0034531095 | L21: =((E21+F21)-D21)-J21 -> 3.6 | M21: =L21/D21 -> 0.012308113 | N21: =L21*G21 -> 564.264 | O21: 組合端 | P21: 抓樣不穩 | Q21: 人員抓樣手感不穩 | R21: 共用類
A23: 超用金額前十名半成品
A24: 明細展開 | D24: 生產資訊 | O24: 類別 | P24: 分析原因 (請填寫8大原因) | Q24: 其他原因說明 | R24: 備註-商品名稱
A25: 排序 | B25: 半成品 | D25: 生產端 | J25: 組合端
B26: 名稱 | C26: 超用金額 排序 | D26: 產出量 | J26: 報廢 | M26: 超用
D27: 訂單需求 (kg) | E27: 實際產出 (kg) | F27: 補單 (kg) | G27: 單價 (元) | H27: 實際生產 (對比訂單需求) | I27: 差異 (元) | J27: kg | K27: 占比 | L27: 金額 (元) | M27: kg | N27: 占比
A28: 1 | B28: 蒸基礎風味雞肉絲 | C28: 1792.4 | D28: 79.38 | E28: 82.1 | F28: 2.02 | G28: 410.16 | H28: =(E28+F28)/D28 -> 1.0597128 | I28: 1944.16 | J28: 0.37 | K28: =J28/D28 -> 0.0046611237 | L28: =J28*G28 -> 151.7592 | M28: =((E28+F28)-D28)-J28 -> 4.37 | N28: =M28/D28 -> 0.05505165 | O28: 組合室 | P28: 抓樣不穩 | Q28: 原物料特性，梗葉比例重量差異，抓樣不穩 | R28: 共用類
A29: 2 | B29: 鮪魚沙拉(113.05) | C29: 1474.7 | D29: 143.13 | E29: 143.13 | F29: 14.3 | G29: 194.04 | H29: =(E29+F29)/D29 -> 1.0999092 | I29: 2774.77 | J29: 6.7 | K29: =J29/D29 -> 0.046810592 | L29: =J29*G29 -> 1300.068 | M29: =((E29+F29)-D29)-J29 -> 7.6 | N29: =M29/D29 -> 0.053098582 | O29: 組合室 | P29: 抓樣不穩 | Q29: 原物料特性，梗葉比例重量差異，抓樣不穩 | R29: 鮪魚起司溏心蛋三明治
A30: 3 | B30: 龍蝦沙拉(114.08) | C30: 1129.18 | D30: 85.88 | E30: 87.6 | F30: 3.94 | G30: 228.58 | H30: =(E30+F30)/D30 -> 1.0659059 | I30: 1293.76 | J30: 0.72 | K30: =J30/D30 -> 0.0083837913 | L30: =J30*G30 -> 164.5776 | M30: =((E30+F30)-D30)-J30 -> 4.94 | N30: =M30/D30 -> 0.057522124 | O30: 組合室 | P30: 抓樣不穩 | Q30: 冰杓定量挖取(使用量上會較起伏)，持續上抽測確認人員使用準確度 | R30: 龍蝦風味總匯三明治
A31: 4 | B31: 蒸鼎泰豐香辣醬 | C31: 1037.35 | D31: 20.6 | E31: 20.98 | F31: 0.9 | G31: 930.36 | H31: =(E31+F31)/D31 -> 1.0621359 | I31: 1190.86 | J31: 0.165 | K31: =J31/D31 -> 0.0080097087 | L31: =J31*G31 -> 153.5094 | M31: =((E31+F31)-D31)-J31 -> 1.115 | N31: =M31/D31 -> 0.054126214 | O31: 組合室 | P31: 抓樣不穩 | Q31: 秤重物料，秤重精準度須持續校正 | R31: 二配香辣醬蒜味香腸蛋炒飯
A32: 5 | B32: F-台式特級沙拉醬 | C32: 703.56 | D32: 169.28 | E32: 169.28 | F32: 10.98 | G32: 78 | H32: =(E32+F32)/D32 -> 1.0648629 | I32: 856.44 | J32: 1.96 | K32: =J32/D32 -> 0.01157845 | L32: =J32*G32 -> 152.88 | M32: =((E32+F32)-D32)-J32 -> 9.02 | N32: =M32/D32 -> 0.053284499 | O32: 組合室 | P32: 抓樣不穩 | Q32: 刮板挖取使用，持續上抽測確認人員使用準確度 | R32: 共用類
A33: 6 | B33: 青檸沙拉醬(113.03) | C33: 682.86 | D33: 117.41 | E33: 117.41 | F33: 6.56 | G33: 127.4 | H33: =(E33+F33)/D33 -> 1.0558726 | I33: 835.74 | J33: 1.2 | K33: =J33/D33 -> 0.010220594 | L33: =J33*G33 -> 152.88 | M33: =((E33+F33)-D33)-J33 -> 5.36 | N33: =M33/D33 -> 0.045651989 | O33: 組合室 | P33: 抓樣不穩 | Q33: 秤重物料，過多無法剝除 | R33: 共用類
A34: 7 | B34: 拌總匯雞蛋沙拉CL(112年) | C34: 676.91 | D34: 199.66 | E34: 199.66 | F34: 8.74 | G34: 95.34 | H34: =(E34+F34)/D34 -> 1.0437744 | I34: 833.27 | J34: 1.64 | K34: =J34/D34 -> 0.0082139637 | L34: =J34*G34 -> 156.3576 | M34: =((E34+F34)-D34)-J34 -> 7.1 | N34: =M34/D34 -> 0.035560453 | O34: 組合室 | P34: 抓樣不穩 | Q34: 冰杓定量挖取(使用量上會較起伏)，持續上抽測確認人員使用準確度 | R34: 共用類
A35: 8 | B35: 水果莎莎醬(114.06) | C35: 664.57 | D35: 115.36 | E35: 115.36 | F35: 4.91 | G35: 166.56 | H35: =(E35+F35)/D35 -> 1.0425624 | I35: 817.81 | J35: 0.92 | K35: =J35/D35 -> 0.0079750347 | L35: =J35*G35 -> 153.2352 | M35: =((E35+F35)-D35)-J35 -> 3.99 | N35: =M35/D35 -> 0.034587379 | O35: 組合室 | P35: 抓樣不穩 | Q35: 秤重物料，過多無法剝除 | R35: 莎莎烤雞麵沙拉
A36: 9 | B36: 電解消毒十字切美生菜 | C36: 664.53 | D36: 195.34 | E36: 195.34 | F36: 5.22 | G36: 156.73 | H36: =(E36+F36)/D36 -> 1.0267226 | I36: 818.13 | J36: 0.98 | K36: =J36/D36 -> 0.0050168936 | L36: =J36*G36 -> 153.5954 | M36: =((E36+F36)-D36)-J36 -> 4.24 | N36: =M36/D36 -> 0.021705744 | O36: 組合室 | P36: 抓樣不穩 | Q36: 人員抓樣，絲狀較長抓樣重量差異 | R36: 共用類
A37: 10 | B37: 親子柴魚風味醬汁(114年) | C37: 663.03 | D37: 201.74 | E37: 201.74 | F37: 18.19 | G37: 44.86 | H37: =(E37+F37)/D37 -> 1.0901656 | I37: 816 | J37: 3.41 | K37: =J37/D37 -> 0.016902944 | L37: =J37*G37 -> 152.9726 | M37: =((E37+F37)-D37)-J37 -> 14.78 | N37: =M37/D37 -> 0.073262615 | O37: 組合室 | P37: 抓樣不穩 | Q37: 注餡機使用(機器出料就有落差)，人員持續於線上不定時抽測重量 | R37: 共用類
A39: 共用類報廢金額前十名半成品
A40: 明細展開
A41: 排序 | B41: 半成品
B42: 名稱 | C42: 報廢金額 排序 | D42: 共用類總金額 占比
A44: 1 | B44: 炒素鬆(新豐113.04) | C44: 325.88 | D44: =C44/$L$5 -> 0.065680558
...

Sheet 0828分析標準表 
A1: 新豐廠半成品管理分析
A2: 日期 | C2: 營業額 | D2: 報廢展開 | F2: 超用展開 | H2: 報廢展開 | J2: 超用展開 | L2: 報廢展開
A3: 45897 | C3: 5359266.3 | D3: 總報廢 | F3: 總超用 | H3: 報廢-前10名 | J3: 超用-前10名 | L3: 共用類-總報廢
D4: 金額 | E4: 占比(營業額) | F4: 金額 | G4: 占比(營業額) | H4: 金額 | I4: 占比(總報廢) | J4: 金額 | K4: 占比(總超用) | L4: 金額 | M4: 占比(總報廢)
A5: 年度KPI目標0.25% | D5: 13027.68 | E5: =D5/C3 -> 0.0024308701 | F5: 40204.63 | G5: =F5/C3 -> 0.0075018907 | H5: =SUM(C12:C21) -> 3495.16 | I5: =H5/D5 -> 0.26828722 | J5: =SUM(C28:C37) -> 12036.15 | K5: =J5/F5 -> 0.29937224 | L5: 6563.25 | M5: =L5/D5 -> 0.50379269
A7: 報廢金額前十名半成品
A8: 明細展開 | D8: 生產資訊 | O8: 類別 | P8: 分析原因 (請填寫8大原因) | Q8: 其他原因說明 | R8: 備註-商品名稱
A9: 排序 | B9: 半成品 | D9: 生產端 | J9: 組合端
B10: 名稱 | C10: 報廢金額 排序 | D10: 產出量 | J10: 報廢 | L10: 超用
D11: 訂單需求 (kg) | E11: 實際產出 (kg) | F11: 補單 (kg) | G11: 單價 (元) | H11: 實際生產 (對比訂單需求) | I11: 差異 (元) | J11: kg | K11: 占比 | L11: kg | M11: 占比 | N11: 金額 (元)
A12: 1 | B12: 拌總匯雞蛋沙拉CL(112年) | C12: 618.76 | D12: 250.39 | E12: 250.39 | F12: 24.98 | G12: 95.34 | H12: =(E12+F12)/D12 -> 1.0997644 | I12: 2381.59 | J12: 6.49 | K12: =J12/D12 -> 0.025919565 | L12: =((E12+F12)-D12)-J12 -> 18.49 | M12: =L12/D12 -> 0.073844802 | N12: =L12*G12 -> 1762.8366 | O12: 組合端 | P12: 抓樣不穩 | Q12: 人員冰杓定量手法不穩 | R12: 共用類
A13: 2 | B13: 拌總匯鮪魚沙拉CL(113年) | C13: 477.11 | D13: 73.78 | E13: 73.78 | F13: 7.32 | G13: 114.14 | H13: =(E13+F13)/D13 -> 1.0992139 | I13: 835.5 | J13: 4.18 | K13: =J13/D13 -> 0.05665492 | L13: =((E13+F13)-D13)-J13 -> 3.14 | M13: =L13/D13 -> 0.042558959 | N13: =L13*G13 -> 358.3996 | O13: 組合端 | P13: 抓樣不穩 | Q13: 人員冰杓定量手法不穩 | R13: 經典總匯三明治
A14: 3 | B14: 電解消毒紫洋蔥(去皮)切絲 | C14: 465.17 | D14: 32.45 | E14: 27.3 | F14: 8.37 | G14: 113.18 | H14: =(E14+F14)/D14 -> 1.0992296 | I14: 364.44 | J14: 4.11 | K14: =J14/D14 -> 0.12665639 | L14: =((E14+F14)-D14)-J14 -> -0.89 | M14: =L14/D14 -> -0.02742681 | N14: =L14*G14 -> -100.7302 | O14: 組合端 | P14: 抓樣不穩 | Q14: 人員抓樣手感不穩 | R14: 莎莎烤雞麵沙拉
A15: 4 | B15: 電解消毒十字切美生菜 | C15: 429.44 | D15: 280.21 | E15: 280.21 | F15: 19 | G15: 156.73 | H15: =(E15+F15)/D15 -> 1.0678063 | I15: 2977.87 | J15: 2.74 | K15: =J15/D15 -> 0.0097783805 | L15: =((E15+F15)-D15)-J15 -> 16.26 | M15: =L15/D15 -> 0.058027908 | N15: =L15*G15 -> 2548.4298 | O15: 原物料 | P15: 原物料規格 | Q15: 原物料特性，梗葉比例重量差異大 | R15: 共用類
A16: 5 | B16: 炒辛口馬鈴薯丁(112年) | C16: 297.29 | D16: 51.18 | E16: 51.18 | F16: 5.11 | G16: 124.39 | H16: =(E16+F16)/D16 -> 1.0998437 | I16: 635.63 | J16: 2.39 | K16: =J16/D16 -> 0.046697929 | L16: =((E16+F16)-D16)-J16 -> 2.72 | M16: =L16/D16 -> 0.05314576 | N16: =L16*G16 -> 338.3408 | O16: 原物料 | P16: 原物料規格 | Q16: 原物料製程未過篩，調理製程後較細碎 | R16: 二配金咖哩濃厚辛辣咖哩飯
A17: 6 | B17: 電解消毒雙色高麗菜絲(7:3) | C17: 286.46 | D17: 222.15 | E17: 222.15 | F17: 9.36 | G17: 99.12 | H17: =(E17+F17)/D17 -> 1.0421337 | I17: 927.76 | J17: 2.89 | K17: =J17/D17 -> 0.013009228 | L17: =((E17+F17)-D17)-J17 -> 6.47 | M17: =L17/D17 -> 0.029124465 | N17: =L17*G17 -> 641.3064 | O17: 組合端 | P17: 抓樣不穩 | Q17: 人員抓樣手感不穩 | R17: 共用類
A18: 7 | B18: 電解消毒切段美生菜2-3cm | C18: 235.11 | D18: 339.98 | E18: 339.98 | F18: 15.7 | G18: 156.74 | H18: =(E18+F18)/D18 -> 1.0461792 | I18: 2460.82 | J18: 1.5 | K18: =J18/D18 -> 0.0044120242 | L18: =((E18+F18)-D18)-J18 -> 14.2 | M18: =L18/D18 -> 0.041767163 | N18: =L18*G18 -> 2225.708 | O18: 原物料 | P18: 原物料規格 | Q18: 原物料特性，梗葉比例重量差異大 | R18: 共用類
A19: 8 | B19: 義美業務用馬芬堡 | C19: 233.74 | D19: 12964 | E19: 12964 | F19: 80.57 | G19: 5.8 | H19: =(E19+F19)/D19 -> 1.0062149 | I19: 467.31 | J19: 40.3 | K19: =J19/D19 -> 0.0031086085 | L19: =((E19+F19)-D19)-J19 -> 40.27 | M19: =L19/D19 -> 0.0031062944 | N19: =L19*G19 -> 233.566 | O19: 組合端 | P19: 其他原因 | Q19: 包材過於貼體 | R19: 共用類
A20: 9 | B20: 墨西哥餅皮-原味(8英吋)新 | C20: 231.16 | D20: 6347 | E20: 6347 | F20: 70.76 | G20: 6.58 | H20: =(E20+F20)/D20 -> 1.0111486 | I20: 465.6 | J20: 35.13 | K20: =J20/D20 -> 0.0055348984 | L20: =((E20+F20)-D20)-J20 -> 35.63 | M20: =L20/D20 -> 0.0056136758 | N20: =L20*G20 -> 234.4454 | O20: 原物料 | P20: 原物料規格 | Q20: 菜梗太硬導致捲的時候破損 | R20: 共用類
A21: 10 | B21: 電解消毒蔥花 | C21: 220.92 | D21: 21.74 | E21: 21.74 | F21: 2.17 | G21: 232.55 | H21: =(E21+F21)/D21 -> 1.099816 | I21: 504.63 | J21: 0.95 | K21: =J21/D21 -> 0.043698252 | L21: =((E21+F21)-D21)-J21 -> 1.22 | M21: =L21/D21 -> 0.056117755 | N21: =L21*G21 -> 283.711 | O21: 組合端 | P21: 抓樣不穩 | Q21: 人員抓樣手感不穩 | R21: 共用類
A23: 超用金額前十名半成品
A24: 明細展開 | D24: 生產資訊 | O24: 類別 | P24: 分析原因 (請填寫8大原因) | Q24: 其他原因說明 | R24: 備註-商品名稱
A25: 排序 | B25: 半成品 | D25: 生產端 | J25: 組合端
B26: 名稱 | C26: 超用金額 排序 | D26: 產出量 | J26: 報廢 | M26: 超用
D27: 訂單需求 (kg) | E27: 實際產出 (kg) | F27: 補單 (kg) | G27: 單價 (元) | H27: 實際生產 (對比訂單需求) | I27: 差異 (元) | J27: kg | K27: 占比 | L27: 金額 (元) | M27: kg | N27: 占比
A28: 1 | B28: 電解消毒十字切美生菜 | C28: 2548.43 | D28: 280.21 | E28: 280.21 | F28: 19 | G28: 156.73 | H28: =(E28+F28)/D28 -> 1.0678063 | I28: 2977.87 | J28: 2.74 | K28: =J28/D28 -> 0.0097783805 | L28: =J28*G28 -> 429.4402 | M28: =((E28+F28)-D28)-J28 -> 16.26 | N28: =M28/D28 -> 0.058027908 | O28: 組合室 | P28: 抓樣不穩 | Q28: 原物料特性，梗葉比例重量差異，抓樣不穩 | R28: 共用類
A29: 2 | B29: 電解消毒切段美生菜2-3cm | C29: 2225.71 | D29: 339.98 | E29: 339.98 | F29: 15.7 | G29: 156.74 | H29: =(E29+F29)/D29 -> 1.0461792 | I29: 2460.82 | J29: 1.5 | K29: =J29/D29 -> 0.0044120242 | L29: =J29*G29 -> 235.11 | M29: =((E29+F29)-D29)-J29 -> 14.2 | N29: =M29/D29 -> 0.041767163 | O29: 組合室 | P29: 抓樣不穩 | Q29: 原物料特性，梗葉比例重量差異，抓樣不穩 | R29: 共用類
A30: 3 | B30: 拌總匯雞蛋沙拉CL(112年) | C30: 1762.83 | D30: 250.39 | E30: 250.39 | F30: 24.98 | G30: 95.34 | H30: =(E30+F30)/D30 -> 1.0997644 | I30: 2381.59 | J30: 6.49 | K30: =J30/D30 -> 0.025919565 | L30: =J30*G30 -> 618.7566 | M30: =((E30+F30)-D30)-J30 -> 18.49 | N30: =M30/D30 -> 0.073844802 | O30: 組合室 | P30: 抓樣不穩 | Q30: 冰杓定量挖取(使用量上會較起伏)，持續上抽測確認人員使用準確度 | R30: 共用類
A31: 4 | B31: 雞排蛋炒飯 | C31: 805.99 | D31: 444.15 | E31: 444.15 | F31: 14.94 | G31: 59.22 | H31: =(E31+F31)/D31 -> 1.0336373 | I31: 884.75 | J31: 1.33 | K31: =J31/D31 -> 0.0029944838 | L31: =J31*G31 -> 78.7626 | M31: =((E31+F31)-D31)-J31 -> 13.61 | N31: =M31/D31 -> 0.030642801 | O31: 組合室 | P31: 抓樣不穩 | Q31: 秤重物料，秤重精準度須持續校正 | R31: 二配粗飽系雞排炒飯
A32: 5 | B32: F-台式特級沙拉醬 | C32: 794.04 | D32: 207.81 | E32: 207.81 | F32: 12.78 | G32: 78 | H32: =(E32+F32)/D32 -> 1.0614985 | I32: 996.84 | J32: 2.6 | K32: =J32/D32 -> 0.012511429 | L32: =J32*G32 -> 202.8 | M32: =((E32+F32)-D32)-J32 -> 10.18 | N32: =M32/D32 -> 0.048987055 | O32: 組合室 | P32: 抓樣不穩 | Q32: 刮板挖取使用，持續上抽測確認人員使用準確度 | R32: 共用類
A33: 6 | B33: 蒸基礎風味雞肉絲 | C33: 791.61 | D33: 93.24 | E33: 93.24 | F33: 2.36 | G33: 410.16 | H33: =(E33+F33)/D33 -> 1.025311 | I33: 967.98 | J33: 0.43 | K33: =J33/D33 -> 0.0046117546 | L33: =J33*G33 -> 176.3688 | M33: =((E33+F33)-D33)-J33 -> 1.93 | N33: =M33/D33 -> 0.020699271 | O33: 組合室 | P33: 抓樣不穩 | Q33: 秤重物料，過多無法剝除 | R33: 共用類
A34: 7 | B34: 蒸鼎泰豐香辣醬 | C34: 790.81 | D34: 20.89 | E34: 20.89 | F34: 1.08 | G34: 930.36 | H34: =(E34+F34)/D34 -> 1.0516994 | I34: 1004.79 | J34: 0.23 | K34: =J34/D34 -> 0.011010053 | L34: =J34*G34 -> 213.9828 | M34: =((E34+F34)-D34)-J34 -> 0.85 | N34: =M34/D34 -> 0.040689325 | O34: 組合室 | P34: 抓樣不穩 | Q34: 冰杓定量挖取(使用量上會較起伏)，持續上抽測確認人員使用準確度 | R34: 二配香辣醬蒜味香腸蛋炒飯
A35: 8 | B35: 油亮蒜味香腸片 | C35: 773.52 | D35: 70.26 | E35: 70.26 | F35: 2.99 | G35: 318.32 | H35: =(E35+F35)/D35 -> 1.0425562 | I35: 951.78 | J35: 0.56 | K35: =J35/D35 -> 0.0079703957 | L35: =J35*G35 -> 178.2592 | M35: =((E35+F35)-D35)-J35 -> 2.43 | N35: =M35/D35 -> 0.034585824 | O35: 組合室 | P35: 抓樣不穩 | Q35: 秤重物料，過多無法剝除 | R35: 二配香辣醬蒜味香腸蛋炒飯
A36: 9 | B36: 電解消毒混合紅K高麗絲 | C36: 771.62 | D36: 93.24 | E36: 93.24 | F36: 9.05 | G36: 104.84 | H36: =(E36+F36)/D36 -> 1.0970613 | I36: 948.8 | J36: 1.69 | K36: =J36/D36 -> 0.018125268 | L36: =J36*G36 -> 177.1796 | M36: =((E36+F36)-D36)-J36 -> 7.36 | N36: =M36/D36 -> 0.078936079 | O36: 組合室 | P36: 抓樣不穩 | Q36: 人員抓樣，絲狀較長抓樣重量差異 | R36: 共用類
A37: 10 | B37: 親子柴魚風味醬汁(114年) | C37: 771.59 | D37: 226.06 | E37: 226.06 | F37: 21.15 | G37: 44.86 | H37: =(E37+F37)/D37 -> 1.0935592 | I37: 948.79 | J37: 3.95 | K37: =J37/D37 -> 0.017473237 | L37: =J37*G37 -> 177.197 | M37: =((E37+F37)-D37)-J37 -> 17.2 | N37: =M37/D37 -> 0.076085995 | O37: 組合室 | P37: 抓樣不穩 | Q37: 注餡機使用(機器出料就有落差)，人員持續於線上不定時抽測重量 | R37: 共用類
A39: 共用類報廢金額前十名半成品
A40: 明細展開
A41: 排序 | B41: 半成品
B42: 名稱 | C42: 報廢金額 排序 | D42: 共用類總金額 占比
A44: 1 | B44: 拌總匯雞蛋沙拉CL(112年) | C44: 618.76 | D44: =C44/$L$5 -> 0.094276464
...

Sheet 0827分析標準表 
A1: 新豐廠半成品管理分析
A2: 日期 | C2: 營業額 | D2: 報廢展開 | F2: 超用展開 | H2: 報廢展開 | J2: 超用展開 | L2: 報廢展開
A3: 45896 | C3: 5656058.4 | D3: 總報廢 | F3: 總超用 | H3: 報廢-前10名 | J3: 超用-前10名 | L3: 共用類-總報廢
D4: 金額 | E4: 占比(營業額) | F4: 金額 | G4: 占比(營業額) | H4: 金額 | I4: 占比(總報廢) | J4: 金額 | K4: 占比(總超用) | L4: 金額 | M4: 占比(總報廢)
A5: 年度KPI目標0.25% | D5: 13725.69 | E5: =D5/C3 -> 0.0024267235 | F5: 43410.63 | G5: =F5/C3 -> 0.0076750676 | H5: =SUM(C12:C21) -> 3800.4 | I5: =H5/D5 -> 0.27688226 | J5: =SUM(C28:C37) -> 12041.49 | K5: =J5/F5 -> 0.27738575 | L5: 6230.94 | M5: =L5/D5 -> 0.45396188
A7: 報廢金額前十名半成品
A8: 明細展開 | D8: 生產資訊 | O8: 類別 | P8: 分析原因 (請填寫8大原因) | Q8: 其他原因說明 | R8: 備註-商品名稱
A9: 排序 | B9: 半成品 | D9: 生產端 | J9: 組合端
B10: 名稱 | C10: 報廢金額 排序 | D10: 產出量 | J10: 報廢 | L10: 超用
D11: 訂單需求 (kg) | E11: 實際產出 (kg) | F11: 補單 (kg) | G11: 單價 (元) | H11: 實際生產 (對比訂單需求) | I11: 差異 (元) | J11: kg | K11: 占比 | L11: kg | M11: 占比 | N11: 金額 (元)
A12: 1 | B12: 鮪魚沙拉(113.05) | C12: 950.8 | D12: 197.73 | E12: 197.73 | F12: 19.7 | G12: 194.04 | H12: =(E12+F12)/D12 -> 1.0996308 | I12: 3822.59 | J12: 4.9 | K12: =J12/D12 -> 0.024781267 | L12: =((E12+F12)-D12)-J12 -> 14.8 | M12: =L12/D12 -> 0.074849542 | N12: =L12*G12 -> 2871.792 | O12: 組合端 | P12: 抓樣不穩 | Q12: 人員冰杓定量手法不穩 | R12: 鮪魚起司溏心蛋三明治
A13: 2 | B13: 拌總匯雞蛋沙拉CL(112年) | C13: 457.63 | D13: 277.84 | E13: 277.84 | F13: 23.5 | G13: 95.34 | H13: =(E13+F13)/D13 -> 1.0845811 | I13: 2240.49 | J13: 4.8 | K13: =J13/D13 -> 0.01727613 | L13: =((E13+F13)-D13)-J13 -> 18.7 | M13: =L13/D13 -> 0.067304924 | N13: =L13*G13 -> 1782.858 | O13: 組合端 | P13: 抓樣不穩 | Q13: 人員冰杓定量手法不穩 | R13: 共用類
A14: 3 | B14: 義美業務用馬芬堡 | C14: 444.69 | D14: 13382 | E14: 13382 | F14: 76.67 | G14: 5.8 | H14: =(E14+F14)/D14 -> 1.0057293 | I14: 444.69 | J14: 76.67 | K14: =J14/D14 -> 0.0057293379 | L14: =((E14+F14)-D14)-J14 -> 0 | M14: =L14/D14 -> 0 | N14: =L14*G14 -> 0 | O14: 組合端 | P14: 其他原因 | Q14: 包材過於貼體 | R14: 共用類
A15: 4 | B15: 墨西哥餅皮-原味(8英吋)新 | C15: 393.62 | D15: 6628 | E15: 6628 | F15: 59.82 | G15: 6.58 | H15: =(E15+F15)/D15 -> 1.0090253 | I15: 393.62 | J15: 59.82 | K15: =J15/D15 -> 0.009025347 | L15: =((E15+F15)-D15)-J15 -> -2.9132252e-13 | M15: =L15/D15 -> -4.3953307e-17 | N15: =L15*G15 -> -1.9169022e-12 | O15: 原物料 | P15: 原物料規格 | Q15: 菜梗太硬導致捲的時候破損 | R15: 共用類
A16: 5 | B16: 溏心洋芋沙拉(113.06) | C16: 319.14 | D16: 334.5 | E16: 334.5 | F16: 14.94 | G16: 111.2 | H16: =(E16+F16)/D16 -> 1.0446637 | I16: 1661.33 | J16: 2.87 | K16: =J16/D16 -> 0.0085799701 | L16: =((E16+F16)-D16)-J16 -> 12.07 | M16: =L16/D16 -> 0.036083707 | N16: =L16*G16 -> 1342.184 | O16: 組合端 | P16: 抓樣不穩 | Q16: 人員冰杓定量手法不穩 | R16: 溏心蛋洋芋沙拉
A17: 6 | B17: 電解消毒十字切美生菜 | C17: 300.92 | D17: 291.15 | E17: 291.15 | F17: 10.24 | G17: 156.73 | H17: =(E17+F17)/D17 -> 1.0351709 | I17: 1604.92 | J17: 1.92 | K17: =J17/D17 -> 0.0065945389 | L17: =((E17+F17)-D17)-J17 -> 8.32 | M17: =L17/D17 -> 0.028576335 | N17: =L17*G17 -> 1303.9936 | O17: 原物料 | P17: 原物料規格 | Q17: 原物料特性，梗葉比例重量差異大 | R17: 共用類
A18: 7 | B18: 炒素鬆(新豐113.04) | C18: 271.57 | D18: 39.34 | E18: 39.34 | F18: 2 | G18: 271.57 | H18: =(E18+F18)/D18 -> 1.0508388 | I18: 543.14 | J18: 1 | K18: =J18/D18 -> 0.02541942 | L18: =((E18+F18)-D18)-J18 -> 1 | M18: =L18/D18 -> 0.02541942 | N18: =L18*G18 -> 271.57 | O18: 組合端 | P18: 抓樣不穩 | Q18: 人員冰杓定量手法不穩 | R18: 共用類
A19: 8 | B19: 炒辛口紅蘿蔔丁(112年) | C19: 259.49 | D19: 64.27 | E19: 64.27 | F19: 6.4 | G19: 90.1 | H19: =(E19+F19)/D19 -> 1.0995799 | I19: 576.64 | J19: 2.88 | K19: =J19/D19 -> 0.044810954 | L19: =((E19+F19)-D19)-J19 -> 3.52 | M19: =L19/D19 -> 0.054768944 | N19: =L19*G19 -> 317.152 | O19: 原物料 | P19: 原物料規格 | Q19: 原物料製程未過篩，調理製程後較細碎 | R19: 二配金咖哩濃厚辛辣咖哩飯
A20: 9 | B20: 紐奧良抹醬(113.04) | C20: 202.52 | D20: 36.98 | E20: 36.98 | F20: 3.6 | G20: 118.43 | H20: =(E20+F20)/D20 -> 1.0973499 | I20: 426.35 | J20: 1.71 | K20: =J20/D20 -> 0.046241211 | L20: =((E20+F20)-D20)-J20 -> 1.89 | M20: =L20/D20 -> 0.051108707 | N20: =L20*G20 -> 223.8327 | O20: 組合端 | P20: 抓樣不穩 | Q20: 刮板挖取使用，持續上抽測確認人員使用準確度 | R20: 紐奧良風味烤雞鮮蔬三明治
A21: 10 | B21: 青檸沙拉醬(113.03) | C21: 200.02 | D21: 145.81 | E21: 145.81 | F21: 8.58 | G21: 127.4 | H21: =(E21+F21)/D21 -> 1.0588437 | I21: 1093.09 | J21: 1.57 | K21: =J21/D21 -> 0.010767437 | L21: =((E21+F21)-D21)-J21 -> 7.01 | M21: =L21/D21 -> 0.048076264 | N21: =L21*G21 -> 893.074 | O21: 組合端 | P21: 抓樣不穩 | Q21: 人員冰杓定量手法不穩 | R21: 共用類
A23: 超用金額前十名半成品
A24: 明細展開 | D24: 生產資訊 | O24: 類別 | P24: 分析原因 (請填寫8大原因) | Q24: 其他原因說明 | R24: 備註-商品名稱
A25: 排序 | B25: 半成品 | D25: 生產端 | J25: 組合端
B26: 名稱 | C26: 超用金額 排序 | D26: 產出量 | J26: 報廢 | M26: 超用
D27: 訂單需求 (kg) | E27: 實際產出 (kg) | F27: 補單 (kg) | G27: 單價 (元) | H27: 實際生產 (對比訂單需求) | I27: 差異 (元) | J27: kg | K27: 占比 | L27: 金額 (元) | M27: kg | N27: 占比
A28: 1 | B28: 鮪魚沙拉(113.05) | C28: 2871.79 | D28: 197.73 | E28: 197.73 | F28: 19.7 | G28: 194.04 | H28: =(E28+F28)/D28 -> 1.0996308 | I28: 3822.59 | J28: 4.9 | K28: =J28/D28 -> 0.024781267 | L28: =J28*G28 -> 950.796 | M28: =((E28+F28)-D28)-J28 -> 14.8 | N28: =M28/D28 -> 0.074849542 | O28: 組合室 | P28: 抓樣不穩 | Q28: 冰杓定量挖取(使用量上會較起伏)，持續上抽測確認人員使用準確度 | R28: 鮪魚起司溏心蛋三明治
A29: 2 | B29: 拌總匯雞蛋沙拉CL(112年) | C29: 1782.86 | D29: 277.84 | E29: 277.84 | F29: 23.5 | G29: 95.34 | H29: =(E29+F29)/D29 -> 1.0845811 | I29: 2240.49 | J29: 4.8 | K29: =J29/D29 -> 0.01727613 | L29: =J29*G29 -> 457.632 | M29: =((E29+F29)-D29)-J29 -> 18.7 | N29: =M29/D29 -> 0.067304924 | O29: 組合室 | P29: 抓樣不穩 | Q29: 冰杓定量挖取(使用量上會較起伏)，持續上抽測確認人員使用準確度 | R29: 共用類
A30: 3 | B30: 溏心洋芋沙拉(113.06) | C30: 1342.19 | D30: 334.5 | E30: 334.5 | F30: 14.94 | G30: 111.2 | H30: =(E30+F30)/D30 -> 1.0446637 | I30: 1661.33 | J30: 2.87 | K30: =J30/D30 -> 0.0085799701 | L30: =J30*G30 -> 319.144 | M30: =((E30+F30)-D30)-J30 -> 12.07 | N30: =M30/D30 -> 0.036083707 | O30: 組合室 | P30: 抓樣不穩 | Q30: 冰杓定量挖取(使用量上會較起伏)，持續上抽測確認人員使用準確度 | R30: 溏心蛋洋芋沙拉
A31: 4 | B31: 電解消毒十字切美生菜 | C31: 1304 | D31: 291.15 | E31: 291.15 | F31: 10.24 | G31: 156.73 | H31: =(E31+F31)/D31 -> 1.0351709 | I31: 1604.92 | J31: 1.92 | K31: =J31/D31 -> 0.0065945389 | L31: =J31*G31 -> 300.9216 | M31: =((E31+F31)-D31)-J31 -> 8.32 | N31: =M31/D31 -> 0.028576335 | O31: 組合室 | P31: 抓樣不穩 | Q31: 原物料特性，梗葉比例重量差異，抓樣不穩 | R31: 共用類
A32: 5 | B32: 青檸沙拉醬(113.03) | C32: 893.07 | D32: 145.81 | E32: 145.81 | F32: 8.58 | G32: 127.4 | H32: =(E32+F32)/D32 -> 1.0588437 | I32: 1093.09 | J32: 1.57 | K32: =J32/D32 -> 0.010767437 | L32: =J32*G32 -> 200.018 | M32: =((E32+F32)-D32)-J32 -> 7.01 | N32: =M32/D32 -> 0.048076264 | O32: 組合室 | P32: 抓樣不穩 | Q32: 冰杓定量挖取(使用量上會較起伏)，持續上抽測確認人員使用準確度 | R32: 共用類
A33: 6 | B33: 電解消毒雙色高麗菜絲(7:3) | C33: 796.03 | D33: 231.98 | E33: 231.98 | F33: 8.76 | G33: 99.12 | H33: =(E33+F33)/D33 -> 1.0377619 | I33: 868.29 | J33: 0.729 | K33: =J33/D33 -> 0.0031425123 | L33: =J33*G33 -> 72.25848 | M33: =((E33+F33)-D33)-J33 -> 8.031 | N33: =M33/D33 -> 0.034619364 | O33: 組合室 | P33: 抓樣不穩 | Q33: 人員抓樣，絲狀較長抓樣重量差異 | R33: 共用類
A34: 7 | B34: F-台式特級沙拉醬 | C34: 787.02 | D34: 224.44 | E34: 224.44 | F34: 12.28 | G34: 78 | H34: =(E34+F34)/D34 -> 1.054714 | I34: 957.84 | J34: 2.19 | K34: =J34/D34 -> 0.009757619 | L34: =J34*G34 -> 170.82 | M34: =((E34+F34)-D34)-J34 -> 10.09 | N34: =M34/D34 -> 0.044956336 | O34: 組合室 | P34: 抓樣不穩 | Q34: 刮板挖取使用，持續上抽測確認人員使用準確度 | R34: 共用類
A35: 8 | B35: 蒸基礎風味雞肉絲 | C35: 762.89 | D35: 96.06 | E35: 96.06 | F35: 2.28 | G35: 410.16 | H35: =(E35+F35)/D35 -> 1.0237352 | I35: 935.16 | J35: 0.42 | K35: =J35/D35 -> 0.0043722673 | L35: =J35*G35 -> 172.2672 | M35: =((E35+F35)-D35)-J35 -> 1.86 | N35: =M35/D35 -> 0.019362898 | O35: 組合室 | P35: 抓樣不穩 | Q35: 秤重物料，過多無法剝除 | R35: 共用類
A36: 9 | B36: 蒸鼎泰豐香辣醬 | C36: 753.59 | D36: 23.34 | E36: 23.34 | F36: 1.01 | G36: 930.36 | H36: =(E36+F36)/D36 -> 1.0432734 | I36: 939.66 | J36: 0.2 | K36: =J36/D36 -> 0.0085689803 | L36: =J36*G36 -> 186.072 | M36: =((E36+F36)-D36)-J36 -> 0.81 | N36: =M36/D36 -> 0.03470437 | O36: 組合室 | P36: 抓樣不穩 | Q36: 冰杓定量挖取(使用量上會較起伏)，持續上抽測確認人員使用準確度 | R36: 二配香辣醬蒜味香腸蛋炒飯
A37: 10 | B37: 油亮蒜味香腸片 | C37: 748.05 | D37: 78.51 | E37: 78.51 | F37: 2.89 | G37: 318.32 | H37: =(E37+F37)/D37 -> 1.0368106 | I37: 919.94 | J37: 0.54 | K37: =J37/D37 -> 0.0068781047 | L37: =J37*G37 -> 171.8928 | M37: =((E37+F37)-D37)-J37 -> 2.35 | N37: =M37/D37 -> 0.029932493 | O37: 組合室 | P37: 抓樣不穩 | Q37: 秤重物料，過多無法剝除 | R37: 二配香辣醬蒜味香腸蛋炒飯
A39: 共用類報廢金額前十名半成品
A40: 明細展開
A41: 排序 | B41: 半成品
B42: 名稱 | C42: 報廢金額 排序 | D42: 共用類總金額 占比
A44: 1 | B44: 拌總匯雞蛋沙拉CL(112年) | C44: 457.63 | D44: =C44/$L$5 -> 0.073444777
...

Sheet 0826分析標準表 
A1: 新豐廠半成品管理分析
A2: 日期 | C2: 營業額 | D2: 報廢展開 | F2: 超用展開 | H2: 報廢展開 | J2: 超用展開 | L2: 報廢展開
A3: 45895 | C3: 5751890.8 | D3: 總報廢 | F3: 總超用 | H3: 報廢-前10名 | J3: 超用-前10名 | L3: 共用類-總報廢
D4: 金額 | E4: 占比(營業額) | F4: 金額 | G4: 占比(營業額) | H4: 金額 | I4: 占比(總報廢) | J4: 金額 | K4: 占比(總超用) | L4: 金額 | M4: 占比(總報廢)
A5: 年度KPI目標0.25% | D5: 13980.76 | E5: =D5/C3 -> 0.0024306372 | F5: 44448.19 | G5: =F5/C3 -> 0.0077275789 | H5: =SUM(C12:C21) -> 4161.68 | I5: =H5/D5 -> 0.29767194 | J5: =SUM(C28:C37) -> 10846.39 | K5: =J5/F5 -> 0.24402321 | L5: 8407.66 | M5: =L5/D5 -> 0.6013736
A7: 報廢金額前十名半成品
A8: 明細展開 | D8: 生產資訊 | O8: 類別 | P8: 分析原因 (請填寫8大原因) | Q8: 其他原因說明 | R8: 備註-商品名稱
A9: 排序 | B9: 半成品 | D9: 生產端 | J9: 組合端
B10: 名稱 | C10: 報廢金額 排序 | D10: 產出量 | J10: 報廢 | L10: 超用
D11: 訂單需求 (kg) | E11: 實際產出 (kg) | F11: 補單 (kg) | G11: 單價 (元) | H11: 實際生產 (對比訂單需求) | I11: 差異 (元) | J11: kg | K11: 占比 | L11: kg | M11: 占比 | N11: 金額 (元)
A12: 1 | B12: 義美業務用馬芬堡 | C12: 1447.16 | D12: 13613 | E12: 13613 | F12: 249.51 | G12: 5.8 | H12: =(E12+F12)/D12 -> 1.0183288 | I12: 1447.16 | J12: 249.51 | K12: =J12/D12 -> 0.018328803 | L12: =((E12+F12)-D12)-J12 -> 2.2737368e-13 | M12: =L12/D12 -> 1.6702687e-17 | N12: =L12*G12 -> 1.3187673e-12 | O12: 組合端 | P12: 其他原因 | Q12: 包材過於貼體 | R12: 共用類
A13: 2 | B13: 拌總匯雞蛋沙拉CL(112年) | C13: 656.89 | D13: 281.55 | E13: 281.55 | F13: 27.95 | G13: 95.34 | H13: =(E13+F13)/D13 -> 1.0992719 | I13: 2664.75 | J13: 6.89 | K13: =J13/D13 -> 0.024471675 | L13: =((E13+F13)-D13)-J13 -> 21.06 | M13: =L13/D13 -> 0.074800213 | N13: =L13*G13 -> 2007.8604 | O13: 組合端 | P13: 抓樣不穩 | Q13: 人員冰杓定量手法不穩 | R13: 共用類
A14: 3 | B14: 墨西哥餅皮-原味(8英吋)新 | C14: 392.56 | D14: 6694 | E14: 6694 | F14: 59.66 | G14: 6.58 | H14: =(E14+F14)/D14 -> 1.0089125 | I14: 392.56 | J14: 59.66 | K14: =J14/D14 -> 0.0089124589 | L14: =((E14+F14)-D14)-J14 -> -1.4210855e-13 | M14: =L14/D14 -> -2.1229242e-17 | N14: =L14*G14 -> -9.3507424e-13 | O14: 原物料 | P14: 原物料規格 | Q14: 菜梗太硬導致捲的時候破損 | R14: 共用類
A15: 4 | B15: 青醬優格(113.06) | C15: 365.42 | D15: 72.64 | E15: 72.64 | F15: 6.69 | G15: 159.57 | H15: =(E15+F15)/D15 -> 1.092098 | I15: 1067.52 | J15: 2.29 | K15: =J15/D15 -> 0.03152533 | L15: =((E15+F15)-D15)-J15 -> 4.4 | M15: =L15/D15 -> 0.060572687 | N15: =L15*G15 -> 702.108 | O15: 組合端 | P15: 抓樣不穩 | Q15: 人員冰杓定量手法不穩 | R15: 共用類
A16: 5 | B16: 炒素鬆(新豐113.04) | C16: 233.55 | D16: 39.18 | E16: 39.18 | F16: 3.63 | G16: 271.57 | H16: =(E16+F16)/D16 -> 1.0926493 | I16: 985.8 | J16: 0.86 | K16: =J16/D16 -> 0.021949974 | L16: =((E16+F16)-D16)-J16 -> 2.77 | M16: =L16/D16 -> 0.070699336 | N16: =L16*G16 -> 752.2489 | O16: 組合端 | P16: 抓樣不穩 | Q16: 人員冰杓定量手法不穩 | R16: 共用類
A17: 6 | B17: 電解消毒切段美生菜2-3cm | C17: 227.27 | D17: 355.16 | E17: 355.16 | F17: 7.07 | G17: 156.74 | H17: =(E17+F17)/D17 -> 1.0199065 | I17: 1108.15 | J17: 1.45 | K17: =J17/D17 -> 0.004082667 | L17: =((E17+F17)-D17)-J17 -> 5.62 | M17: =L17/D17 -> 0.015823854 | N17: =L17*G17 -> 880.8788 | O17: 原物料 | P17: 原物料規格 | Q17: 原物料特性，梗葉比例重量差異大 | R17: 共用類
A18: 7 | B18: 紐奧良抹醬(113.04) | C18: 218.5 | D18: 37.34 | E18: 37.34 | F18: 3.69 | G18: 118.43 | H18: =(E18+F18)/D18 -> 1.0988216 | I18: 437.01 | J18: 1.845 | K18: =J18/D18 -> 0.049410819 | L18: =((E18+F18)-D18)-J18 -> 1.845 | M18: =L18/D18 -> 0.049410819 | N18: =L18*G18 -> 218.50335 | O18: 組合端 | P18: 抓樣不穩 | Q18: 刮板挖取使用，持續上抽測確認人員使用準確度 | R18: 紐奧良風味烤雞鮮蔬三明治
A19: 8 | B19: 辛口咖哩豬肉(112年) | C19: 207.02 | D19: 74.05 | E19: 74.05 | F19: 3.08 | G19: 333.9 | H19: =(E19+F19)/D19 -> 1.0415935 | I19: 1028.41 | J19: 0.62 | K19: =J19/D19 -> 0.0083727211 | L19: =((E19+F19)-D19)-J19 -> 2.46 | M19: =L19/D19 -> 0.033220797 | N19: =L19*G19 -> 821.394 | O19: 組合端 | P19: 抓樣不穩 | Q19: 秤重物料，過多無法剝除 | R19: 二配金咖哩濃厚辛辣咖哩飯
A20: 9 | B20: 油亮蒜味香腸片 | C20: 206.91 | D20: 92.28 | E20: 92.28 | F20: 3.7 | G20: 318.32 | H20: =(E20+F20)/D20 -> 1.0400954 | I20: 1177.78 | J20: 0.65 | K20: =J20/D20 -> 0.0070437798 | L20: =((E20+F20)-D20)-J20 -> 3.05 | M20: =L20/D20 -> 0.033051582 | N20: =L20*G20 -> 970.876 | O20: 組合端 | P20: 抓樣不穩 | Q20: 秤重物料，過多無法剝除 | R20: 二配香辣醬蒜味香腸蛋炒飯
A21: 10 | B21: 電解消毒切段甜脆 | C21: 206.4 | D21: 12.64 | E21: 12.64 | F21: 1.25 | G21: 469.08 | H21: =(E21+F21)/D21 -> 1.0988924 | I21: 586.35 | J21: 0.44 | K21: =J21/D21 -> 0.034810127 | L21: =((E21+F21)-D21)-J21 -> 0.81 | M21: =L21/D21 -> 0.064082278 | N21: =L21*G21 -> 379.9548 | O21: 原物料 | P21: 原物料規格 | Q21: 原物料特性，梗葉比例重量差異大 | R21: 蔥鹽雞肉麵沙拉(114年)
A23: 超用金額前十名半成品
A24: 明細展開 | D24: 生產資訊 | O24: 類別 | P24: 分析原因 (請填寫8大原因) | Q24: 其他原因說明 | R24: 備註-商品名稱
A25: 排序 | B25: 半成品 | D25: 生產端 | J25: 組合端
B26: 名稱 | C26: 超用金額 排序 | D26: 產出量 | J26: 報廢 | M26: 超用
D27: 訂單需求 (kg) | E27: 實際產出 (kg) | F27: 補單 (kg) | G27: 單價 (元) | H27: 實際生產 (對比訂單需求) | I27: 差異 (元) | J27: kg | K27: 占比 | L27: 金額 (元) | M27: kg | N27: 占比
A28: 1 | B28: 拌總匯雞蛋沙拉CL(112年) | C28: 2007.86 | D28: 281.55 | E28: 281.55 | F28: 27.95 | G28: 95.34 | H28: =(E28+F28)/D28 -> 1.0992719 | I28: 2664.75 | J28: 6.89 | K28: =J28/D28 -> 0.024471675 | L28: =J28*G28 -> 656.8926 | M28: =((E28+F28)-D28)-J28 -> 21.06 | N28: =M28/D28 -> 0.074800213 | O28: 組合室 | P28: 抓樣不穩 | Q28: 冰杓定量挖取(使用量上會較起伏)，持續上抽測確認人員使用準確度 | R28: 共用類
A29: 2 | B29: F-台式特級沙拉醬 | C29: 1021.8 | D29: 229 | E29: 229 | F29: 15.73 | G29: 78 | H29: =(E29+F29)/D29 -> 1.06869 | I29: 1226.94 | J29: 2.63 | K29: =J29/D29 -> 0.011484716 | L29: =J29*G29 -> 205.14 | M29: =((E29+F29)-D29)-J29 -> 13.1 | N29: =M29/D29 -> 0.05720524 | O29: 組合室 | P29: 抓樣不穩 | Q29: 刮板挖取使用，持續上抽測確認人員使用準確度 | R29: 共用類
A30: 3 | B30: 蒸鼎泰豐香辣醬 | C30: 1014.09 | D30: 27.43 | E30: 27.43 | F30: 1.31 | G30: 930.36 | H30: =(E30+F30)/D30 -> 1.0477579 | I30: 1218.77 | J30: 0.22 | K30: =J30/D30 -> 0.0080204156 | L30: =J30*G30 -> 204.6792 | M30: =((E30+F30)-D30)-J30 -> 1.09 | N30: =M30/D30 -> 0.039737514 | O30: 組合室 | P30: 抓樣不穩 | Q30: 冰杓定量挖取(使用量上會較起伏)，持續上抽測確認人員使用準確度 | R30: 二配香辣醬蒜味香腸蛋炒飯
